Workbook

Sheet BBDD
A1: Fecha Ingreso | B1: Marca | C1: Modelo | D1: Versión | E1: Estado Dealer | F1: Año | G1: Placa Patente | H1: Días Stock | I1: Kilometraje | J1: Estado AutoPro | K1: Suma de Precio Compra Neto | L1: Suma de Precio Lista | M1: Precio Venta Real
A2: 01-02-2023 11:21:43 | B2: RENAULT | C2: RENAULT | D2: DUSTER ZEN 1.6 | E2: DISPONIBLE | F2: 2019 | G2: LBVX44 | H2: 7 | I2: 46987 | J2: Facturado | K2: 13000000 | L2: 15980000 | M2: =IFERROR(VLOOKUP(G2,Hoja3!A:B,2,0),0) -> 8170390
A3: 01-02-2023 11:25:45 | B3: VOLKSWAGEN | C3: TIGUAN | D3: TIGUAN OTTO 1.4 AUT | E3: DISPONIBLE | F3: 2020 | G3: LPXH47 | H3: 7 | I3: 43395 | J3: Facturado | K3: 30000000 | L3: 35980000 | M3: =IFERROR(VLOOKUP(G3,Hoja3!A:B,2,0),0) -> 18320390
A4: 01-03-2023 10:57:53 | B4: NISSAN | C4: QASHQAI | D4: QASHQAI J11 2.0 | E4: DISPONIBLE | F4: 2021 | G4: PPVC34 | H4: 30 | I4: 5928 | J4: Facturado | K4: 24000000 | L4: 28580000 | M4: =IFERROR(VLOOKUP(G4,Hoja3!A:B,2,0),0) -> 18044836
A5: 01-03-2023 11:00:59 | B5: MAZDA | C5: MAZDA | D5: ALL NEW CX30 2.0 | E5: DISPONIBLE | F5: 2020 | G5: LYSR94 | H5: 47 | I5: 35000 | J5: Facturado | K5: 28000000 | L5: 33980000 | M5: =IFERROR(VLOOKUP(G5,Hoja3!A:B,2,0),0) -> 17017540
A6: 01-03-2023 8:27:22 | B6: MG | C6: MG3 | D6: NEW 3 1.5 | E6: DISPONIBLE | F6: 2019 | G6: LBVW84 | H6: 48 | I6: 40350 | J6: Facturado | K6: 10600000 | L6: 13180000 | M6: =IFERROR(VLOOKUP(G6,Hoja3!A:B,2,0),0) -> 6749390
A7: 01-03-2023 8:29:51 | B7: FORD | C7: ESCAPE | D7: ESCAPE 2.0 AUT | E7: DISPONIBLE | F7: 2019 | G7: LBVV62 | H7: 58 | I7: 36000 | J7: Facturado | K7: 26000000 | L7: 29980000 | M7: =IFERROR(VLOOKUP(G7,Hoja3!A:B,2,0),0) -> 14870890
A8: 01-03-2024 9:01:07 | B8: PEUGEOT | C8: 5008 | D8: 5008 BLUEHDI 130 1.5 AUT | E8: DISPONIBLE | F8: 2022 | G8: RLSG73 | H8: 6 | I8: 71000 | J8: Facturado | K8: 36000000 | L8: 41980000 | M8: =IFERROR(VLOOKUP(G8,Hoja3!A:B,2,0),0) -> 21026030
A9: 01-03-2024 9:04:24 | B9: MAXUS | C9: MAXUS | D9: T90 4WD 2.0 AUT | E9: DISPONIBLE | F9: 2024 | G9: TBZL63 | H9: 25 | I9: 2200 | J9: Facturado | K9: 48000000 | L9: 55380000 | M9: =IFERROR(VLOOKUP(G9,Hoja3!A:B,2,0),0) -> 27733729
A10: 01-03-2024 9:08:00 | B10: PEUGEOT | C10: 3008 | D10: 3008 ALLURE BLUEHDI 1.5 AT | E10: DISPONIBLE | F10: 2019 | G10: LHCW17 | H10: 700 | I10: 103000 | J10: Facturado | K10: 22600000 | L10: 24980000 | M10: =IFERROR(VLOOKUP(G10,Hoja3!A:B,2,0),0) -> 12753377
A11: 01-03-2024 9:11:14 | B11: CHERY | C11: TIGGO 2 PRO | D11: TIGGO 2 GLS CVT PRO 1.5 AUT | E11: DISPONIBLE | F11: 2021 | G11: RDLL62 | H11: 183 | I11: 35000 | J11: Facturado | K11: 13600000 | L11: 16780000 | M11: =IFERROR(VLOOKUP(G11,Hoja3!A:B,2,0),0) -> 8084880
A12: 01-03-2024 9:19:20 | B12: OPEL | C12: MOKKA | D12: MOKKA 1.4 AUT | E12: DISPONIBLE | F12: 2020 | G12: LRWG63 | H12: 14 | I12: 30000 | J12: Facturado | K12: 20000000 | L12: 24180000 | M12: =IFERROR(VLOOKUP(G12,Hoja3!A:B,2,0),0) -> 12090000
A13: 01-03-2024 9:21:58 | B13: NISSAN | C13: KICKS | D13: KICKS 1.6 | E13: DISPONIBLE | F13: 2021 | G13: PPJG76 | H13: 25 | I13: 34479 | J13: Facturado | K13: 19600000 | L13: 23780000 | M13: =IFERROR(VLOOKUP(G13,Hoja3!A:B,2,0),0) -> 11890000
... A1010: 16-09-2025 18:44:05 | B1010: HYUNDAI | C1010: HYUNDAI | D1010: TUCSON NX4 GDI 7DCT 1.6 AUT | E1010: DISPONIBLE | F1010: 2022 | G1010: RSHS21 | H1010: 99 | I1010: 33000 | J1010: Facturado | K1010: 29125790 | L1010: 35580000 | M1010: =IFERROR(VLOOKUP(G1010,Hoja3!A:B,2,0),0) -> 15497319
A1011: 16-10-2024 10:05:22 | B1011: PEUGEOT | D1011: 4008 FELINE 4WD 2.0 AUT | E1011: DISPONIBLE | F1011: 2016 | G1011: HTBJ27 | H1011: 195 | I1011: 92000 | J1011: Facturado | K1011: 16000000 | L1011: 20380000 | M1011: =IFERROR(VLOOKUP(G1011,Hoja3!A:B,2,0),0) -> 9043393
A1012: 16-10-2024 10:38:41 | B1012: KIA MOTORS | C1012: SELTOS | D1012: SELTOS EX 1.6 AUT | E1012: DISPONIBLE | F1012: 2020 | G1012: PFRR40 | H1012: 13 | I1012: 45000 | J1012: Facturado | K1012: 23000000 | L1012: 27180000 | M1012: =IFERROR(VLOOKUP(G1012,Hoja3!A:B,2,0),0) -> 13590000
A1013: 16-10-2024 9:24:20 | B1013: KIA MOTORS | C1013: SELTOS | D1013: SELTOS EX 1.5 | E1013: DISPONIBLE | F1013: 2024 | G1013: TPTZ11 | H1013: 14 | I1013: 1326 | J1013: Facturado | K1013: 30000000 | L1013: 33980000 | M1013: =IFERROR(VLOOKUP(G1013,Hoja3!A:B,2,0),0) -> 17026030
A1014: 16-10-2024 9:40:21 | B1014: KIA MOTORS | C1014: MORNING | D1014: MORNING EX 1.2 | E1014: DISPONIBLE | F1014: 2017 | G1014: JPLT11 | H1014: 13 | I1014: 77390 | J1014: Facturado | K1014: 8600000 | L1014: 11780000 | M1014: =IFERROR(VLOOKUP(G1014,Hoja3!A:B,2,0),0) -> 5926030
A1015: 16-10-2025 17:45:02 | B1015: RENAULT | C1015: RENAULT | D1015: OROCH 2.0 | E1015: DISPONIBLE | F1015: 2018 | G1015: KJWV14 | H1015: 32 | I1015: 41894 | J1015: Facturado | K1015: 12900000 | L1015: 15980000 | M1015: =IFERROR(VLOOKUP(G1015,Hoja3!A:B,2,0),0) -> 10895259
A1016: 16-10-2025 18:22:16 | B1016: KIA MOTORS | C1016: SPORTAGE | D1016: SPORTAGE EX 2.0L | E1016: DISPONIBLE | F1016: 2023 | G1016: SJJG29 | H1016: 44 | I1016: 62929 | J1016: Facturado | K1016: 32000000 | L1016: 37780000 | M1016: =IFERROR(VLOOKUP(G1016,Hoja3!A:B,2,0),0) -> 19149380
A1017: 16-12-2025 17:17:41 | B1017: JAC | C1017: JS | D1017: JS2 HATCHBACK 1.5 | E1017: DISPONIBLE | F1017: 2024 | G1017: TJDF16 | H1017: 35 | I1017: 6147 | J1017: Facturado | K1017: 14000000 | L1017: 16780000 | M1017: =IFERROR(VLOOKUP(G1017,Hoja3!A:B,2,0),0) -> 8528955
A1018: 16-12-2025 17:44:20 | B1018: KIA MOTORS | C1018: SPORTAGE | D1018: SPORTAGE EX 2.0 | E1018: CON PRENDA | F1018: 2023 | G1018: SLZG20 | H1018: 31 | I1018: 68000 | J1018: Facturado | K1018: 31400000 | L1018: 38580000 | M1018: =IFERROR(VLOOKUP(G1018,Hoja3!A:B,2,0),0) -> 19290000
A1019: 16-12-2025 19:06:45 | B1019: CHEVROLET | C1019: ONIX | D1019: ONIX HB RS 1.0T | E1019: DISPONIBLE | F1019: 2023 | G1019: SPSY59 | H1019: 36 | I1019: 62213 | J1019: Facturado | K1019: 16000000 | L1019: 19380000 | M1019: =IFERROR(VLOOKUP(G1019,Hoja3!A:B,2,0),0) -> 9911380
A1020: 17-01-2023 15:07:53 | B1020: JMC | C1020: VIGUS PICK UP | D1020: . | E1020: DISPONIBLE | F1020: 2022 | G1020: RTLV30 | H1020: 252 | I1020: 20300 | J1020: Facturado | K1020: 29600000 | L1020: 28980000 | M1020: =IFERROR(VLOOKUP(G1020,Hoja3!A:B,2,0),0) -> 14531063
A1021: 17-01-2025 11:11:03 | B1021: PEUGEOT | C1021: LANDTREK | D1021: LANDTREK BLUEHDI 4X4 2.2 AUT | E1021: DISPONIBLE | F1021: 2024 | G1021: THRH47 | H1021: 0 | I1021: 6600 | J1021: Facturado | K1021: 43600000 | L1021: 53980000 | M1021: =IFERROR(VLOOKUP(G1021,Hoja3!A:B,2,0),0) -> 26990000
A1022: 17-02-2023 12:51:51 | B1022: SUZUKI | C1022: IGNIS | D1022: IGNIS GL HB 1.2 | E1022: DISPONIBLE | F1022: 2017 | G1022: JLTJ52 | H1022: 0 | I1022: 80200 | J1022: Facturado | K1022: 10200000 | L1022: 11800000 | M1022: =IFERROR(VLOOKUP(G1022,Hoja3!A:B,2,0),0) -> 6049040
A1023: 17-02-2023 12:57:37 | B1023: KIA MOTORS | C1023: SOLUTO | D1023: SOLUTO 1.4 | E1023: DISPONIBLE | F1023: 2022 | G1023: RJCT51 | H1023: 7 | I1023: 15000 | J1023: Facturado | K1023: 13400000 | L1023: 15980000 | M1023: =IFERROR(VLOOKUP(G1023,Hoja3!A:B,2,0),0) -> 8295212
... A2253: 31-12-2025 13:17:08 | B2253: RAM | C2253: RAM 700 | D2253: 700 BIGHORN D CAB 4X2 1.4 | E2253: DISPONIBLE | F2253: 2024 | G2253: SZTK19 | H2253: 0 | I2253: 29000 | J2253: Facturado | K2253: 22600000 | L2253: 24000000 | M2253: =IFERROR(VLOOKUP(G2253,Hoja3!A:B,2,0),0) -> 12256030
A2254: Total general | K2254: 56279491157 | L2254: 67467966401

Sheet Hoja3
A1: Placa Patente | B1: Total Venta
A2: HRWV51 | B2: 26592657
A3: RFVX24 | B3: 18990000
A4: KBCK12 | B4: 7800406
A5: RKRX82 | B5: 17305390
A6: RBCZ59 | B6: 18286390
A7: JXSZ39 | B7: 13078406
A8: JKYG98 | B8: 19335390
A9: PFSC16 | B9: 14071566
A10: PJDD13 | B10: 19650040
A11: LYPB29 | B11: 16302290
A12: JBJW21 | B12: 11450000
A13: PSHY94 | B13: 19944390
... A139: PTDH25 | B139: 39629508
B140: 21017540
B141: 14265181
A142: KZVZ40 | B142: 21974390
A143: GFFR39 | B143: 11517540
A144: FFZW59 | B144: 11225540
A145: SPZB66 | B145: 25055530
A146: PLSP29 | B146: 10822824
A147: JXFZ74 | B147: 7192113
A148: PRBC55 | B148: 16598174
A149: PRSH84 | B149: 12110195
A150: JHSB38 | B150: 22401738
A151: KTCS55 | B151: 13017540
A152: PJLL59 | B152: 15596312
A153: LLBJ17 | B153: 9997390
... A228: PSHX59 | B228: 14853540
B229: 13245390
A230: RBJH90 | B230: 14490000
A231: KCBZ34 | B231: 22026048
A232: RFVG61 | B232: 10001642
A233: LXHV17 | B233: 19061945
A234: JHRZ76 | B234: 7099776
A235: LYLV18 | B235: 11017316
A236: GSDW61 | B236: 6647890
A237: KCBZ60 | B237: 10504890
A238: JPZG71 | B238: 7017540
A239: KTCS69 | B239: 18191715
...

Sheet Hoja1
A1: Empresa | B1: Sucursal | C1: Folio Venta | D1: Venta | E1: Estado Venta | F1: Fecha Venta | G1: Tipo Documento (Folio) | H1: Vendedor | I1: Fecha Ingreso | J1: Fecha Facturación | K1: Numero VIN | L1: Marca | M1: Modelo | N1: Versión | O1: Código Versión | P1: Año | Q1: Kilometraje | R1: Código Interno | S1: Placa Patente | T1: Condición Vehículo | U1: Color Exterior | V1: Color Interior | W1: Precio Venta Total | X1: Estado AutoPro | Y1: Días Stock | Z1: Estado Dealer | AA1: Bodega | AB1: Equipamiento | AC1: Numero Motor | AD1: Numero Chasis | AE1: Proveedor | AF1: Fecha Disponibilidad | AG1: Factura Compra | AH1: Vencimiento Documento | AI1: Fecha Compra | AJ1: Fecha Vencto. Revisión Técnica | AK1: N° Propietarios | AL1: Folio Retoma | AM1: Fecha Retoma | AN1: Días Reservado | AO1: Precio Compra Neto | AP1: Gasto | AQ1: Accesorios | AR1: Total Costo | AS1: Precio Lista | AT1: Margen | AU1: Margen %
A2: IMPORTADORA TRENTO LTDA | B2: LOCAL USADOS | C2: 2296 | D2: 44381 | E2: Facturada | F2: 18-01-2025 12:55:55 | G2: Factura Exenta Electrónica (68870) | H2: VANESSA CASANGA CASTILLO | I2: 19-11-2024 19:08:12 | J2: 30-01-2025 0:00:00 | K2: MALC381CA KM453860 | L2: HYUNDAI | M2: HYUNDAI | N2: CRETA GS PE 1.6 | O2: HYCRRE16MT | P2: 2019 | Q2: 79000 | R2: THYSTWU000528 | S2: KZKC62 | T2: USADO | U2: GRIS OSCURO | V2: POR DEFINIR | W2: 9790000 | X2: Facturado | Y2: 72 | Z2: DISPONIBLE | AA2: BODEGA VEHICULOS | AB2: AE,CC,EE,NB,ABS,LL,4AB,AC,AISO,AAUTO,CRE,ACD,SR,UD | AC2: G4FGJW523548 | AD2: MALC381CA KM453860 | AE2: MARIA MIRNA COVARRUBIAS CARMONA | AF2: 19-11-2024 0:00:00 | AG2: 1 | AH2: 04-12-2024 19:29:00 | AI2: 04-12-2024 19:29:00 | AJ2: 31-05-2025 0:00:00 | AK2: 1 | AL2: 0 | AN2: 2 | AO2: 7400000 | AP2: 237030 | AQ2: 0 | AR2: 7637030 | AS2: 9790000 | AT2: 2152970 | AU2: 2199
A3: IMPORTADORA TRENTO LTDA | B3: LOCAL USADOS | C3: 2296 | D3: 44381 | E3: Facturada | F3: 18-01-2025 12:55:55 | G3: Factura Exenta Electrónica (68870) | H3: VANESSA CASANGA CASTILLO | I3: 19-11-2024 19:08:12 | J3: 30-01-2025 0:00:00 | K3: MALC381CA KM453860 | L3: HYUNDAI | M3: HYUNDAI | N3: CRETA GS PE 1.6 | O3: HYCRRE16MT | P3: 2019 | Q3: 79000 | R3: THYSTWU000528 | S3: KZKC62 | T3: USADO | U3: GRIS OSCURO | V3: POR DEFINIR | W3: 9790000 | X3: Facturado | Y3: 72 | Z3: DISPONIBLE | AA3: BODEGA VEHICULOS | AB3: AE,CC,EE,NB,ABS,LL,4AB,AC,AISO,AAUTO,CRE,ACD,SR,UD | AC3: G4FGJW523548 | AD3: MALC381CA KM453860 | AE3: MARIA MIRNA COVARRUBIAS CARMONA | AF3: 19-11-2024 0:00:00 | AG3: 1 | AH3: 04-12-2024 19:29:00 | AI3: 04-12-2024 19:29:00 | AJ3: 31-05-2025 0:00:00 | AK3: 1 | AL3: 0 | AN3: 2 | AO3: 7400000 | AP3: 237030 | AQ3: 0 | AR3: 7637030 | AS3: 9790000 | AT3: 2152970 | AU3: 2199
A4: IMPORTADORA TRENTO LTDA | B4: LOCAL USADOS | C4: 2077 | D4: 40116 | E4: Facturada | F4: 15-02-2024 9:43:21 | G4: Factura Exenta Electrónica (63553) | H4: FEDERICO ALBERT | I4: 13-02-2024 9:18:39 | J4: 16-02-2024 0:00:00 | K4: KNAB3512AJT021057 | L4: KIA MOTORS | M4: MORNING | N4: MORNING EX 1.2 | O4: 17--1510E4 | P4: 2017 | Q4: 66000 | R4: TKIAUTU002128 | S4: JLHR52 | T4: USADO | U4: AZUL CIELO | V4: POR DEFINIR | W4: 6090000 | X4: Facturado | Y4: 3 | Z4: DISPONIBLE | AA4: BODEGA VEHICULOS | AC4: G4LAHP009994 | AD4: KNAB3512AJT021057 | AE4: LILIAN ANGELICA PARRA GONZALEZ | AF4: 13-02-2024 0:00:00 | AG4: 1 | AH4: 13-02-2024 0:00:00 | AI4: 26-02-2024 15:27:55 | AK4: 0 | AL4: 0 | AN4: 2 | AO4: 4500000 | AP4: 0 | AQ4: 0 | AR4: 4500000 | AS4: 6090000 | AT4: 1590000 | AU4: 2611
A5: IMPORTADORA TRENTO LTDA | B5: LOCAL USADOS | C5: 2077 | D5: 40116 | E5: Facturada | F5: 15-02-2024 9:43:21 | G5: Factura Exenta Electrónica (63553) | H5: FEDERICO ALBERT | I5: 13-02-2024 9:18:39 | J5: 16-02-2024 0:00:00 | K5: KNAB3512AJT021057 | L5: KIA MOTORS | M5: MORNING | N5: MORNING EX 1.2 | O5: 17--1510E4 | P5: 2017 | Q5: 66000 | R5: TKIAUTU002128 | S5: JLHR52 | T5: USADO | U5: AZUL CIELO | V5: POR DEFINIR | W5: 6090000 | X5: Facturado | Y5: 3 | Z5: DISPONIBLE | AA5: BODEGA VEHICULOS | AC5: G4LAHP009994 | AD5: KNAB3512AJT021057 | AE5: LILIAN ANGELICA PARRA GONZALEZ | AF5: 13-02-2024 0:00:00 | AG5: 1 | AH5: 13-02-2024 0:00:00 | AI5: 26-02-2024 15:27:55 | AK5: 0 | AL5: 0 | AN5: 2 | AO5: 4500000 | AP5: 0 | AQ5: 0 | AR5: 4500000 | AS5: 6090000 | AT5: 1590000 | AU5: 2611
A6: IMPORTADORA TRENTO LTDA | B6: LOCAL USADOS | C6: 2349 | D6: 45512 | E6: Facturada | F6: 15-04-2025 16:11:59 | G6: Factura Exenta Electrónica (69703) | H6: FEDERICO ALBERT | I6: 31-01-2025 15:39:03 | J6: 29-04-2025 0:00:00 | K6: WVWZZZ60ZHT137869 | L6: VOLKSWAGEN | M6: POLO | N6: POLO HIGHLINE 1.6 | O6: VWPOLO16MT | P6: 2018 | Q6: 51777 | R6: TVOAUTU000223 | S6: JXGB32 | T6: USADO | U6: BLANCO CANDY | V6: POR DEFINIR | W6: 8990000 | X6: Facturado | Y6: 88 | Z6: DISPONIBLE | AA6: BODEGA VEHICULOS | AB6: AE,CC,EE,2AB,NB,ABS,LL,AC,AAUTO,ACD,SR,UD,GF | AC6: CLS 597900 | AD6: WVWZZZ60ZHT137869 | AE6: CARLOS EDIN TAPIA LEIVA | AF6: 31-01-2025 0:00:00 | AG6: 1 | AH6: 28-04-2025 16:57:00 | AI6: 28-04-2025 16:57:00 | AJ6: 31-05-2025 0:00:00 | AK6: 1 | AL6: 0 | AN6: 0 | AO6: 6500000 | AP6: 223530 | AQ6: 9923 | AR6: 6733453 | AS6: 8990000 | AT6: 2256547 | AU6: 251
A7: IMPORTADORA TRENTO LTDA | B7: LOCAL USADOS | C7: 2349 | D7: 45512 | E7: Facturada | F7: 15-04-2025 16:11:59 | G7: Factura Exenta Electrónica (69703) | H7: FEDERICO ALBERT | I7: 31-01-2025 15:39:03 | J7: 29-04-2025 0:00:00 | K7: WVWZZZ60ZHT137869 | L7: VOLKSWAGEN | M7: POLO | N7: POLO HIGHLINE 1.6 | O7: VWPOLO16MT | P7: 2018 | Q7: 51777 | R7: TVOAUTU000223 | S7: JXGB32 | T7: USADO | U7: BLANCO CANDY | V7: POR DEFINIR | W7: 8990000 | X7: Facturado | Y7: 88 | Z7: DISPONIBLE | AA7: BODEGA VEHICULOS | AB7: AE,CC,EE,2AB,NB,ABS,LL,AC,AAUTO,ACD,SR,UD,GF | AC7: CLS 597900 | AD7: WVWZZZ60ZHT137869 | AE7: CARLOS EDIN TAPIA LEIVA | AF7: 31-01-2025 0:00:00 | AG7: 1 | AH7: 28-04-2025 16:57:00 | AI7: 28-04-2025 16:57:00 | AJ7: 31-05-2025 0:00:00 | AK7: 1 | AL7: 0 | AN7: 0 | AO7: 6500000 | AP7: 223530 | AQ7: 9923 | AR7: 6733453 | AS7: 8990000 | AT7: 2256547 | AU7: 251
A8: IMPORTADORA TRENTO LTDA | B8: LOCAL PREMIUM CAR SALES | C8: 1594 | D8: 37848 | E8: Facturada | F8: 25-07-2023 12:34:31 | G8: Factura Exenta Electrónica (63173) | H8: JORDI AGUSTIN FOITZICK MUÑOZ | I8: 19-07-2023 16:42:47 | J8: 26-07-2023 0:00:00 | K8: 3N8CP5HE1PL462445 | L8: NISSAN | M8: KICKS | N8: KICKS CVT 1.6 AUT | O8: KICKS | P8: 2022 | Q8: 4000 | R8: TNISTWU000494 | S8: RZSK13 | T8: USADO | U8: GRIS METALICO | V8: POR DEFINIR | W8: 14990000 | X8: Facturado | Y8: 7 | Z8: DISPONIBLE | AA8: PREMIUM CAR SALES | AC8: HR16-540239V | AD8: 3N8CP5HE1PL462445 | AE8: JAIME EDUARDO GALLEGUILLOS ARAYA | AF8: 19-07-2023 0:00:00 | AG8: 1 | AH8: 19-07-2023 0:00:00 | AI8: 19-07-2023 16:42:08 | AK8: 0 | AL8: 0 | AN8: 4 | AO8: 12200000 | AP8: 353540 | AQ8: 0 | AR8: 12553540 | AS8: 14990000 | AT8: 2436460 | AU8: 1625
A9: IMPORTADORA TRENTO LTDA | B9: LOCAL PREMIUM CAR SALES | C9: 1594 | D9: 37848 | E9: Facturada | F9: 25-07-2023 12:34:31 | G9: Factura Exenta Electrónica (63173) | H9: JORDI AGUSTIN FOITZICK MUÑOZ | I9: 19-07-2023 16:42:47 | J9: 26-07-2023 0:00:00 | K9: 3N8CP5HE1PL462445 | L9: NISSAN | M9: KICKS | N9: KICKS CVT 1.6 AUT | O9: KICKS | P9: 2022 | Q9: 4000 | R9: TNISTWU000494 | S9: RZSK13 | T9: USADO | U9: GRIS METALICO | V9: POR DEFINIR | W9: 14990000 | X9: Facturado | Y9: 7 | Z9: DISPONIBLE | AA9: PREMIUM CAR SALES | AC9: HR16-540239V | AD9: 3N8CP5HE1PL462445 | AE9: JAIME EDUARDO GALLEGUILLOS ARAYA | AF9: 19-07-2023 0:00:00 | AG9: 1 | AH9: 19-07-2023 0:00:00 | AI9: 19-07-2023 16:42:08 | AK9: 0 | AL9: 0 | AN9: 4 | AO9: 12200000 | AP9: 353540 | AQ9: 0 | AR9: 12553540 | AS9: 14990000 | AT9: 2436460 | AU9: 1625
A10: IMPORTADORA TRENTO LTDA | B10: LOCAL PREMIUM CAR SALES | C10: 1881 | D10: 44331 | E10: Facturada | F10: 14-01-2025 15:46:54 | G10: Factura Exenta Electrónica (68850) | H10: DANIEL ALEJANDRO AGUILERA CORTES | I10: 13-12-2024 14:03:40 | J10: 15-01-2025 0:00:00 | K10: VF3MCYHZU SS000521 | L10: PEUGEOT | M10: 5008 | N10: 5008 BLUEHDI 130 1.5 AUT | O10: 5008BH130 | P10: 2024 | Q10: 3361 | R10: TPESTWU000383 | S10: TRTY36 | T10: USADO | U10: GRIS ARTENSE | V10: POR DEFINIR | W10: 26490000 | X10: Facturado | Y10: 33 | Z10: DISPONIBLE | AA10: PREMIUM CAR SALES | AB10: AE,CC,EE,AAC,ABS,LL,ESP,AISO,AAUTO,CRE,ACD,SR,UD,D | AC10: 10Q3EJ1887283 | AD10: VF3MCYHZU SS000521 | AE10: TITO DANILO LEIVA RIQUELME | AF10: 13-12-2024 0:00:00 | AG10: 1 | AH10: 13-12-2024 0:00:00 | AI10: 13-12-2024 13:57:07 | AK10: 1 | AL10: 0 | AN10: 5 | AO10: 22800000 | AP10: 468030 | AQ10: 0 | AR10: 23268030 | AS10: 26490000 | AT10: 3221970 | AU10: 1216
A11: IMPORTADORA TRENTO LTDA | B11: LOCAL PREMIUM CAR SALES | C11: 1881 | D11: 44331 | E11: Facturada | F11: 14-01-2025 15:46:54 | G11: Factura Exenta Electrónica (68850) | H11: DANIEL ALEJANDRO AGUILERA CORTES | I11: 13-12-2024 14:03:40 | J11: 15-01-2025 0:00:00 | K11: VF3MCYHZU SS000521 | L11: PEUGEOT | M11: 5008 | N11: 5008 BLUEHDI 130 1.5 AUT | O11: 5008BH130 | P11: 2024 | Q11: 3361 | R11: TPESTWU000383 | S11: TRTY36 | T11: USADO | U11: GRIS ARTENSE | V11: POR DEFINIR | W11: 26490000 | X11: Facturado | Y11: 33 | Z11: DISPONIBLE | AA11: PREMIUM CAR SALES | AB11: AE,CC,EE,AAC,ABS,LL,ESP,AISO,AAUTO,CRE,ACD,SR,UD,D | AC11: 10Q3EJ1887283 | AD11: VF3MCYHZU SS000521 | AE11: TITO DANILO LEIVA RIQUELME | AF11: 13-12-2024 0:00:00 | AG11: 1 | AH11: 13-12-2024 0:00:00 | AI11: 13-12-2024 13:57:07 | AK11: 1 | AL11: 0 | AN11: 5 | AO11: 22800000 | AP11: 468030 | AQ11: 0 | AR11: 23268030 | AS11: 26490000 | AT11: 3221970 | AU11: 1216
A12: IMPORTADORA TRENTO LTDA | B12: MEGACENTRO OVALLE | C12: 391 | D12: 42945 | E12: Facturada | F12: 04-10-2024 17:30:37 | G12: Factura Exenta Electrónica (64020) | H12: JOSE GREGORIO TORRES | I12: 03-09-2024 15:21:33 | J12: 10-10-2024 0:00:00 | K12: *----....../***// | L12: HYUNDAI | M12: HYUNDAI | N12: CRETA GRAND MPI 2.0 | O12: HYUNCRET2.0 | P12: 2024 | Q12: 1665 | R12: THYSTWU000524 | S12: TLRP41 | T12: USADO | U12: GRIS GRAFITO | V12: POR DEFINIR | W12: 16490000 | X12: Facturado | Y12: 37 | Z12: DISPONIBLE | AA12: BODEGA OVALLEveih | AB12: AE,CC,EE,NB,ABS,LL,4AB,AC,AISO,CRE,MAV,ACD,SR,UD,D | AC12: G4NLPW632552 | AD12: MALPC815ARM865510 | AE12: TITO DANILO LEIVA RIQUELME | AF12: 03-09-2024 0:00:00 | AG12: 1 | AH12: 17-10-2024 18:59:00 | AI12: 17-10-2024 18:59:00 | AK12: 0 | AL12: 0 | AN12: 24 | AO12: 14000000 | AP12: 476280 | AQ12: 9211 | AR12: 14485491 | AS12: 16490000 | AT12: 2004509 | AU12: 1216
A13: IMPORTADORA TRENTO LTDA | B13: MEGACENTRO OVALLE | C13: 391 | D13: 42945 | E13: Facturada | F13: 04-10-2024 17:30:37 | G13: Factura Exenta Electrónica (64020) | H13: JOSE GREGORIO TORRES | I13: 03-09-2024 15:21:33 | J13: 10-10-2024 0:00:00 | K13: *----....../***// | L13: HYUNDAI | M13: HYUNDAI | N13: CRETA GRAND MPI 2.0 | O13: HYUNCRET2.0 | P13: 2024 | Q13: 1665 | R13: THYSTWU000524 | S13: TLRP41 | T13: USADO | U13: GRIS GRAFITO | V13: POR DEFINIR | W13: 16490000 | X13: Facturado | Y13: 37 | Z13: DISPONIBLE | AA13: BODEGA OVALLEveih | AB13: AE,CC,EE,NB,ABS,LL,4AB,AC,AISO,CRE,MAV,ACD,SR,UD,D | AC13: G4NLPW632552 | AD13: MALPC815ARM865510 | AE13: TITO DANILO LEIVA RIQUELME | AF13: 03-09-2024 0:00:00 | AG13: 1 | AH13: 17-10-2024 18:59:00 | AI13: 17-10-2024 18:59:00 | AK13: 0 | AL13: 0 | AN13: 24 | AO13: 14000000 | AP13: 476280 | AQ13: 9211 | AR13: 14485491 | AS13: 16490000 | AT13: 2004509 | AU13: 1216
A14: IMPORTADORA TRENTO LTDA | B14: LOCAL USADOS | C14: 1911 | D14: 36761 | E14: Facturada | F14: 28-03-2023 10:27:22 | G14: Factura Exenta Electrónica (63012) | H14: Rodrigo Andres Toro Orostegui | I14: 27-03-2023 15:11:30 | J14: 28-03-2023 0:00:00 | K14: MZBFC814APN166309 | L14: KIA MOTORS | M14: SONET | N14: SONET EX 1.5 | O14: SOU1 | P14: 2022 | Q14: 6300 | R14: TKISTWU001224 | S14: SBKC22 | T14: USADO | U14: BLANCO INVIERNO | V14: POR DEFINIR | W14: 13990000 | X14: Facturado | Y14: 1 | Z14: DISPONIBLE | AA14: BODEGA VEHICULOS | AC14: G4FLNV303090 | AD14: MZBFC814APN166309 | AE14: JUAN GABRIEL CORTES GAJARDO | AF14: 27-03-2023 0:00:00 | AG14: 1 | AH14: 27-03-2023 0:00:00 | AI14: 27-03-2023 15:11:09 | AK14: 0 | AL14: 0 | AN14: 1 | AO14: 12000000 | AP14: 340540 | AQ14: 10844 | AR14: 12351384 | AS14: 13990000 | AT14: 1638616 | AU14: 1171
A15: IMPORTADORA TRENTO LTDA | B15: LOCAL USADOS | C15: 1911 | D15: 36761 | E15: Facturada | F15: 28-03-2023 10:27:22 | G15: Factura Exenta Electrónica (63012) | H15: Rodrigo Andres Toro Orostegui | I15: 27-03-2023 15:11:30 | J15: 28-03-2023 0:00:00 | K15: MZBFC814APN166309 | L15: KIA MOTORS | M15: SONET | N15: SONET EX 1.5 | O15: SOU1 | P15: 2022 | Q15: 6300 | R15: TKISTWU001224 | S15: SBKC22 | T15: USADO | U15: BLANCO INVIERNO | V15: POR DEFINIR | W15: 13990000 | X15: Facturado | Y15: 1 | Z15: DISPONIBLE | AA15: BODEGA VEHICULOS | AC15: G4FLNV303090 | AD15: MZBFC814APN166309 | AE15: JUAN GABRIEL CORTES GAJARDO | AF15: 27-03-2023 0:00:00 | AG15: 1 | AH15: 27-03-2023 0:00:00 | AI15: 27-03-2023 15:11:09 | AK15: 0 | AL15: 0 | AN15: 1 | AO15: 12000000 | AP15: 340540 | AQ15: 10844 | AR15: 12351384 | AS15: 13990000 | AT15: 1638616 | AU15: 1171
A16: IMPORTADORA TRENTO LTDA | B16: LOCAL PREMIUM CAR SALES | C16: 1819 | D16: 43094 | E16: Facturada | F16: 18-10-2024 15:31:01 | G16: Factura Exenta Electrónica (64041) | H16: DANIEL ALEJANDRO AGUILERA CORTES | I16: 10-10-2024 17:46:14 | J16: 21-10-2024 0:00:00 | K16: LJXCU2BB6MTP06598 | L16: FORD | M16: TERRITORY | N16: TERRITORY 1.5 AUT | O16: FTU1 | P16: 2021 | Q16: 26500 | R16: TFOSTWU001321 | S16: PSHX11 | T16: USADO | U16: BLANCO METALICO | V16: POR DEFINIR | W16: 13290000 | X16: Facturado | Y16: 11 | Z16: DISPONIBLE | AA16: PREMIUM CAR SALES | AB16: AE,CC,EE,NB,AAC,ABS,LL,VC,4AB,AISO,AAUTO,CRE,MAV,A | AC16: LCG061349 | AD16: LJXCU2BB6MTP06598 | AE16: FABIAN RENATO COLLAO CUBILLOS | AF16: 10-10-2024 0:00:00 | AG16: 1 | AH16: 10-10-2024 0:00:00 | AI16: 10-10-2024 17:42:08 | AK16: 0 | AL16: 0 | AN16: 7 | AO16: 11000000 | AP16: 341030 | AQ16: 0 | AR16: 11341030 | AS16: 13290000 | AT16: 1948970 | AU16: 1466
A17: IMPORTADORA TRENTO LTDA | B17: LOCAL PREMIUM CAR SALES | C17: 1819 | D17: 43094 | E17: Facturada | F17: 18-10-2024 15:31:01 | G17: Factura Exenta Electrónica (64041) | H17: DANIEL ALEJANDRO AGUILERA CORTES | I17: 10-10-2024 17:46:14 | J17: 21-10-2024 0:00:00 | K17: LJXCU2BB6MTP06598 | L17: FORD | M17: TERRITORY | N17: TERRITORY 1.5 AUT | O17: FTU1 | P17: 2021 | Q17: 26500 | R17: TFOSTWU001321 | S17: PSHX11 | T17: USADO | U17: BLANCO METALICO | V17: POR DEFINIR | W17: 13290000 | X17: Facturado | Y17: 11 | Z17: DISPONIBLE | AA17: PREMIUM CAR SALES | AB17: AE,CC,EE,NB,AAC,ABS,LL,VC,4AB,AISO,AAUTO,CRE,MAV,A | AC17: LCG061349 | AD17: LJXCU2BB6MTP06598 | AE17: FABIAN RENATO COLLAO CUBILLOS | AF17: 10-10-2024 0:00:00 | AG17: 1 | AH17: 10-10-2024 0:00:00 | AI17: 10-10-2024 17:42:08 | AK17: 0 | AL17: 0 | AN17: 7 | AO17: 11000000 | AP17: 341030 | AQ17: 0 | AR17: 11341030 | AS17: 13290000 | AT17: 1948970 | AU17: 1466
A18: IMPORTADORA TRENTO LTDA | B18: LOCAL USADOS | C18: 2342 | D18: 45388 | E18: Facturada | F18: 04-04-2025 16:20:47 | G18: Factura Exenta Electrónica (69024) | H18: VANESSA CASANGA CASTILLO | I18: 21-03-2025 17:16:00 | J18: 09-04-2025 0:00:00 | K18: 9BFZB55U7J8687464 | L18: FORD | M18: ECOSPORT | N18: ECOSPORT TITANIUM 1.5 | O18: EC3333 | P18: 2018 | Q18: 52119 | R18: TFOSTWU001356 | S18: KDTL69 | T18: USADO | U18: BLANCO | V18: POR DEFINIR | W18: 8990000 | X18: Facturado | Y18: 19 | Z18: CON PRENDA | AA18: BODEGA VEHICULOS | AB18: AE,CC,EE,2AB,NB,ABS,LL,TC,AC,AISO,AAUTO,CRE,MAV,TE | AC18: XZJAJ8687464 | AD18: 9BFZB55U7J8687464 | AE18: SERGIO FLORENCIO GAMBOA | AF18: 21-03-2025 0:00:00 | AG18: 1 | AH18: 21-03-2025 0:00:00 | AI18: 21-03-2025 17:09:36 | AJ18: 31-01-2026 0:00:00 | AK18: 3 | AL18: 0 | AN18: 11 | AO18: 7000000 | AP18: 381608 | AQ18: 2893 | AR18: 7384501 | AS18: 8990000 | AT18: 1605499 | AU18: 1786
A19: IMPORTADORA TRENTO LTDA | B19: LOCAL USADOS | C19: 2342 | D19: 45388 | E19: Facturada | F19: 04-04-2025 16:20:47 | G19: Factura Exenta Electrónica (69024) | H19: VANESSA CASANGA CASTILLO | I19: 21-03-2025 17:16:00 | J19: 09-04-2025 0:00:00 | K19: 9BFZB55U7J8687464 | L19: FORD | M19: ECOSPORT | N19: ECOSPORT TITANIUM 1.5 | O19: EC3333 | P19: 2018 | Q19: 52119 | R19: TFOSTWU001356 | S19: KDTL69 | T19: USADO | U19: BLANCO | V19: POR DEFINIR | W19: 8990000 | X19: Facturado | Y19: 19 | Z19: CON PRENDA | AA19: BODEGA VEHICULOS | AB19: AE,CC,EE,2AB,NB,ABS,LL,TC,AC,AISO,AAUTO,CRE,MAV,TE | AC19: XZJAJ8687464 | AD19: 9BFZB55U7J8687464 | AE19: SERGIO FLORENCIO GAMBOA | AF19: 21-03-2025 0:00:00 | AG19: 1 | AH19: 21-03-2025 0:00:00 | AI19: 21-03-2025 17:09:36 | AJ19: 31-01-2026 0:00:00 | AK19: 3 | AL19: 0 | AN19: 11 | AO19: 7000000 | AP19: 381608 | AQ19: 2893 | AR19: 7384501 | AS19: 8990000 | AT19: 1605499 | AU19: 1786
A20: IMPORTADORA TRENTO LTDA | B20: LOCAL PREMIUM CAR SALES | C20: 1643 | D20: 39079 | E20: Facturada | F20: 16-11-2023 13:48:51 | G20: Factura Exenta Electrónica (63403) | H20: JORDI AGUSTIN FOITZICK MUÑOZ | I20: 19-07-2023 17:01:59 | J20: 20-11-2023 0:00:00 | K20: 9BGEP69K0NG166056 | L20: CHEVROLET | M20: ONIX | N20: ONIX NB PREMIER 1.0T AUT | O20: AG12 | P20: 2022 | Q20: 5200 | R20: TCHAUTU000883 | S20: RVPZ64 | T20: USADO | U20: BLANCO | V20: POR DEFINIR | W20: 11490000 | X20: Facturado | Y20: 124 | Z20: DISPONIBLE | AA20: PREMIUM CAR SALES | AC20: L4F 213434039 | AD20: 9BGEP69K0NG166056 | AE20: NASIB MAJMUT AMPUERO | AF20: 19-07-2023 0:00:00 | AG20: 1 | AH20: 19-07-2023 0:00:00 | AI20: 19-07-2023 17:01:25 | AK20: 0 | AL20: 0 | AN20: 0 | AO20: 10300000 | AP20: 325040 | AQ20: 0 | AR20: 10625040 | AS20: 11490000 | AT20: 864960 | AU20: 753
A21: IMPORTADORA TRENTO LTDA | B21: LOCAL PREMIUM CAR SALES | C21: 1643 | D21: 39079 | E21: Facturada | F21: 16-11-2023 13:48:51 | G21: Factura Exenta Electrónica (63403) | H21: JORDI AGUSTIN FOITZICK MUÑOZ | I21: 19-07-2023 17:01:59 | J21: 20-11-2023 0:00:00 | K21: 9BGEP69K0NG166056 | L21: CHEVROLET | M21: ONIX | N21: ONIX NB PREMIER 1.0T AUT | O21: AG12 | P21: 2022 | Q21: 5200 | R21: TCHAUTU000883 | S21: RVPZ64 | T21: USADO | U21: BLANCO | V21: POR DEFINIR | W21: 11490000 | X21: Facturado | Y21: 124 | Z21: DISPONIBLE | AA21: PREMIUM CAR SALES | AC21: L4F 213434039 | AD21: 9BGEP69K0NG166056 | AE21: NASIB MAJMUT AMPUERO | AF21: 19-07-2023 0:00:00 | AG21: 1 | AH21: 19-07-2023 0:00:00 | AI21: 19-07-2023 17:01:25 | AK21: 0 | AL21: 0 | AN21: 0 | AO21: 10300000 | AP21: 325040 | AQ21: 0 | AR21: 10625040 | AS21: 11490000 | AT21: 864960 | AU21: 753
A22: IMPORTADORA TRENTO LTDA | B22: LOCAL PREMIUM CAR SALES | C22: 1824 | D22: 43176 | E22: Facturada | F22: 24-10-2024 14:20:56 | G22: Factura Exenta Electrónica (68703) | H22: JORDI AGUSTIN FOITZICK MUÑOZ | I22: 18-10-2024 13:25:37 | J22: 28-10-2024 0:00:00 | K22: JMBXNGA1W NU000433 | L22: MITSUBISHI | M22: ASX | N22: ASX 1.6 | O22: ASX 1.6 | P22: 2022 | Q22: 20000 | R22: TMISTWU000344 | S22: RJCW25 | T22: USADO | U22: BLANCO | V22: POR DEFINIR | W22: 14390000 | X22: Facturado | Y22: 10 | Z22: DISPONIBLE | AA22: PREMIUM CAR SALES | AB22: AE,CC,EE,2AB,NB,ABS,LL,AC,AAUTO,CRE,MAV,ACD,SR,UD, | AC22: 4A92 JK8535 | AD22: JMBXNGA1W NU000433 | AE22: HECTOR DIMAS HURIAZ CACERES | AF22: 18-10-2024 0:00:00 | AG22: 1 | AH22: 18-10-2024 0:00:00 | AI22: 18-10-2024 13:21:09 | AK22: 0 | AL22: 0 | AN22: 1 | AO22: 12000000 | AP22: 356030 | AQ22: 0 | AR22: 12356030 | AS22: 14390000 | AT22: 2033970 | AU22: 1413
A23: IMPORTADORA TRENTO LTDA | B23: LOCAL PREMIUM CAR SALES | C23: 1824 | D23: 43176 | E23: Facturada | F23: 24-10-2024 14:20:56 | G23: Factura Exenta Electrónica (68703) | H23: JORDI AGUSTIN FOITZICK MUÑOZ | I23: 18-10-2024 13:25:37 | J23: 28-10-2024 0:00:00 | K23: JMBXNGA1W NU000433 | L23: MITSUBISHI | M23: ASX | N23: ASX 1.6 | O23: ASX 1.6 | P23: 2022 | Q23: 20000 | R23: TMISTWU000344 | S23: RJCW25 | T23: USADO | U23: BLANCO | V23: POR DEFINIR | W23: 14390000 | X23: Facturado | Y23: 10 | Z23: DISPONIBLE | AA23: PREMIUM CAR SALES | AB23: AE,CC,EE,2AB,NB,ABS,LL,AC,AAUTO,CRE,MAV,ACD,SR,UD, | AC23: 4A92 JK8535 | AD23: JMBXNGA1W NU000433 | AE23: HECTOR DIMAS HURIAZ CACERES | AF23: 18-10-2024 0:00:00 | AG23: 1 | AH23: 18-10-2024 0:00:00 | AI23: 18-10-2024 13:21:09 | AK23: 0 | AL23: 0 | AN23: 1 | AO23: 12000000 | AP23: 356030 | AQ23: 0 | AR23: 12356030 | AS23: 14390000 | AT23: 2033970 | AU23: 1413
A24: IMPORTADORA TRENTO LTDA | B24: LOCAL PREMIUM CAR SALES | C24: 0 | D24: 0 | I24: 06-05-2026 18:05:59 | K24: //.//+*+///++*... | L24: MITSUBISHI | M24: OUTLANDER | N24: OUTLANDER GLS 4X4 2.5 AT | O24: NOI09 | P24: 2025 | Q24: 13500 | R24: TMISTWU000373 | S24: VDFP78 | T24: USADO | U24: GRIS GRAFITO | V24: POR DEFINIR | W24: 31590000 | X24: Disponible | Y24: 35 | Z24: EN PREPARACION | AA24: PREMIUM CAR SALES | AB24: AE,CC,EE,NB,AAC,ABS,LL,VC,AISO,AAUTO,CRE,MAV,ACD,S | AC24: PR25 573855F | AD24: JMYXTGM4WSZ002020 | AE24: LUIS GASTÓN ALCAYAGA NUÑEZ | AF24: 06-05-2026 0:00:00 | AG24: 1 | AH24: 06-05-2026 0:00:00 | AI24: 06-05-2026 18:05:30 | AK24: 1 | AL24: 0 | AN24: 0 | AO24: 26300000 | AP24: 523740 | AQ24: 0 | AR24: 26823740 | AS24: 31590000 | AT24: 4766260 | AU24: 1509
A25: IMPORTADORA TRENTO LTDA | B25: LOCAL PREMIUM CAR SALES | C25: 0 | D25: 0 | I25: 06-05-2026 18:05:59 | K25: //.//+*+///++*... | L25: MITSUBISHI | M25: OUTLANDER | N25: OUTLANDER GLS 4X4 2.5 AT | O25: NOI09 | P25: 2025 | Q25: 13500 | R25: TMISTWU000373 | S25: VDFP78 | T25: USADO | U25: GRIS GRAFITO | V25: POR DEFINIR | W25: 31590000 | X25: Disponible | Y25: 35 | Z25: EN PREPARACION | AA25: PREMIUM CAR SALES | AB25: AE,CC,EE,NB,AAC,ABS,LL,VC,AISO,AAUTO,CRE,MAV,ACD,S | AC25: PR25 573855F | AD25: JMYXTGM4WSZ002020 | AE25: LUIS GASTÓN ALCAYAGA NUÑEZ | AF25: 06-05-2026 0:00:00 | AG25: 1 | AH25: 06-05-2026 0:00:00 | AI25: 06-05-2026 18:05:30 | AK25: 1 | AL25: 0 | AN25: 0 | AO25: 26300000 | AP25: 523740 | AQ25: 0 | AR25: 26823740 | AS25: 31590000 | AT25: 4766260 | AU25: 1509
A26: IMPORTADORA TRENTO LTDA | B26: LOCAL PREMIUM CAR SALES | C26: 2012 | D26: 46789 | E26: Facturada | F26: 23-07-2025 12:04:43 | G26: Factura Exenta Electrónica (69867) | H26: JORDI AGUSTIN FOITZICK MUÑOZ | I26: 22-07-2025 18:54:34 | J26: 25-07-2025 0:00:00 | K26: /////////....+++* | L26: CITROEN | M26: C4 | N26: C4 1.2 AT | O26: CIC412AT | P26: 2025 | Q26: 2858 | R26: TCIAUTU000123 | S26: VBHL43 | T26: USADO | U26: GRIS ARTENSE | V26: POR DEFINIR | W26: 18990000 | X26: Facturado | Y26: 3 | Z26: DISPONIBLE | AA26: PREMIUM CAR SALES | AB26: AE,CC,EE,AAC,ABS,LL,VC,AISO,AAUTO,CRE,MAV,ACD,SR,D | AC26: 10XVBB2277247 | AD26: VR7BAHNSBSE000591 | AE26: NELSON JOSE ALEJANDRO GAETE GONZALEZ | AF26: 22-07-2025 0:00:00 | AG26: 1 | AH26: 22-07-2025 0:00:00 | AI26: 22-07-2025 18:51:05 | AK26: 2 | AL26: 0 | AN26: 0 | AO26: 16500000 | AP26: 373530 | AQ26: 0 | AR26: 16873530 | AS26: 18990000 | AT26: 2116470 | AU26: 1115
A27: IMPORTADORA TRENTO LTDA | B27: LOCAL PREMIUM CAR SALES | C27: 2012 | D27: 46789 | E27: Facturada | F27: 23-07-2025 12:04:43 | G27: Factura Exenta Electrónica (69867) | H27: JORDI AGUSTIN FOITZICK MUÑOZ | I27: 22-07-2025 18:54:34 | J27: 25-07-2025 0:00:00 | K27: /////////....+++* | L27: CITROEN | M27: C4 | N27: C4 1.2 AT | O27: CIC412AT | P27: 2025 | Q27: 2858 | R27: TCIAUTU000123 | S27: VBHL43 | T27: USADO | U27: GRIS ARTENSE | V27: POR DEFINIR | W27: 18990000 | X27: Facturado | Y27: 3 | Z27: DISPONIBLE | AA27: PREMIUM CAR SALES | AB27: AE,CC,EE,AAC,ABS,LL,VC,AISO,AAUTO,CRE,MAV,ACD,SR,D | AC27: 10XVBB2277247 | AD27: VR7BAHNSBSE000591 | AE27: NELSON JOSE ALEJANDRO GAETE GONZALEZ | AF27: 22-07-2025 0:00:00 | AG27: 1 | AH27: 22-07-2025 0:00:00 | AI27: 22-07-2025 18:51:05 | AK27: 2 | AL27: 0 | AN27: 0 | AO27: 16500000 | AP27: 373530 | AQ27: 0 | AR27: 16873530 | AS27: 18990000 | AT27: 2116470 | AU27: 1115
A28: IMPORTADORA TRENTO LTDA | B28: LOCAL USADOS COPIAPO | C28: 1069 | D28: 42166 | E28: Facturada | F28: 07-08-2024 12:17:53 | G28: Factura Exenta Electrónica (63901) | H28: LUCILA ANTONIA ARREDONDO CASTRO | I28: 29-07-2024 12:30:11 | J28: 23-08-2024 0:00:00 | K28: LVTDB11B5ND048433 | L28: CHERY | M28: TIGGO 8 | N28: TIGGO 8 1.5 | O28: TIIII8 | P28: 2022 | Q28: 42500 | R28: TCYSTWU000259 | S28: RTWY58 | T28: USADO | U28: AZUL METALIZADO | V28: POR DEFINIR | W28: 12090000 | X28: Facturado | Y28: 25 | Z28: DISPONIBLE | AA28: BODEGA LOS CARRERA COPIAPO | AB28: AE,CC,EE,AAC,ABS,LL,TC,VC,ESP,AISO,AAUTO,CRE,MAV,A | AC28: SQRE4T15BALMM00605 | AD28: LVTDB11B5ND048433 | AE28: TELMO FRANCISCO GALLEGUILLOS QUIROGA | AF28: 29-07-2024 0:00:00 | AG28: 1 | AH28: 29-07-2024 0:00:00 | AI28: 29-07-2024 12:27:27 | AK28: 0 | AL28: 0 | AN28: 6 | AO28: 10200000 | AP28: 329030 | AQ28: 1178 | AR28: 10530208 | AS28: 12090000 | AT28: 1559792 | AU28: 129
A29: IMPORTADORA TRENTO LTDA | B29: LOCAL USADOS COPIAPO | C29: 1069 | D29: 42166 | E29: Facturada | F29: 07-08-2024 12:17:53 | G29: Factura Exenta Electrónica (63901) | H29: LUCILA ANTONIA ARREDONDO CASTRO | I29: 29-07-2024 12:30:11 | J29: 23-08-2024 0:00:00 | K29: LVTDB11B5ND048433 | L29: CHERY | M29: TIGGO 8 | N29: TIGGO 8 1.5 | O29: TIIII8 | P29: 2022 | Q29: 42500 | R29: TCYSTWU000259 | S29: RTWY58 | T29: USADO | U29: AZUL METALIZADO | V29: POR DEFINIR | W29: 12090000 | X29: Facturado | Y29: 25 | Z29: DISPONIBLE | AA29: BODEGA LOS CARRERA COPIAPO | AB29: AE,CC,EE,AAC,ABS,LL,TC,VC,ESP,AISO,AAUTO,CRE,MAV,A | AC29: SQRE4T15BALMM00605 | AD29: LVTDB11B5ND048433 | AE29: TELMO FRANCISCO GALLEGUILLOS QUIROGA | AF29: 29-07-2024 0:00:00 | AG29: 1 | AH29: 29-07-2024 0:00:00 | AI29: 29-07-2024 12:27:27 | AK29: 0 | AL29: 0 | AN29: 6 | AO29: 10200000 | AP29: 329030 | AQ29: 1178 | AR29: 10530208 | AS29: 12090000 | AT29: 1559792 | AU29: 129
A30: IMPORTADORA TRENTO LTDA | B30: LOCAL PREMIUM CAR SALES | C30: 0 | D30: 0 | I30: 28-04-2026 11:16:31 | K30: /////++***/++*... | L30: ZX AUTO | M30: TERRALORD | N30: TERRALORD DCAB DLX 2.5 | O30: ZXTERRDCDLX25MT | P30: 2022 | Q30: 58000 | R30: TZXCMTU000004 | S30: RDWB83 | T30: USADO | U30: PLATEADO PLATA | V30: POR DEFINIR | W30: 11290000 | X30: Disponible | Y30: 43 | Z30: DISPONIBLE | AA30: PREMIUM CAR SALES | AB30: AE,CC,EE,NB,ABS,LL,VC,4AB,AC,AISO,AAUTO,MAV,ACD,UD | AC30: 20-36100283 | AD30: LTA1222U2N9101636 | AE30: ALFONSO SEGUNDO CARVAJAL ROJAS | AF30: 28-04-2026 0:00:00 | AG30: 1 | AH30: 28-04-2026 0:00:00 | AI30: 28-04-2026 11:16:03 | AK30: 1 | AL30: 0 | AN30: 0 | AO30: 8900000 | AP30: 262740 | AQ30: 0 | AR30: 9162740 | AS30: 11290000 | AT30: 2127260 | AU30: 1884
A31: IMPORTADORA TRENTO LTDA | B31: LOCAL PREMIUM CAR SALES | C31: 0 | D31: 0 | I31: 28-04-2026 11:16:31 | K31: /////++***/++*... | L31: ZX AUTO | M31: TERRALORD | N31: TERRALORD DCAB DLX 2.5 | O31: ZXTERRDCDLX25MT | P31: 2022 | Q31: 58000 | R31: TZXCMTU000004 | S31: RDWB83 | T31: USADO | U31: PLATEADO PLATA | V31: POR DEFINIR | W31: 11290000 | X31: Disponible | Y31: 43 | Z31: DISPONIBLE | AA31: PREMIUM CAR SALES | AB31: AE,CC,EE,NB,ABS,LL,VC,4AB,AC,AISO,AAUTO,MAV,ACD,UD | AC31: 20-36100283 | AD31: LTA1222U2N9101636 | AE31: ALFONSO SEGUNDO CARVAJAL ROJAS | AF31: 28-04-2026 0:00:00 | AG31: 1 | AH31: 28-04-2026 0:00:00 | AI31: 28-04-2026 11:16:03 | AK31: 1 | AL31: 0 | AN31: 0 | AO31: 8900000 | AP31: 262740 | AQ31: 0 | AR31: 9162740 | AS31: 11290000 | AT31: 2127260 | AU31: 1884
A32: IMPORTADORA TRENTO LTDA | B32: MEGACENTRO OVALLE | C32: 317 | D32: 36199 | E32: Facturada | F32: 07-02-2023 15:44:29 | G32: Factura Exenta Electrónica (62073) | H32: Armando Canihuante . | I32: 27-01-2023 10:23:12 | J32: 07-02-2023 0:00:00 | K32: LVZA53P91JCB00949 | L32: DFSK | M32: 580 | N32: 580 1.8 | O32: HJ70 | P32: 2018 | Q32: 63900 | R32: TDFSTWU000016 | S32: KGKZ84 | T32: USADO | U32: BLANCO | V32: POR DEFINIR | W32: 7990000 | X32: Facturado | Y32: 11 | Z32: DISPONIBLE | AA32: BODEGA OVALLEveih | AC32: SFG1817552648 | AD32: LVZA53P91JCB00949 | AE32: HERNAN HUMBERTO JIMENEZ RAMOS | AF32: 27-01-2023 0:00:00 | AG32: 1 | AH32: 27-02-2023 17:55:00 | AI32: 27-02-2023 17:55:00 | AK32: 0 | AL32: 0 | AN32: 8 | AO32: 6000000 | AP32: 388323 | AQ32: 21270 | AR32: 6409593 | AS32: 7990000 | AT32: 1580407 | AU32: 1978
A33: IMPORTADORA TRENTO LTDA | B33: MEGACENTRO OVALLE | C33: 317 | D33: 36199 | E33: Facturada | F33: 07-02-2023 15:44:29 | G33: Factura Exenta Electrónica (62073) | H33: Armando Canihuante . | I33: 27-01-2023 10:23:12 | J33: 07-02-2023 0:00:00 | K33: LVZA53P91JCB00949 | L33: DFSK | M33: 580 | N33: 580 1.8 | O33: HJ70 | P33: 2018 | Q33: 63900 | R33: TDFSTWU000016 | S33: KGKZ84 | T33: USADO | U33: BLANCO | V33: POR DEFINIR | W33: 7990000 | X33: Facturado | Y33: 11 | Z33: DISPONIBLE | AA33: BODEGA OVALLEveih | AC33: SFG1817552648 | AD33: LVZA53P91JCB00949 | AE33: HERNAN HUMBERTO JIMENEZ RAMOS | AF33: 27-01-2023 0:00:00 | AG33: 1 | AH33: 27-02-2023 17:55:00 | AI33: 27-02-2023 17:55:00 | AK33: 0 | AL33: 0 | AN33: 8 | AO33: 6000000 | AP33: 388323 | AQ33: 21270 | AR33: 6409593 | AS33: 7990000 | AT33: 1580407 | AU33: 1978
A34: IMPORTADORA TRENTO LTDA | B34: LOCAL USADOS | C34: 2023 | D34: 39101 | E34: Facturada | F34: 17-11-2023 19:12:57 | G34: Factura Exenta Electrónica (63412) | H34: VANESSA CASANGA CASTILLO | I34: 14-11-2023 8:50:02 | J34: 23-11-2023 0:00:00 | K34: LSJW74U98LZ035051 | L34: MG | M34: MGZS | N34: ZS 1.5 AUT | O34: Z87W | P34: 2020 | Q34: 15000 | R34: TMGSTWU000037 | S34: PCDX27 | T34: USADO | U34: BLANCO | V34: POR DEFINIR | W34: 9290000 | X34: Facturado | Y34: 9 | Z34: DISPONIBLE | AA34: BODEGA VEHICULOS | AC34: 15S4C8FGKB011199 | AD34: LSJW74U98LZ035051 | AE34: SERGIO EDUARDO MATURANA ESPINOZA | AF34: 14-11-2023 0:00:00 | AG34: 1 | AH34: 14-11-2023 0:00:00 | AI34: 14-11-2023 8:49:31 | AK34: 0 | AL34: 0 | AN34: 1 | AO34: 7500000 | AP34: 273040 | AQ34: 3946 | AR34: 7776986 | AS34: 9290000 | AT34: 1513014 | AU34: 1629
A35: IMPORTADORA TRENTO LTDA | B35: LOCAL USADOS | C35: 2023 | D35: 39101 | E35: Facturada | F35: 17-11-2023 19:12:57 | G35: Factura Exenta Electrónica (63412) | H35: VANESSA CASANGA CASTILLO | I35: 14-11-2023 8:50:02 | J35: 23-11-2023 0:00:00 | K35: LSJW74U98LZ035051 | L35: MG | M35: MGZS | N35: ZS 1.5 AUT | O35: Z87W | P35: 2020 | Q35: 15000 | R35: TMGSTWU000037 | S35: PCDX27 | T35: USADO | U35: BLANCO | V35: POR DEFINIR | W35: 9290000 | X35: Facturado | Y35: 9 | Z35: DISPONIBLE | AA35: BODEGA VEHICULOS | AC35: 15S4C8FGKB011199 | AD35: LSJW74U98LZ035051 | AE35: SERGIO EDUARDO MATURANA ESPINOZA | AF35: 14-11-2023 0:00:00 | AG35: 1 | AH35: 14-11-2023 0:00:00 | AI35: 14-11-2023 8:49:31 | AK35: 0 | AL35: 0 | AN35: 1 | AO35: 7500000 | AP35: 273040 | AQ35: 3946 | AR35: 7776986 | AS35: 9290000 | AT35: 1513014 | AU35: 1629
A36: IMPORTADORA TRENTO LTDA | B36: LOCAL USADOS | C36: 1892 | D36: 36216 | E36: Facturada | F36: 09-02-2023 12:41:03 | G36: Factura Exenta Electrónica (62086) | H36: VANESSA CASANGA CASTILLO | I36: 03-02-2023 17:48:30 | J36: 13-02-2023 0:00:00 | K36: ...+-*+/*-....... | L36: PEUGEOT | M36: 2008 | N36: 2008 ALLURE BLUEHDI 1.6 | O36: pmu1 | P36: 2017 | Q36: 89000 | R36: TPESTWU000311 | S36: JCDG98 | T36: USADO | U36: ROJO ULTIMATE | V36: POR DEFINIR | W36: 10590000 | X36: Facturado | Y36: 10 | Z36: DISPONIBLE | AA36: BODEGA VEHICULOS | AC36: 10JBHA0187931 | AD36: VF3CUBHY6HY002129 | AE36: GUILLERMO SANCHEZ MUÑOZ | AF36: 03-02-2023 0:00:00 | AG36: 1 | AH36: 03-02-2023 0:00:00 | AI36: 03-02-2023 17:48:04 | AK36: 0 | AL36: 0 | AN36: 0 | AO36: 8500000 | AP36: 288040 | AQ36: 3652 | AR36: 8791692 | AS36: 10590000 | AT36: 1798308 | AU36: 1698
A37: IMPORTADORA TRENTO LTDA | B37: LOCAL USADOS | C37: 1892 | D37: 36216 | E37: Facturada | F37: 09-02-2023 12:41:03 | G37: Factura Exenta Electrónica (62086) | H37: VANESSA CASANGA CASTILLO | I37: 03-02-2023 17:48:30 | J37: 13-02-2023 0:00:00 | K37: ...+-*+/*-....... | L37: PEUGEOT | M37: 2008 | N37: 2008 ALLURE BLUEHDI 1.6 | O37: pmu1 | P37: 2017 | Q37: 89000 | R37: TPESTWU000311 | S37: JCDG98 | T37: USADO | U37: ROJO ULTIMATE | V37: POR DEFINIR | W37: 10590000 | X37: Facturado | Y37: 10 | Z37: DISPONIBLE | AA37: BODEGA VEHICULOS | AC37: 10JBHA0187931 | AD37: VF3CUBHY6HY002129 | AE37: GUILLERMO SANCHEZ MUÑOZ | AF37: 03-02-2023 0:00:00 | AG37: 1 | AH37: 03-02-2023 0:00:00 | AI37: 03-02-2023 17:48:04 | AK37: 0 | AL37: 0 | AN37: 0 | AO37: 8500000 | AP37: 288040 | AQ37: 3652 | AR37: 8791692 | AS37: 10590000 | AT37: 1798308 | AU37: 1698
A38: IMPORTADORA TRENTO LTDA | B38: LOCAL USADOS | C38: 2006 | D38: 38964 | E38: Facturada | F38: 31-10-2023 18:55:41 | G38: Factura Exenta Electrónica (63378) | H38: FEDERICO ALBERT | I38: 31-10-2023 16:43:42 | J38: 31-10-2023 0:00:00 | K38: JN1JBAT32JW013654 | L38: NISSAN | M38: XTRAIL | N38: X TRAIL SENSE 2.5 AUT | O38: XUSADO | P38: 2018 | Q38: 0 | R38: TNISTWU000510 | S38: JXGD53 | T38: USADO | U38: GRIS METALICO | V38: POR DEFINIR | W38: 11690000 | X38: Facturado | Y38: 0 | Z38: DISPONIBLE | AA38: BODEGA VEHICULOS | AC38: QR25006200M | AD38: JN1JBAT32JW013654 | AE38: JORGE EDUARDO CONTRERAS ROBLES | AF38: 31-10-2023 0:00:00 | AG38: 1 | AH38: 31-10-2023 0:00:00 | AI38: 31-10-2023 16:43:18 | AK38: 0 | AL38: 0 | AN38: 0 | AO38: 9000000 | AP38: 295540 | AQ38: 3999 | AR38: 9299539 | AS38: 11690000 | AT38: 2390461 | AU38: 2045
A39: IMPORTADORA TRENTO LTDA | B39: LOCAL USADOS | C39: 2006 | D39: 38964 | E39: Facturada | F39: 31-10-2023 18:55:41 | G39: Factura Exenta Electrónica (63378) | H39: FEDERICO ALBERT | I39: 31-10-2023 16:43:42 | J39: 31-10-2023 0:00:00 | K39: JN1JBAT32JW013654 | L39: NISSAN | M39: XTRAIL | N39: X TRAIL SENSE 2.5 AUT | O39: XUSADO | P39: 2018 | Q39: 0 | R39: TNISTWU000510 | S39: JXGD53 | T39: USADO | U39: GRIS METALICO | V39: POR DEFINIR | W39: 11690000 | X39: Facturado | Y39: 0 | Z39: DISPONIBLE | AA39: BODEGA VEHICULOS | AC39: QR25006200M | AD39: JN1JBAT32JW013654 | AE39: JORGE EDUARDO CONTRERAS ROBLES | AF39: 31-10-2023 0:00:00 | AG39: 1 | AH39: 31-10-2023 0:00:00 | AI39: 31-10-2023 16:43:18 | AK39: 0 | AL39: 0 | AN39: 0 | AO39: 9000000 | AP39: 295540 | AQ39: 3999 | AR39: 9299539 | AS39: 11690000 | AT39: 2390461 | AU39: 2045
A40: IMPORTADORA TRENTO LTDA | B40: LOCAL USADOS | C40: 0 | D40: 0 | I40: 02-09-2025 10:22:59 | K40: ////////..**/++++ | L40: SUZUKI | M40: BALENO | N40: BALENO 4X2 1.5 | O40: SZBAL4X215 | P40: 2024 | Q40: 15000 | R40: TSZAUTU000454 | S40: TJSK21 | T40: USADO | U40: BLANCO PERLA | V40: POR DEFINIR | W40: 11290000 | X40: Retirado Stock | Y40: 0 | Z40: NO DISPONIBLE | AA40: BODEGA VEHICULOS | AB40: AE,CC,EE,2AB,NB,ABS,LL,AC,AISO,AAUTO,CRE,MAV,ACD,S | AC40: K15BN1460866 | AD40: MBHWBA3S1SG665159 | AE40: HECTOR ARMANDO MOYA ROMERO | AF40: 02-09-2025 0:00:00 | AG40: 0 | AK40: 1 | AL40: 0 | AN40: 0 | AO40: 0 | AP40: 0 | AQ40: 0 | AR40: 0 | AS40: 11290000 | AT40: 11290000 | AU40: 100
...
