Workbook

Sheet BBDD2
A1: Marca | B1: Modelo | C1: Versión | D1: Estado Dealer | E1: Año | F1: Placa Patente | G1: Días Stock | H1: Kilometraje | I1: Empresa | J1: Modelo-versión-año | K1: Precio toma historico | L1: Precio toma historico autored | M1: Precio unidad venta | N1: Precio Lista informe stock | O1: Precio Mercado | P1: Precio Compra Neto Informe Stock | Q1: Total Costo Informe Stock | R1: Tipo rotación
A2: AUDI | B2: Q2 | C2: Q2 35 TFSI 1.4 AUT | D2: DISPONIBLE | E2: 2023 | F2: SPZD69 | G2: 47 | H2: 58362 | I2: IMPORTADORA TRENTO LTDA | J2: =CONCATENATE(B2,C2,E2) -> Q2Q2 35 TFSI 1.4 AUT2023 | L2: =IFERROR(_xlfn.XLOOKUP(F2,'PRECIO TOMA HISTORICO '!$A:$A,'PRECIO TOMA HISTORICO '!$B:$B,_xlfn.XLOOKUP(F2,BBDD!$S:$S,BBDD!$AO:$AO,"",0,1),0,-1),"") -> 16700000 | N2: =_xlfn.XLOOKUP(F2,BBDD!$S:$S,BBDD!$AS:$AS) -> 20990000 | O2: =IFERROR(VLOOKUP(F2,'PRECIO MERCADO'!D:E,2,0),"0") -> 22400000 | P2: =_xlfn.XLOOKUP(F2,BBDD!$S:$S,BBDD!$AO:$AO) -> 16500000 | Q2: =_xlfn.XLOOKUP(F2,BBDD!$S:$S,BBDD!$AR:$AR) -> 16876740 | R2: =IF(G2<=30,"ROTACION ALTA",IF(G2<30,"ROTACION MEDIA",IF(G2<60,"ROTACION BAJA",IF(G2>60,"LIQUIDAR")))) -> ROTACION BAJA
A3: BAIC | B3: BJ30 | C3: BJ30 LV5 AWD HEV | D3: EN PREPARACION | E3: 2026 | F3: VSWT54 | G3: 228 | H3: 2500 | I3: CALLEGARI E HIJOS LTDA | J3: =CONCATENATE(B3,C3,E3) -> BJ30BJ30 LV5 AWD HEV2026 | L3: =IFERROR(_xlfn.XLOOKUP(F3,'PRECIO TOMA HISTORICO '!$A:$A,'PRECIO TOMA HISTORICO '!$B:$B,_xlfn.XLOOKUP(F3,BBDD!$S:$S,BBDD!$AO:$AO,"",0,1),0,-1),"") -> 21210924 | N3: =_xlfn.XLOOKUP(F3,BBDD!$S:$S,BBDD!$AS:$AS) -> 24900000 | O3: =IFERROR(VLOOKUP(F3,'PRECIO MERCADO'!D:E,2,0),"0") -> 20000000 | P3: =_xlfn.XLOOKUP(F3,BBDD!$S:$S,BBDD!$AO:$AO) -> 21210924 | Q3: =_xlfn.XLOOKUP(F3,BBDD!$S:$S,BBDD!$AR:$AR) -> 22186979 | R3: =IF(G3<=30,"ROTACION ALTA",IF(G3<30,"ROTACION MEDIA",IF(G3<60,"ROTACION BAJA",IF(G3>60,"LIQUIDAR")))) -> LIQUIDAR
A4: BAIC | B4: BJ60 | C4: BJ60 FLAGSHIP 7P MHEV (Mild Hybrid) | D4: EN PREPARACION | E4: 2026 | F4: TGVT33 | G4: 228 | H4: 5200 | I4: CALLEGARI E HIJOS LTDA | J4: =CONCATENATE(B4,C4,E4) -> BJ60BJ60 FLAGSHIP 7P MHEV (Mild Hybrid)2026 | L4: =IFERROR(_xlfn.XLOOKUP(F4,'PRECIO TOMA HISTORICO '!$A:$A,'PRECIO TOMA HISTORICO '!$B:$B,_xlfn.XLOOKUP(F4,BBDD!$S:$S,BBDD!$AO:$AO,"",0,1),0,-1),"") -> 37849580 | N4: =_xlfn.XLOOKUP(F4,BBDD!$S:$S,BBDD!$AS:$AS) -> 44800000 | O4: =IFERROR(VLOOKUP(F4,'PRECIO MERCADO'!D:E,2,0),"0") -> 43800000 | P4: =_xlfn.XLOOKUP(F4,BBDD!$S:$S,BBDD!$AO:$AO) -> 37849580 | Q4: =_xlfn.XLOOKUP(F4,BBDD!$S:$S,BBDD!$AR:$AR) -> 39771286 | R4: =IF(G4<=30,"ROTACION ALTA",IF(G4<30,"ROTACION MEDIA",IF(G4<60,"ROTACION BAJA",IF(G4>60,"LIQUIDAR")))) -> LIQUIDAR
A5: BAIC | B5: X7 | C5: X7 EXCLUSIVE | D5: EN PREPARACION | E5: 2026 | F5: VSWT56 | G5: 228 | H5: 900 | I5: CALLEGARI E HIJOS LTDA | J5: =CONCATENATE(B5,C5,E5) -> X7X7 EXCLUSIVE2026 | L5: =IFERROR(_xlfn.XLOOKUP(F5,'PRECIO TOMA HISTORICO '!$A:$A,'PRECIO TOMA HISTORICO '!$B:$B,_xlfn.XLOOKUP(F5,BBDD!$S:$S,BBDD!$AO:$AO,"",0,1),0,-1),"") -> 19320168 | N5: =_xlfn.XLOOKUP(F5,BBDD!$S:$S,BBDD!$AS:$AS) -> 22490000 | O5: =IFERROR(VLOOKUP(F5,'PRECIO MERCADO'!D:E,2,0),"0") -> 21800000 | P5: =_xlfn.XLOOKUP(F5,BBDD!$S:$S,BBDD!$AO:$AO) -> 19320168 | Q5: =_xlfn.XLOOKUP(F5,BBDD!$S:$S,BBDD!$AR:$AR) -> 20341262 | R5: =IF(G5<=30,"ROTACION ALTA",IF(G5<30,"ROTACION MEDIA",IF(G5<60,"ROTACION BAJA",IF(G5>60,"LIQUIDAR")))) -> LIQUIDAR
A6: BYD | B6: SONG PLUS DM-i | C6: SONG PLUS 4X2 1.5 AUT | D6: DISPONIBLE | E6: 2024 | F6: TJDC55 | G6: 250 | H6: 30000 | I6: IMPORTADORA TRENTO LTDA | J6: =CONCATENATE(B6,C6,E6) -> SONG PLUS DM-iSONG PLUS 4X2 1.5 AUT2024 | L6: =IFERROR(_xlfn.XLOOKUP(F6,'PRECIO TOMA HISTORICO '!$A:$A,'PRECIO TOMA HISTORICO '!$B:$B,_xlfn.XLOOKUP(F6,BBDD!$S:$S,BBDD!$AO:$AO,"",0,1),0,-1),"") -> 20000000 | N6: =_xlfn.XLOOKUP(F6,BBDD!$S:$S,BBDD!$AS:$AS) -> 20990000 | O6: =IFERROR(VLOOKUP(F6,'PRECIO MERCADO'!D:E,2,0),"0") -> 22100000 | P6: =_xlfn.XLOOKUP(F6,BBDD!$S:$S,BBDD!$AO:$AO) -> 20000000 | Q6: =_xlfn.XLOOKUP(F6,BBDD!$S:$S,BBDD!$AR:$AR) -> 20524003 | R6: =IF(G6<=30,"ROTACION ALTA",IF(G6<30,"ROTACION MEDIA",IF(G6<60,"ROTACION BAJA",IF(G6>60,"LIQUIDAR")))) -> LIQUIDAR
A7: BYD | B7: SONG PLUS DM-i | C7: SONG PLUS GS | D7: DEMO/INTERNO | E7: 2024 | F7: TJSJ84 | G7: 403 | H7: 19482 | I7: SOC. HERMANAS CALLEGARI LTDA | J7: =CONCATENATE(B7,C7,E7) -> SONG PLUS DM-iSONG PLUS GS2024 | L7: =IFERROR(_xlfn.XLOOKUP(F7,'PRECIO TOMA HISTORICO '!$A:$A,'PRECIO TOMA HISTORICO '!$B:$B,_xlfn.XLOOKUP(F7,BBDD!$S:$S,BBDD!$AO:$AO,"",0,1),0,-1),"") -> 29403361 | N7: =_xlfn.XLOOKUP(F7,BBDD!$S:$S,BBDD!$AS:$AS) -> 28990000 | O7: =IFERROR(VLOOKUP(F7,'PRECIO MERCADO'!D:E,2,0),"0") -> 24700000 | P7: =_xlfn.XLOOKUP(F7,BBDD!$S:$S,BBDD!$AO:$AO) -> 29403361 | Q7: =_xlfn.XLOOKUP(F7,BBDD!$S:$S,BBDD!$AR:$AR) -> 30640616 | R7: =IF(G7<=30,"ROTACION ALTA",IF(G7<30,"ROTACION MEDIA",IF(G7<60,"ROTACION BAJA",IF(G7>60,"LIQUIDAR")))) -> LIQUIDAR
A8: BYD | B8: YUAN PLUS EV | C8: YUAN PLUS EV GS | D8: DEMO/INTERNO | E8: 2024 | F8: SYPY23 | G8: 960 | H8: 15100 | I8: SOC. HERMANAS CALLEGARI LTDA | J8: =CONCATENATE(B8,C8,E8) -> YUAN PLUS EVYUAN PLUS EV GS2024 | L8: =IFERROR(_xlfn.XLOOKUP(F8,'PRECIO TOMA HISTORICO '!$A:$A,'PRECIO TOMA HISTORICO '!$B:$B,_xlfn.XLOOKUP(F8,BBDD!$S:$S,BBDD!$AO:$AO,"",0,1),0,-1),"") -> 30243697 | N8: =_xlfn.XLOOKUP(F8,BBDD!$S:$S,BBDD!$AS:$AS) -> 19790000 | O8: =IFERROR(VLOOKUP(F8,'PRECIO MERCADO'!D:E,2,0),"0") -> 19700000 | P8: =_xlfn.XLOOKUP(F8,BBDD!$S:$S,BBDD!$AO:$AO) -> 30243697 | Q8: =_xlfn.XLOOKUP(F8,BBDD!$S:$S,BBDD!$AR:$AR) -> 31091577 | R8: =IF(G8<=30,"ROTACION ALTA",IF(G8<30,"ROTACION MEDIA",IF(G8<60,"ROTACION BAJA",IF(G8>60,"LIQUIDAR")))) -> LIQUIDAR
A9: CHANGAN | B9: CS15 | C9: CS15 HB 4X2 1.5 | D9: EN TALLER | E9: 2021 | F9: RJDX35 | G9: 64 | H9: 90000 | I9: IMPORTADORA TRENTO LTDA | J9: =CONCATENATE(B9,C9,E9) -> CS15CS15 HB 4X2 1.52021 | L9: =IFERROR(_xlfn.XLOOKUP(F9,'PRECIO TOMA HISTORICO '!$A:$A,'PRECIO TOMA HISTORICO '!$B:$B,_xlfn.XLOOKUP(F9,BBDD!$S:$S,BBDD!$AO:$AO,"",0,1),0,-1),"") -> 5200000 | N9: =_xlfn.XLOOKUP(F9,BBDD!$S:$S,BBDD!$AS:$AS) -> 7290000 | O9: =IFERROR(VLOOKUP(F9,'PRECIO MERCADO'!D:E,2,0),"0") -> 7290000 | P9: =_xlfn.XLOOKUP(F9,BBDD!$S:$S,BBDD!$AO:$AO) -> 5200000 | Q9: =_xlfn.XLOOKUP(F9,BBDD!$S:$S,BBDD!$AR:$AR) -> 5407240 | R9: =IF(G9<=30,"ROTACION ALTA",IF(G9<30,"ROTACION MEDIA",IF(G9<60,"ROTACION BAJA",IF(G9>60,"LIQUIDAR")))) -> LIQUIDAR
A10: CHANGAN | B10: HUNTER | C10: HUNTER 4X4 2.0 | D10: DISPONIBLE | E10: 2026 | F10: VRHK60 | G10: 14 | H10: 5250 | I10: IMPORTADORA TRENTO LTDA | J10: =CONCATENATE(B10,C10,E10) -> HUNTERHUNTER 4X4 2.02026 | L10: =IFERROR(_xlfn.XLOOKUP(F10,'PRECIO TOMA HISTORICO '!$A:$A,'PRECIO TOMA HISTORICO '!$B:$B,_xlfn.XLOOKUP(F10,BBDD!$S:$S,BBDD!$AO:$AO,"",0,1),0,-1),"") -> 15000000 | N10: =_xlfn.XLOOKUP(F10,BBDD!$S:$S,BBDD!$AS:$AS) -> 17990000 | O10: =IFERROR(VLOOKUP(F10,'PRECIO MERCADO'!D:E,2,0),"0") -> 17100000 | P10: =_xlfn.XLOOKUP(F10,BBDD!$S:$S,BBDD!$AO:$AO) -> 15000000 | Q10: =_xlfn.XLOOKUP(F10,BBDD!$S:$S,BBDD!$AR:$AR) -> 15354240 | R10: =IF(G10<=30,"ROTACION ALTA",IF(G10<30,"ROTACION MEDIA",IF(G10<60,"ROTACION BAJA",IF(G10>60,"LIQUIDAR")))) -> ROTACION ALTA
A11: CHANGAN | B11: MS201 | C11: MS201 DCAB 1.2 | D11: EN PREPARACION | E11: 2023 | F11: SDYB13 | G11: 6 | H11: 34836 | I11: IMPORTADORA TRENTO LTDA | J11: =CONCATENATE(B11,C11,E11) -> MS201MS201 DCAB 1.22023 | L11: =IFERROR(_xlfn.XLOOKUP(F11,'PRECIO TOMA HISTORICO '!$A:$A,'PRECIO TOMA HISTORICO '!$B:$B,_xlfn.XLOOKUP(F11,BBDD!$S:$S,BBDD!$AO:$AO,"",0,1),0,-1),"") -> 5100000 | N11: =_xlfn.XLOOKUP(F11,BBDD!$S:$S,BBDD!$AS:$AS) -> 6290000 | O11: =IFERROR(VLOOKUP(F11,'PRECIO MERCADO'!D:E,2,0),"0") -> 7060000 | P11: =_xlfn.XLOOKUP(F11,BBDD!$S:$S,BBDD!$AO:$AO) -> 5100000 | Q11: =_xlfn.XLOOKUP(F11,BBDD!$S:$S,BBDD!$AR:$AR) -> 5305740 | R11: =IF(G11<=30,"ROTACION ALTA",IF(G11<30,"ROTACION MEDIA",IF(G11<60,"ROTACION BAJA",IF(G11>60,"LIQUIDAR")))) -> ROTACION ALTA
A12: CHANGAN | B12: X7 | C12: X7 PLUS TURBO 1.5 | D12: EN PREPARACION | E12: 2026 | F12: VLYP47 | G12: 21 | H12: 15600 | I12: IMPORTADORA TRENTO LTDA | J12: =CONCATENATE(B12,C12,E12) -> X7X7 PLUS TURBO 1.52026 | L12: =IFERROR(_xlfn.XLOOKUP(F12,'PRECIO TOMA HISTORICO '!$A:$A,'PRECIO TOMA HISTORICO '!$B:$B,_xlfn.XLOOKUP(F12,BBDD!$S:$S,BBDD!$AO:$AO,"",0,1),0,-1),"") -> 11550000 | N12: =_xlfn.XLOOKUP(F12,BBDD!$S:$S,BBDD!$AS:$AS) -> 14200000 | O12: =IFERROR(VLOOKUP(F12,'PRECIO MERCADO'!D:E,2,0),"0") -> 14400000 | P12: =_xlfn.XLOOKUP(F12,BBDD!$S:$S,BBDD!$AO:$AO) -> 11550000 | Q12: =_xlfn.XLOOKUP(F12,BBDD!$S:$S,BBDD!$AR:$AR) -> 11852490 | R12: =IF(G12<=30,"ROTACION ALTA",IF(G12<30,"ROTACION MEDIA",IF(G12<60,"ROTACION BAJA",IF(G12>60,"LIQUIDAR")))) -> ROTACION ALTA
A13: CHERY | B13: TIGGO 2 | C13: TIGGO 2 1.5 | D13: DISPONIBLE | E13: 2021 | F13: PPPB53 | G13: 14 | H13: 30197 | I13: IMPORTADORA TRENTO LTDA | J13: =CONCATENATE(B13,C13,E13) -> TIGGO 2TIGGO 2 1.52021 | L13: =IFERROR(_xlfn.XLOOKUP(F13,'PRECIO TOMA HISTORICO '!$A:$A,'PRECIO TOMA HISTORICO '!$B:$B,_xlfn.XLOOKUP(F13,BBDD!$S:$S,BBDD!$AO:$AO,"",0,1),0,-1),"") -> 6000000 | N13: =_xlfn.XLOOKUP(F13,BBDD!$S:$S,BBDD!$AS:$AS) -> 7290000 | O13: =IFERROR(VLOOKUP(F13,'PRECIO MERCADO'!D:E,2,0),"0") -> 7310000 | P13: =_xlfn.XLOOKUP(F13,BBDD!$S:$S,BBDD!$AO:$AO) -> 6000000 | Q13: =_xlfn.XLOOKUP(F13,BBDD!$S:$S,BBDD!$AR:$AR) -> 6219240 | R13: =IF(G13<=30,"ROTACION ALTA",IF(G13<30,"ROTACION MEDIA",IF(G13<60,"ROTACION BAJA",IF(G13>60,"LIQUIDAR")))) -> ROTACION ALTA
... A262: SSANGYONG | B262: TORRES | C262: TORRES 4X2 1.5 | D262: DISPONIBLE | E262: 2024 | F262: TLRS70 | G262: 256 | H262: 35150 | I262: IMPORTADORA TRENTO LTDA | J262: =CONCATENATE(B262,C262,E262) -> TORRESTORRES 4X2 1.52024 | L262: =IFERROR(_xlfn.XLOOKUP(F262,'PRECIO TOMA HISTORICO '!$A:$A,'PRECIO TOMA HISTORICO '!$B:$B,_xlfn.XLOOKUP(F262,BBDD!$S:$S,BBDD!$AO:$AO,"",0,1),0,-1),"") -> 16400000 | N262: =_xlfn.XLOOKUP(F262,BBDD!$S:$S,BBDD!$AS:$AS) -> 17490000 | O262: =IFERROR(VLOOKUP(F262,'PRECIO MERCADO'!D:E,2,0),"0") -> 19300000 | P262: =_xlfn.XLOOKUP(F262,BBDD!$S:$S,BBDD!$AO:$AO) -> 16400000 | Q262: =_xlfn.XLOOKUP(F262,BBDD!$S:$S,BBDD!$AR:$AR) -> 16772030 | R262: =IF(G262<=30,"ROTACION ALTA",IF(G262<30,"ROTACION MEDIA",IF(G262<60,"ROTACION BAJA",IF(G262>60,"LIQUIDAR")))) -> LIQUIDAR
A263: SUBARU | B263: FORESTER | C263: FORESTER 4X4 2.0 AT | E263: 2023 | F263: SFLW10 | G263: 14 | H263: 60800 | I263: IMPORTADORA TRENTO LTDA | J263: =CONCATENATE(B263,C263,E263) -> FORESTERFORESTER 4X4 2.0 AT2023 | L263: =IFERROR(_xlfn.XLOOKUP(F263,'PRECIO TOMA HISTORICO '!$A:$A,'PRECIO TOMA HISTORICO '!$B:$B,_xlfn.XLOOKUP(F263,BBDD!$S:$S,BBDD!$AO:$AO,"",0,1),0,-1),"") -> 19000000 | N263: =_xlfn.XLOOKUP(F263,BBDD!$S:$S,BBDD!$AS:$AS) -> 22490000 | O263: =IFERROR(VLOOKUP(F263,'PRECIO MERCADO'!D:E,2,0),"0") -> 22500000 | P263: =_xlfn.XLOOKUP(F263,BBDD!$S:$S,BBDD!$AO:$AO) -> 19000000 | Q263: =_xlfn.XLOOKUP(F263,BBDD!$S:$S,BBDD!$AR:$AR) -> 19414240 | R263: =IF(G263<=30,"ROTACION ALTA",IF(G263<30,"ROTACION MEDIA",IF(G263<60,"ROTACION BAJA",IF(G263>60,"LIQUIDAR")))) -> ROTACION ALTA
A264: SUBARU | B264: FORESTER | C264: FORESTER 4X4 2.0 AT | D264: DISPONIBLE | E264: 2024 | F264: TPCS18 | G264: 111 | H264: 76000 | I264: IMPORTADORA TRENTO LTDA | J264: =CONCATENATE(B264,C264,E264) -> FORESTERFORESTER 4X4 2.0 AT2024 | L264: =IFERROR(_xlfn.XLOOKUP(F264,'PRECIO TOMA HISTORICO '!$A:$A,'PRECIO TOMA HISTORICO '!$B:$B,_xlfn.XLOOKUP(F264,BBDD!$S:$S,BBDD!$AO:$AO,"",0,1),0,-1),"") -> 19000000 | N264: =_xlfn.XLOOKUP(F264,BBDD!$S:$S,BBDD!$AS:$AS) -> 20490000 | O264: =IFERROR(VLOOKUP(F264,'PRECIO MERCADO'!D:E,2,0),"0") -> 20900000 | P264: =_xlfn.XLOOKUP(F264,BBDD!$S:$S,BBDD!$AO:$AO) -> 19000000 | Q264: =_xlfn.XLOOKUP(F264,BBDD!$S:$S,BBDD!$AR:$AR) -> 19414240 | R264: =IF(G264<=30,"ROTACION ALTA",IF(G264<30,"ROTACION MEDIA",IF(G264<60,"ROTACION BAJA",IF(G264>60,"LIQUIDAR")))) -> LIQUIDAR
A265: SUBARU | B265: FORESTER | C265: FORESTER 4X4 2.0 AT | D265: EN PREPARACION | E265: 2023 | F265: SGTD48 | G265: 19 | H265: 48000 | I265: IMPORTADORA TRENTO LTDA | J265: =CONCATENATE(B265,C265,E265) -> FORESTERFORESTER 4X4 2.0 AT2023 | L265: =IFERROR(_xlfn.XLOOKUP(F265,'PRECIO TOMA HISTORICO '!$A:$A,'PRECIO TOMA HISTORICO '!$B:$B,_xlfn.XLOOKUP(F265,BBDD!$S:$S,BBDD!$AO:$AO,"",0,1),0,-1),"") -> 17000000 | N265: =_xlfn.XLOOKUP(F265,BBDD!$S:$S,BBDD!$AS:$AS) -> 22490000 | O265: =IFERROR(VLOOKUP(F265,'PRECIO MERCADO'!D:E,2,0),"0") -> 23100000 | P265: =_xlfn.XLOOKUP(F265,BBDD!$S:$S,BBDD!$AO:$AO) -> 17000000 | Q265: =_xlfn.XLOOKUP(F265,BBDD!$S:$S,BBDD!$AR:$AR) -> 17384240 | R265: =IF(G265<=30,"ROTACION ALTA",IF(G265<30,"ROTACION MEDIA",IF(G265<60,"ROTACION BAJA",IF(G265>60,"LIQUIDAR")))) -> ROTACION ALTA
A266: SUBARU | B266: FORESTER | C266: FORESTER CVT 4X4 2.0 AUT | D266: EN PREPARACION | E266: 2020 | F266: PJDF47 | G266: 18 | H266: 47000 | I266: IMPORTADORA TRENTO LTDA | J266: =CONCATENATE(B266,C266,E266) -> FORESTERFORESTER CVT 4X4 2.0 AUT2020 | L266: =IFERROR(_xlfn.XLOOKUP(F266,'PRECIO TOMA HISTORICO '!$A:$A,'PRECIO TOMA HISTORICO '!$B:$B,_xlfn.XLOOKUP(F266,BBDD!$S:$S,BBDD!$AO:$AO,"",0,1),0,-1),"") -> 15700000 | N266: =_xlfn.XLOOKUP(F266,BBDD!$S:$S,BBDD!$AS:$AS) -> 17990000 | O266: =IFERROR(VLOOKUP(F266,'PRECIO MERCADO'!D:E,2,0),"0") -> 18800000 | P266: =_xlfn.XLOOKUP(F266,BBDD!$S:$S,BBDD!$AO:$AO) -> 15700000 | Q266: =_xlfn.XLOOKUP(F266,BBDD!$S:$S,BBDD!$AR:$AR) -> 16064740 | R266: =IF(G266<=30,"ROTACION ALTA",IF(G266<30,"ROTACION MEDIA",IF(G266<60,"ROTACION BAJA",IF(G266>60,"LIQUIDAR")))) -> ROTACION ALTA
A267: SUBARU | B267: XV | C267: NEW XV 2.0I AWD CVT DYNAMIC | D267: NO DISPONIBLE | E267: 2019 | F267: LBGX66 | G267: 1411 | H267: 6400 | I267: CALLEGARI E HIJOS LTDA | J267: =CONCATENATE(B267,C267,E267) -> XVNEW XV 2.0I AWD CVT DYNAMIC2019 | L267: =IFERROR(_xlfn.XLOOKUP(F267,'PRECIO TOMA HISTORICO '!$A:$A,'PRECIO TOMA HISTORICO '!$B:$B,_xlfn.XLOOKUP(F267,BBDD!$S:$S,BBDD!$AO:$AO,"",0,1),0,-1),"") -> 12497480 | N267: =_xlfn.XLOOKUP(F267,BBDD!$S:$S,BBDD!$AS:$AS) -> 15900000 | O267: =IFERROR(VLOOKUP(F267,'PRECIO MERCADO'!D:E,2,0),"0") -> 15500000 | P267: =_xlfn.XLOOKUP(F267,BBDD!$S:$S,BBDD!$AO:$AO) -> 12497480 | Q267: =_xlfn.XLOOKUP(F267,BBDD!$S:$S,BBDD!$AR:$AR) -> 15632904 | R267: =IF(G267<=30,"ROTACION ALTA",IF(G267<30,"ROTACION MEDIA",IF(G267<60,"ROTACION BAJA",IF(G267>60,"LIQUIDAR")))) -> LIQUIDAR
A268: TOYOTA | B268: RAV | C268: RAV4 CVT 2.0 | D268: EN PREPARACION | E268: 2024 | F268: SYRB80 | G268: 76 | H268: 56985 | I268: IMPORTADORA TRENTO LTDA | J268: =CONCATENATE(B268,C268,E268) -> RAVRAV4 CVT 2.02024 | L268: =IFERROR(_xlfn.XLOOKUP(F268,'PRECIO TOMA HISTORICO '!$A:$A,'PRECIO TOMA HISTORICO '!$B:$B,_xlfn.XLOOKUP(F268,BBDD!$S:$S,BBDD!$AO:$AO,"",0,1),0,-1),"") -> 17000000 | N268: =_xlfn.XLOOKUP(F268,BBDD!$S:$S,BBDD!$AS:$AS) -> 20290000 | O268: =IFERROR(VLOOKUP(F268,'PRECIO MERCADO'!D:E,2,0),"0") -> 21800000 | P268: =_xlfn.XLOOKUP(F268,BBDD!$S:$S,BBDD!$AO:$AO) -> 17000000 | Q268: =_xlfn.XLOOKUP(F268,BBDD!$S:$S,BBDD!$AR:$AR) -> 17384240 | R268: =IF(G268<=30,"ROTACION ALTA",IF(G268<30,"ROTACION MEDIA",IF(G268<60,"ROTACION BAJA",IF(G268>60,"LIQUIDAR")))) -> LIQUIDAR
A269: VOLKSWAGEN | B269: AMAROK | C269: AMAROK DCAB TDI DOHC 4X4 2.0 AUT | D269: NO DISPONIBLE | E269: 2023 | F269: SRHZ99 | G269: 868 | H269: 15600 | I269: IMPORTADORA TRENTO LTDA | J269: =CONCATENATE(B269,C269,E269) -> AMAROKAMAROK DCAB TDI DOHC 4X4 2.0 AUT2023 | L269: =IFERROR(_xlfn.XLOOKUP(F269,'PRECIO TOMA HISTORICO '!$A:$A,'PRECIO TOMA HISTORICO '!$B:$B,_xlfn.XLOOKUP(F269,BBDD!$S:$S,BBDD!$AO:$AO,"",0,1),0,-1),"") -> 28500000 | N269: =_xlfn.XLOOKUP(F269,BBDD!$S:$S,BBDD!$AS:$AS) -> 33190000 | O269: =IFERROR(VLOOKUP(F269,'PRECIO MERCADO'!D:E,2,0),"0") -> 31500000 | P269: =_xlfn.XLOOKUP(F269,BBDD!$S:$S,BBDD!$AO:$AO) -> 28500000 | Q269: =_xlfn.XLOOKUP(F269,BBDD!$S:$S,BBDD!$AR:$AR) -> 29597663 | R269: =IF(G269<=30,"ROTACION ALTA",IF(G269<30,"ROTACION MEDIA",IF(G269<60,"ROTACION BAJA",IF(G269>60,"LIQUIDAR")))) -> LIQUIDAR
A270: VOLKSWAGEN | B270: GOLF | C270: GOLF HB 1.4 AUT | D270: NO DISPONIBLE | E270: 2016 | F270: HTSJ81 | G270: 46 | H270: 80000 | I270: IMPORTADORA TRENTO LTDA | J270: =CONCATENATE(B270,C270,E270) -> GOLFGOLF HB 1.4 AUT2016 | L270: =IFERROR(_xlfn.XLOOKUP(F270,'PRECIO TOMA HISTORICO '!$A:$A,'PRECIO TOMA HISTORICO '!$B:$B,_xlfn.XLOOKUP(F270,BBDD!$S:$S,BBDD!$AO:$AO,"",0,1),0,-1),"") -> 6600000 | N270: =_xlfn.XLOOKUP(F270,BBDD!$S:$S,BBDD!$AS:$AS) -> 8990000 | O270: =IFERROR(VLOOKUP(F270,'PRECIO MERCADO'!D:E,2,0),"0") -> 10100000 | P270: =_xlfn.XLOOKUP(F270,BBDD!$S:$S,BBDD!$AO:$AO) -> 6600000 | Q270: =_xlfn.XLOOKUP(F270,BBDD!$S:$S,BBDD!$AR:$AR) -> 6828240 | R270: =IF(G270<=30,"ROTACION ALTA",IF(G270<30,"ROTACION MEDIA",IF(G270<60,"ROTACION BAJA",IF(G270>60,"LIQUIDAR")))) -> ROTACION BAJA
A271: ZX AUTO | B271: TERRALORD | C271: TERRALORD 4X4 2.5 AUT | D271: NO DISPONIBLE | E271: 2022 | F271: RSWX56 | G271: 162 | H271: 65000 | I271: IMPORTADORA TRENTO LTDA | J271: =CONCATENATE(B271,C271,E271) -> TERRALORDTERRALORD 4X4 2.5 AUT2022 | L271: =IFERROR(_xlfn.XLOOKUP(F271,'PRECIO TOMA HISTORICO '!$A:$A,'PRECIO TOMA HISTORICO '!$B:$B,_xlfn.XLOOKUP(F271,BBDD!$S:$S,BBDD!$AO:$AO,"",0,1),0,-1),"") -> 11500000 | N271: =_xlfn.XLOOKUP(F271,BBDD!$S:$S,BBDD!$AS:$AS) -> 13690000 | O271: =IFERROR(VLOOKUP(F271,'PRECIO MERCADO'!D:E,2,0),"0") -> 14100000 | P271: =_xlfn.XLOOKUP(F271,BBDD!$S:$S,BBDD!$AO:$AO) -> 11500000 | Q271: =_xlfn.XLOOKUP(F271,BBDD!$S:$S,BBDD!$AR:$AR) -> 11801740 | R271: =IF(G271<=30,"ROTACION ALTA",IF(G271<30,"ROTACION MEDIA",IF(G271<60,"ROTACION BAJA",IF(G271>60,"LIQUIDAR")))) -> LIQUIDAR

Sheet PRECIO TOMA HISTORICO 
A1: Patente | B1: Precio toma autored
A2: PFRX97 | B2: 14500000
A3: LSYG12 | B3: 15000000
A4: JZGD93 | B4: 17700000
A5: HRWV51 | B5: 20500000
A6: KLHJ78 | B6: 11000000
A7: PFSC16 | B7: 11700000
A8: SCGS82 | B8: 6500000
A9: LVXR90 | B9: 8000000
A10: LYPF74 | B10: 8000000
A11: LDVR65 | B11: 7700000
A12: RFVX24 | B12: 16000000
A13: RTLV30 | B13: 14800000
... A2472: VYCH76 | B2472: 8000000

Sheet PRECIO MERCADO
A1: FECHA CONSULTA | B1: MARCA | C1: MODELO | D1: PATENTE | E1: VALOR AUTOPRESS
A2: 2024-03-01 14:46:22 | B2: NISSAN | C2: QASHQAI | D2: SWTP31 | E2: 21800000
A3: 2024-03-01 14:51:13 | B3: PEUGEOT | C3: 3008 | D3: No informado | E3: 15400000
A4: 2024-03-01 14:53:18 | B4: FORD | C4: F-150 NEW | D4: KLPL67 | E4: 27800000
A5: 2024-03-01 14:54:44 | B5: CHERY | C5: TIGGO 7 | D5: RVPX58 | E5: 14100000
A6: 2024-03-01 14:57:14 | B6: FORD | C6: TERRITORY | D6: SVRR83 | E6: 16400000
A7: 2024-03-01 14:59:00 | B7: DFSK | C7: 500 | D7: SGXX60 | E7: 8800000
A8: 2024-03-01 15:02:52 | B8: DFSK | C8: 580 | D8: SYXS66 | E8: 12700000
A9: 2024-03-02 07:29:35 | B9: SSANGYONG | C9: NEW MUSSO | D9: RFKS23 | E9: 18000000
A10: 2024-03-02 07:31:21 | B10: KIA | C10: OPIRUS | D10: CDLV87 | E10: 5820000
A11: 2024-03-02 07:34:07 | B11: FORD | C11: F-150 NEW | D11: SPTC39 | E11: 43800000
A12: 2024-05-23 12:21:26 | B12: NISSAN | C12: NEW QASHQAI | D12: LLBT84 | E12: 11800000
A13: 2024-05-23 12:29:53 | B13: CHEVROLET | C13: ALL NEW TRACKER | D13: RSDZ65 | E13: 13400000
A14: 2025-06-19 09:51:03 | B14: HONDA | C14: HR-V | D14: PKTY15 | E14: 13100000
A15: 2025-12-23 06:11:20 | B15: FORD | C15: F-150 NEW | D15: TCTV39 | E15: 43400000
A16: 2025-12-23 06:50:57 | B16: FORD | C16: BRONCO | D16: No informado | E16: 48700000
A17: 2025-12-23 07:32:14 | B17: PEUGEOT | C17: NUEVO 308 | D17: SLRJ93 | E17: 16500000
A18: 2025-12-23 07:51:24 | B18: HYUNDAI | C18: ACCENT | D18: RDJS62 | E18: 10500000
A19: 2025-12-23 08:01:01 | B19: CHEVROLET | C19: ALL NEW TRACKER | D19: SBWS64 | E19: 11000000
A20: 2025-12-23 08:02:39 | B20: PEUGEOT | C20: 3008 | D20: LVCS57 | E20: 15000000
A21: 2025-12-23 08:19:28 | B21: MITSUBISHI | C21: MONTERO SPORT NEW | D21: LBVX49 | E21: 20200000
A22: 2025-12-23 08:27:10 | B22: FORD | C22: F-150 NEW | D22: TCTV39 | E22: 43400000
A23: 2025-12-23 09:07:44 | B23: JEEP | C23: GRAND CHEROKEE | D23: THRJ80 | E23: 43000000
A24: 2025-12-23 09:21:47 | B24: RENAULT | C24: KWID | D24: SJHZ88 | E24: 6780000
A25: 2025-12-23 09:31:04 | B25: PEUGEOT | C25: NUEVO 2008 | D25: RJCW76 | E25: 12400000
A26: 2025-12-23 09:37:46 | B26: PEUGEOT | C26: NUEVO 208 | D26: VBBD69 | E26: 19000000
A27: 2025-12-23 09:45:53 | B27: DFSK | C27: 560 | D27: RCBJ98 | E27: 8200000
A28: 2025-12-23 09:50:23 | B28: PEUGEOT | C28: NUEVO 3008 | D28: PRVP72 | E28: 15200000
A29: 2025-12-23 09:58:07 | B29: FORD | C29: NUEVO MUSTANG | D29: VDBS14 | E29: 45800000
A30: 2025-12-23 10:06:57 | B30: CHERY | C30: TIGGO 8 | D30: PSGB54 | E30: 11500000
A31: 2025-12-23 10:16:14 | B31: CHERY | C31: TIGGO 8 PRO | D31: SPPY18 | E31: 14700000
A32: 2025-12-23 10:30:51 | B32: TOYOTA | C32: COROLLA CROSS | D32: RVKL20 | E32: 23300000
A33: 2025-12-23 11:23:38 | B33: RAM | C33: 1500 | D33: SHLW33 | E33: 31400000
A34: 2025-12-23 11:29:51 | B34: NISSAN | C34: NUEVA X-TRAIL | D34: SHDG89 | E34: 20100000
A35: 2025-12-23 11:54:02 | B35: EXEED | C35: LX | D35: TRJC45 | E35: 14700000
A36: 2025-12-23 12:14:38 | B36: CHANGAN | C36: CS15 | D36: KTCV74 | E36: 5850000
A37: 2025-12-23 12:23:10 | B37: PEUGEOT | C37: 3008 | D37: TLRT68 | E37: 25800000
A38: 2025-12-23 13:16:31 | B38: CHERY | C38: TIGGO 2 | D38: RYDL24 | E38: 7600000
A39: 2025-12-24 07:06:40 | B39: KIA | C39: SOLUTO | D39: SYPS56 | E39: 8600000
A40: 2025-12-24 07:36:01 | B40: NISSAN | C40: QASHQAI | D40: RBXV26 | E40: 13000000
...

Sheet INFORME VENTAS
A1: Marca | B1: Modelo | C1: Versión | D1: Año | E1: Modelo-version-año | F1: Placa Patente | G1: Suma de Unidad Venta | H1: Suma de Unidad Costo
G2: 0 | H2: 0
A3: AUDI | B3: A3 | C3: A3 HB 1.4 AUT | D3: 2019 | E3: =CONCATENATE(B3,C3,D3) -> A3A3 HB 1.4 AUT2019 | F3: KZRK80 | G3: 14582000 | H3: 15000000
A4: AUDI | B4: A3 | C4: A3 SEDAN 35 TFSI 1.4 AUT | D4: 2022 | E4: =CONCATENATE(B4,C4,D4) -> A3A3 SEDAN 35 TFSI 1.4 AUT2022 | F4: RTLW29 | G4: 22990000 | H4: 23800000
A5: AUDI | B5: Q2 | C5: Q2 35 TFSI 1.4 AUT | D5: 2023 | E5: =CONCATENATE(B5,C5,D5) -> Q2Q2 35 TFSI 1.4 AUT2023 | F5: SPZD69 | G5: 26190000 | H5: 22500000
A6: AUDI | B6: Q3 | C6: Q3 35 TFSI 1.4 AUT | D6: 2023 | E6: =CONCATENATE(B6,C6,D6) -> Q3Q3 35 TFSI 1.4 AUT2023 | F6: SRZH16 | G6: 25990000 | H6: 23200000
A7: AUDI | B7: Q3 | C7: Q3 35 TFSI SPORTBACK 1.4 AUT | D7: 2023 | E7: =CONCATENATE(B7,C7,D7) -> Q3Q3 35 TFSI SPORTBACK 1.4 AUT2023 | F7: SLYZ27 | G7: 33990000 | H7: 29000000
A8: AUDI | B8: Q5 | C8: Q5 TDI 2.0 | D8: 2012 | E8: =CONCATENATE(B8,C8,D8) -> Q5Q5 TDI 2.02012 | F8: DTLC56 | G8: 11000000 | H8: 15000000
A9: AUDI | B9: Q5 | C9: Q5 TFSI 4X4 2.0 AUT | D9: 2020 | E9: =CONCATENATE(B9,C9,D9) -> Q5Q5 TFSI 4X4 2.0 AUT2020 | F9: LPXH29 | G9: 25390000 | H9: 31300000
A10: AUDI | B10: Q5 | C10: Q5 TFSI 4X4 2.0 AUT | D10: 2020 | E10: =CONCATENATE(B10,C10,D10) -> Q5Q5 TFSI 4X4 2.0 AUT2020 | F10: PFRP23 | G10: 23490000 | H10: 32000000
A11: AUDI | B11: Q7 | C11: Q7 TDI 4X4 3.0 AUT | D11: 2019 | E11: =CONCATENATE(B11,C11,D11) -> Q7Q7 TDI 4X4 3.0 AUT2019 | F11: KWYD58 | G11: 33490000 | H11: 29000000
A12: BAIC | B12: BAIC | C12: X35 1.5 | D12: 2019 | E12: =CONCATENATE(B12,C12,D12) -> BAICX35 1.52019 | F12: LGXV34 | G12: 7990000 | H12: 8800000
A13: BAIC | B13: BAIC | C13: X35 1.5 | D13: 2023 | E13: =CONCATENATE(B13,C13,D13) -> BAICX35 1.52023 | F13: SBLF15 | G13: 7890000 | H13: 6500000
A14: BAIC | B14: BAIC | C14: X55 1.5T | D14: 2023 | E14: =CONCATENATE(B14,C14,D14) -> BAICX55 1.5T2023 | F14: SSRS44 | G14: 8690000 | H14: 6800000
... A326: CITROEN | B326: C4 | C326: C4 1.2 AT | D326: 2025 | E326: =CONCATENATE(B326,C326,D326) -> C4C4 1.2 AT2025 | F326: VBHL43 | G326: 18990000 | H326: 16500000
A327: CITROEN | B327: C4 | C327: C4 1.5 AUT | D327: 2025 | E327: =CONCATENATE(B327,C327,D327) -> C4C4 1.5 AUT2025 | G327: 17990000 | H327: 0
A328: CITROEN | B328: C4 | C328: C4 1.5 AUT | D328: 2025 | E328: =CONCATENATE(B328,C328,D328) -> C4C4 1.5 AUT2025 | F328: TXZB72 | G328: 17990000 | H328: 14500000
A329: CITROEN | B329: C4 | C329: C4 1.6 | D329: 2010 | E329: =CONCATENATE(B329,C329,D329) -> C4C4 1.62010 | F329: CJZV22 | G329: 2000000 | H329: 3600000
A330: CITROEN | B330: C4 | C330: C4 CACTUS HDI 1.6 | D330: 2016 | E330: =CONCATENATE(B330,C330,D330) -> C4C4 CACTUS HDI 1.62016 | F330: HRWS66 | G330: 9690000 | H330: 8000000
A331: CITROEN | B331: C4 | C331: C4 HDI 1.6 | D331: 2016 | E331: =CONCATENATE(B331,C331,D331) -> C4C4 HDI 1.62016 | F331: HJSY32 | G331: 8490000 | H331: 7000000
A332: CITROEN | B332: C5 | C332: C5 AIRCROSS 1.5 AUT | D332: 2019 | E332: =CONCATENATE(B332,C332,D332) -> C5C5 AIRCROSS 1.5 AUT2019 | G332: 16490000 | H332: 0
A333: CITROEN | B333: C5 | C333: C5 AIRCROSS 1.5 AUT | D333: 2019 | E333: =CONCATENATE(B333,C333,D333) -> C5C5 AIRCROSS 1.5 AUT2019 | F333: LFXV54 | G333: 27980000 | H333: 29800000
A334: CITROEN | B334: C5 | C334: C5 AIRCROSS 1.5 AUT | D334: 2020 | E334: =CONCATENATE(B334,C334,D334) -> C5C5 AIRCROSS 1.5 AUT2020 | F334: LVWV64 | G334: 14190000 | H334: 12000000
A335: CITROEN | B335: C5 | C335: C5 AIRCROSS BHDI 1.5 AUT | D335: 2020 | E335: =CONCATENATE(B335,C335,D335) -> C5C5 AIRCROSS BHDI 1.5 AUT2020 | F335: LVWY70 | G335: 21990000 | H335: 21330300
A336: CITROEN | B336: C5 | C336: C5 AIRCROSS BLUEHDI 1.5 AUT | D336: 2022 | E336: =CONCATENATE(B336,C336,D336) -> C5C5 AIRCROSS BLUEHDI 1.5 AUT2022 | F336: PCFG80 | G336: 18090000 | H336: 15500000
A337: CITROEN | B337: C5 | C337: C5 AIRCROSS CVA8 STT 1.5 AUT | D337: 2024 | E337: =CONCATENATE(B337,C337,D337) -> C5C5 AIRCROSS CVA8 STT 1.5 AUT2024 | F337: TCTS12 | G337: 19150000 | H337: 16750000
A338: CITROEN | B338: C-ELYSEE | C338: C ELYSEE 1.2 | D338: 2018 | E338: =CONCATENATE(B338,C338,D338) -> C-ELYSEEC ELYSEE 1.22018 | F338: KGLK41 | G338: 6100000 | H338: 4900000
A339: CITROEN | B339: C-ELYSEE | C339: C ELYSEE 1.6 | D339: 2017 | E339: =CONCATENATE(B339,C339,D339) -> C-ELYSEEC ELYSEE 1.62017 | F339: JGCC12 | G339: 5590000 | H339: 5000000
A340: CITROEN | B340: SPACETOURER | C340: BUSINEES HDI 2.0 | D340: 2022 | E340: =CONCATENATE(B340,C340,D340) -> SPACETOURERBUSINEES HDI 2.02022 | F340: PCFG40 | G340: 20390000 | H340: 17500000
A341: DFLM | B341: JOYEAR | C341: JOYEAR SX5 1.6 | D341: 2021 | E341: =CONCATENATE(B341,C341,D341) -> JOYEARJOYEAR SX5 1.62021 | F341: RFHP74 | G341: 7746004 | H341: 6500000
A342: DFM | B342: AX4 | C342: AX4 LUXURY 1.6 AUT | D342: 2021 | E342: =CONCATENATE(B342,C342,D342) -> AX4AX4 LUXURY 1.6 AUT2021 | F342: PSPC17 | G342: 7990000 | H342: 5700000
A343: DFM | B343: JOYEAR | C343: JOYEAR SX5 1.6 | D343: 2022 | E343: =CONCATENATE(B343,C343,D343) -> JOYEARJOYEAR SX5 1.62022 | F343: RXSL88 | G343: 7850000 | H343: 6500000
A344: DFM | B344: T5L | C344: T5L LUX 1.8 | D344: 2025 | E344: =CONCATENATE(B344,C344,D344) -> T5LT5L LUX 1.82025 | F344: TSRG98 | G344: 11990000 | H344: 10700000
... A380: DFSK | B380: CARGO | C380: CARGO VAN C35 1.5 | D380: 2022 | E380: =CONCATENATE(B380,C380,D380) -> CARGOCARGO VAN C35 1.52022 | F380: SCGS46 | G380: 10265960 | H380: 12000000
A381: DFSK | B381: DFSK | C381: CARGO BOX XL 1.3 | D381: 2014 | E381: =CONCATENATE(B381,C381,D381) -> DFSKCARGO BOX XL 1.32014 | G381: 3990000 | H381: 0
A382: DFSK | B382: DFSK | C382: CARGO BOX XL 1.3 | D382: 2014 | E382: =CONCATENATE(B382,C382,D382) -> DFSKCARGO BOX XL 1.32014 | F382: GBDZ39 | G382: 3990000 | H382: 4331719
A383: DFSK | B383: PICK UP D1 | C383: D1 COMFORT 2.3 | D383: 2024 | E383: =CONCATENATE(B383,C383,D383) -> PICK UP D1D1 COMFORT 2.32024 | F383: TCHY13 | G383: 13990000 | H383: 14500000
A384: DFSK | B384: PICK UP D1 | C384: D1 LUXURY 4X4 2.3 | D384: 2024 | E384: =CONCATENATE(B384,C384,D384) -> PICK UP D1D1 LUXURY 4X4 2.32024 | F384: TLRR98 | G384: 16490000 | H384: 13750000
A385: DFSK | B385: TRUCK | C385: TRUCK CS C21 1.3 | D385: 2026 | E385: =CONCATENATE(B385,C385,D385) -> TRUCKTRUCK CS C21 1.32026 | F385: VJTT72 | G385: 7690000 | H385: 6500000
A386: DFSK | B386: TRUCK | C386: TRUCK DC 1.0 | D386: 2025 | E386: =CONCATENATE(B386,C386,D386) -> TRUCKTRUCK DC 1.02025 | F386: VCRP11 | G386: 6990000 | H386: 0
...

Sheet Hoja1
A1: Empresa | B1: IMPORTADORA TRENTO LTDA
A3: Marca | B3: Modelo | C3: Año | D3: Días Stock | E3: Placa Patente | F3: Estado Dealer
A4: BYD | B4: SHARK DMO | C4: 2025 | D4: 126 | E4: TGVF52 | F4: DISPONIBLE
A5: BYD | B5: SONG PLUS DM-i | C5: 2024 | D5: 214 | E5: TJDC55 | F5: DISPONIBLE
A6: CHANGAN | B6: CHANGAN | C6: 2022 | D6: 70 | E6: RXCG78 | F6: DISPONIBLE
A7: CHERY | B7: ARRIZO 5 | C7: 2019 | D7: 63 | E7: KZKL71 | F7: EN TALLER
A8: CHERY | B8: TIGGO 3 | C8: 2021 | D8: 292 | E8: RBZD91 | F8: EN RESCILIACION
A9: CHERY | B9: TIGGO 3 PRO | C9: 2026 | D9: 102 | E9: VKCY97 | F9: DISPONIBLE
A10: CHERY | B10: TIGGO 7 PRO | C10: 2022 | D10: 187 | E10: RVRD47 | F10: EN TALLER
A11: CHEVROLET | B11: CAPTIVA | C11: 2017 | D11: 348 | E11: JHSK67 | F11: EN TALLER
A12: CHEVROLET | B12: SILVERADO | C12: 2023 | D12: 291 | E12: SJDW14 | F12: DISPONIBLE
A13: CHEVROLET | B13: TAHOE | C13: 2020 | D13: 131 | E13: PDBT76 | F13: DISPONIBLE
A14: CITROEN | B14: C3 | C14: 2019 | D14: 98 | E14: LPXJ44 | F14: EN TALLER
A15: CITROEN | B15: C5 | C15: 2020 | D15: 588 | E15: LVWV64 | F15: EN TALLER
... A80: SUBARU | B80: FORESTER | C80: 2024 | D80: 75 | E80: TPCS18 | F80: DISPONIBLE
A81: Total general

Sheet BBDD
A1: Empresa | B1: Sucursal | C1: Folio Venta | D1: Venta | E1: Estado Venta | F1: Fecha Venta | G1: Tipo Documento (Folio) | H1: Vendedor | I1: Fecha Ingreso | J1: Fecha Facturación | K1: Numero VIN | L1: Marca | M1: Modelo | N1: Versión | O1: Código Versión | P1: Año | Q1: Kilometraje | R1: Código Interno | S1: Placa Patente | T1: Condición Vehículo | U1: Color Exterior | V1: Color Interior | W1: Precio Venta Total | X1: Estado AutoPro | Y1: Días Stock | Z1: Estado Dealer | AA1: Bodega | AB1: Equipamiento | AC1: Numero Motor | AD1: Numero Chasis | AE1: Proveedor | AF1: Fecha Disponibilidad | AG1: Factura Compra | AH1: Vencimiento Documento | AI1: Fecha Compra | AJ1: Fecha Vencto. Revisión Técnica | AK1: N° Propietarios | AL1: Folio Retoma | AM1: Fecha Retoma | AN1: Días Reservado | AO1: Precio Compra Neto | AP1: Gasto | AQ1: Accesorios | AR1: Total Costo | AS1: Precio Lista | AT1: Margen | AU1: Margen %
A2: AUTOMOTRIZ BALMACEDA LTDA. | B2: LOCAL USADOS | C2: 0 | D2: 0 | I2: 14-08-2025 17:36:07 | K2: VR3USHNSKSJ517115 | L2: PEUGEOT | M2: Nuevo 2008 | N2: 2008 ALLURE 130 1.2 | O2: N2008USA | P2: 2025 | Q2: 1510 | R2: BPESTWU000008 | S2: TXYV73 | T2: USADO | U2: GRIS ARTENSE | V2: POR DEFINIR | W2: 16990000 | X2: Disponible | Y2: 397 | Z2: DEVOLUCION NUEVOS DISPONIBLE | AA2: LOCAL USADOS VEHICULOS | AC2: 10TMA60199560 | AD2: VR3USHNSKSJ517115 | AE2: JULIO CESAR GUTIERREZ VARGAS | AF2: 14-08-2025 0:00:00 | AG2: 1 | AH2: 14-08-2025 0:00:00 | AI2: 14-08-2025 17:34:19 | AK2: 0 | AL2: 0 | AN2: 0 | AO2: 20390000 | AP2: 0 | AQ2: 0 | AR2: 20390000 | AS2: 16990000 | AT2: -3400000 | AU2: -2001
A3: AUTOMOTRIZ BALMACEDA LTDA. | B3: LOCAL PEUGEOT | C3: 0 | D3: 0 | I3: 06-11-2025 16:51:55 | K3: 9V8FF4HY1SA819290 | L3: PEUGEOT | M3: Landtrek | N3: LANDTREK BLUEHDI 4X4 2.2 AUT | O3: LANDUSA | P3: 2025 | Q3: 0 | R3: BPECMTU000007 | S3: VJBV25 | T3: USADO | U3: BLANCO BANQUISE | V3: POR DEFINIR | W3: 21990000 | X3: Disponible | Y3: 313 | Z3: EN TALLER | AA3: BODEGA LOCAL PEUGEOT | AC3: 10VRAC4012986 | AD3: 9V8FF4HY1SA819290 | AE3: ECO ARQUING LTDA | AF3: 06-11-2025 0:00:00 | AG3: 1 | AH3: 06-11-2025 0:00:00 | AI3: 06-11-2025 16:50:16 | AK3: 0 | AL3: 0 | AN3: 0 | AO3: 29381100 | AP3: 0 | AQ3: 0 | AR3: 29381100 | AS3: 21990000 | AT3: -7391100 | AU3: -3361
A4: AUTOMOTRIZ BALMACEDA LTDA. | B4: LOCAL PEUGEOT | C4: 0 | D4: 0 | I4: 28-05-2026 12:41:52 | K4: VR3KAHPY0VS001093 | L4: PEUGEOT | M4: NUEVO 3008 | N4: 3008 P64 GT Hybrid 136hp AT | O4: 1PPDSYTJH7NXA0B0167 | P4: 2026 | Q4: 0 | R4: BPESTWN002855 | S4: VZLY15 | T4: SEMINUEVO | U4: BLANCO OKENITA | V4: POR DEFINIR | W4: 37290000 | X4: Disponible | Y4: 110 | Z4: TEST CAR | AA4: BODEGA LOCAL PEUGEOT | AC4: 10XR050087229 | AD4: VR3KAHPY0VS001093 | AE4: FORUM DISTRIBUIDORA SA | AF4: 28-05-2026 0:00:00 | AG4: 0 | AK4: 0 | AL4: 0 | AN4: 0 | AO4: 28515882 | AP4: 1030553 | AQ4: 0 | AR4: 29546435 | AS4: 31336134 | AT4: 1789699 | AU4: 571
A5: AUTOMOTRIZ BALMACEDA LTDA. | B5: LOCAL PEUGEOT | C5: 0 | D5: 0 | I5: 12-09-2025 15:00:44 | K5: VR3EBYHZ9TJ514671 | L5: PEUGEOT | M5: Rifter | N5: RIFTER MCA ALLURE Diesel 130hp AT | O5: 1PK9CLTMK1JRA070059 | P5: 2026 | Q5: 0 | R5: BPESTWN002704 | S5: VKCY37 | T5: SEMINUEVO | U5: GRIS ARTENSE | V5: POR DEFINIR | W5: 26390000 | X5: Disponible | Y5: 368 | Z5: DEMO/INTERNO | AA5: BODEGA LOCAL PEUGEOT | AC5: 10Q4EP0347273 | AD5: VR3EBYHZ9TJ514671 | AE5: FORUM DISTRIBUIDORA SA | AF5: 12-09-2025 0:00:00 | AG5: 912478 | AH5: 25-09-2025 0:00:00 | AI5: 05-10-2025 21:25:13 | AK5: 0 | AL5: 0 | AN5: 0 | AO5: 18211764 | AP5: 826449 | AQ5: 0 | AR5: 19038213 | AS5: 22176471 | AT5: 3138258 | AU5: 1415
A6: AUTOMOTRIZ BALMACEDA LTDA. | B6: LOCAL PEUGEOT | C6: 0 | D6: 0 | I6: 03-12-2025 15:23:05 | K6: VF3YDT6FXTMB55780 | L6: PEUGEOT | M6: Boxer | N6: BOXER 2.2 | O6: BOXUSA1 | P6: 2026 | Q6: 2700 | R6: BPEFRGU000005 | S6: TGVK67 | T6: USADO | U6: BLANCO HIELO | V6: POR DEFINIR | W6: 31990000 | X6: Disponible | Y6: 286 | Z6: EN TALLER | AA6: BODEGA LOCAL PEUGEOT | AC6: 463571691903538 | AD6: VF3YDT6FXTMB55780 | AE6: DAVID REINALDO RAMIREZ PEÑA Y LILLO VENTA, MANTENCION Y RECARGA DE EXTINTORES E.I.R.L | AF6: 03-12-2025 0:00:00 | AG6: 1 | AH6: 03-12-2025 0:00:00 | AI6: 03-12-2025 15:22:45 | AK6: 0 | AL6: 0 | AN6: 0 | AO6: 32237100 | AP6: 0 | AQ6: 0 | AR6: 32237100 | AS6: 31990000 | AT6: -247100 | AU6: -77
A7: AUTOMOTRIZ BALMACEDA LTDA. | B7: BODEGA PDI | C7: 0 | D7: 0 | I7: 08-05-2026 12:47:17 | K7: VR3EDYHT4VJ003832 | L7: PEUGEOT | M7: NUEVA PARTNER | N7: PARTNER MCA L2 Diesel 100hp MT | O7: 2PK95CNMNKJRA070069 | P7: 2026 | Q7: 0 | R7: BPEFRGN001371 | S7: VYCP86 | T7: SEMINUEVO | U7: BLANCO HIELO | V7: POR DEFINIR | W7: 24264100 | X7: Disponible | Y7: 130 | Z7: TEST CAR | AA7: BODEGA PDI | AC7: 10Q4EU0696242 | AD7: VR3EDYHT4VJ003832 | AE7: FORUM DISTRIBUIDORA SA | AF7: 08-05-2026 0:00:00 | AG7: 0 | AK7: 0 | AL7: 0 | AN7: 0 | AO7: 18351000 | AP7: 0 | AQ7: 0 | AR7: 18351000 | AS7: 20390000 | AT7: 2039000 | AU7: 10
A8: AUTOMOTRIZ BALMACEDA LTDA. | B8: MEGACENTRO OVALLE | C8: 0 | D8: 0 | I8: 21-02-2024 15:15:59 | K8: 9V8FF4HY1RA800754 | L8: PEUGEOT | M8: Landtrek | N8: Landtrek Active BlueHDi 180 4x4 AT | O8: 2PKPEKHMQNN088 | P8: 2024 | Q8: 27913 | R8: BPECMTN000252 | S8: TJDB33 | T8: SEMINUEVO | U8: BLANCO BANQUISE | V8: POR DEFINIR | W8: 20990000 | X8: Disponible | Y8: 389 | Z8: DEMO/INTERNO | AA8: MEGACENTRO OVALLE VEHICULOS | AC8: 10VRAC4002482 | AD8: 9V8FF4HY1RA800754 | AE8: FORUM DISTRIBUIDORA SA | AF8: 22-08-2025 0:00:00 | AG8: 781565 | AH8: 19-03-2024 0:00:00 | AI8: 20-03-2024 14:57:19 | AK8: 0 | AL8: 0 | AN8: 0 | AO8: 26670800 | AP8: 991590 | AQ8: 0 | AR8: 27662390 | AS8: 20990000 | AT8: -6672390 | AU8: -3179
A9: AUTOMOTRIZ BALMACEDA LTDA. | B9: LOCAL USADOS | C9: 0 | D9: 0 | I9: 12-09-2025 16:02:19 | K9: VXKUSHNS5TW000787 | L9: OPEL | M9: NEW MOKKA | N9: Mokka GS Gasolina 130HP AT | O9: 1GQOSYHI21JRA033109 | P9: 2026 | Q9: 2705 | R9: BOPSTWN000228 | S9: VKCY38 | T9: SEMINUEVO | U9: VERDE LAGUNA | V9: POR DEFINIR | W9: 24890000 | X9: Disponible | Y9: 162 | Z9: DEMO/INTERNO | AA9: LOCAL USADOS VEHICULOS | AC9: 10XVBB2431060 | AD9: VXKUSHNS5TW000787 | AE9: FORUM DISTRIBUIDORA SA | AF9: 06-04-2026 0:00:00 | AG9: 912475 | AH9: 25-09-2025 0:00:00 | AI9: 05-10-2025 21:20:03 | AK9: 0 | AL9: 0 | AN9: 0 | AO9: 16665547 | AP9: 535096 | AQ9: 0 | AR9: 17200643 | AS9: 20915966 | AT9: 3715323 | AU9: 1776
A10: AUTOMOTRIZ BALMACEDA LTDA. | B10: LOCAL USADOS COPIAPO | C10: 0 | D10: 0 | I10: 07-01-2025 15:56:46 | K10: VR3FDAHDLN3007730 | L10: PEUGEOT | M10: Landtrek | N10: LANDTREK 4X4 1.9 | O10: LANUSA1 | P10: 2022 | Q10: 0 | R10: BPECMTU000002 | S10: RVYJ17 | T10: USADO | U10: GRIS GRAFITO | V10: POR DEFINIR | W10: 37355481 | X10: Disponible | Y10: 616 | Z10: EN TALLER | AA10: BODEGA VEHICULOS | AC10: A5D22001368 | AD10: VR3FDAHDLN3007730 | AE10: FERNANDO GABRIEL LEIVA PANGUE | AF10: 07-01-2025 0:00:00 | AG10: 1 | AH10: 07-01-2025 0:00:00 | AI10: 07-01-2025 15:55:41 | AK10: 0 | AL10: 0 | AN10: 0 | AO10: 37355481 | AP10: 894355 | AQ10: 0 | AR10: 38249836 | AS10: 37355481 | AT10: -894355 | AU10: -239
A11: AUTOMOTRIZ BALMACEDA LTDA. | B11: MEGACENTRO OVALLE | C11: 0 | D11: 0 | I11: 30-10-2023 16:00:03 | K11: VR3UDYHZSRJ524567 | L11: PEUGEOT | M11: Nuevo 2008 | N11: 2008 MCA Allure BlueHDi 130 EAT8 | O11: 1PP1SYPMK1JRA0 | P11: 2024 | Q11: 45647 | R11: BPESTWN002279 | S11: TJCZ90 | T11: SEMINUEVO | U11: BLANCO OKENITE | V11: POR DEFINIR | W11: 17590000 | X11: Disponible | Y11: 1051 | Z11: EN TALLER | AA11: MEGACENTRO OVALLE VEHICULOS | AC11: 10Q3DP1802788 | AD11: VR3UDYHZSRJ524567 | AE11: FORUM DISTRIBUIDORA SA | AF11: 30-10-2023 0:00:00 | AG11: 781568 | AH11: 19-03-2024 0:00:00 | AI11: 20-03-2024 15:01:46 | AK11: 0 | AL11: 0 | AN11: 0 | AO11: 21175461 | AP11: 1288456 | AQ11: 0 | AR11: 22463917 | AS11: 17590000 | AT11: -4873917 | AU11: -2771
A12: AUTOMOTRIZ BALMACEDA LTDA. | B12: BODEGA PDI | C12: 0 | D12: 0 | I12: 12-09-2025 15:22:18 | K12: VXKUPHNKXT4000863 | L12: OPEL | M12: NEW CORSA | N12: Corsa MCA Edition Gasolina 100HP AT | O12: 1GJOA5HL71J0A0F0018 | P12: 2026 | Q12: 0 | R12: BOPAUTN000108 | S12: VKCY43 | T12: SEMINUEVO | U12: GRIS GSE | V12: POR DEFINIR | W12: 18690000 | X12: Disponible | Y12: 368 | Z12: DEMO/INTERNO | AA12: BODEGA PDI | AC12: 10XVBB2453272 | AD12: VXKUPHNKXT4000863 | AE12: FORUM DISTRIBUIDORA SA | AF12: 12-09-2025 0:00:00 | AG12: 912470 | AH12: 25-09-2025 0:00:00 | AI12: 05-10-2025 21:09:55 | AK12: 0 | AL12: 0 | AN12: 0 | AO12: 13236975 | AP12: 460637 | AQ12: 0 | AR12: 13697612 | AS12: 15705882 | AT12: 2008270 | AU12: 1279
A13: AUTOMOTRIZ BALMACEDA LTDA. | B13: MEGACENTRO OVALLE | C13: 0 | D13: 0 | I13: 27-12-2025 22:18:45 | K13: VR3KAHPY3TS012523 | L13: PEUGEOT | M13: NUEVO 3008 | N13: 3008 P64 GT Hybrid 136hp AT | O13: 1PPDSYTJH7NXA0B0167 | P13: 2026 | Q13: 0 | R13: BPESTWN002763 | S13: VVYY78 | T13: SEMINUEVO | U13: GRIS ARTENSE | V13: POR DEFINIR | W13: 37290000 | X13: Disponible | Y13: 262 | Z13: USO GERENCIA | AA13: MEGACENTRO OVALLE VEHICULOS | AC13: 10XR050002280 | AD13: VR3KAHPY3TS012523 | AE13: FORUM DISTRIBUIDORA SA | AF13: 27-12-2025 0:00:00 | AG13: 0 | AK13: 0 | AL13: 0 | AN13: 0 | AO13: 28983865 | AP13: 1338304 | AQ13: 0 | AR13: 30322169 | AS13: 31336134 | AT13: 1013965 | AU13: 324
A14: AUTOMOTRIZ BALMACEDA LTDA. | B14: LOCAL PEUGEOT | C14: 0 | D14: 0 | I14: 12-09-2025 14:24:14 | K14: VR3USHNS6SJ525435 | L14: PEUGEOT | M14: Nuevo 2008 | N14: 2008 MCA Style Gasolina 130hp MT | O14: 1PP1SYHM6KJR2PG0000 | P14: 2026 | Q14: 0 | R14: BPESTWN002701 | S14: VKCY47 | T14: SEMINUEVO | U14: BLANCO OKENITE | V14: POR DEFINIR | W14: 21090000 | X14: Disponible | Y14: 368 | Z14: DEMO/INTERNO | AA14: BODEGA LOCAL PEUGEOT | AC14: 10TMA60220138 | AD14: VR3USHNS6SJ525435 | AE14: FORUM DISTRIBUIDORA SA | AF14: 12-09-2025 0:00:00 | AG14: 912464 | AH14: 25-09-2025 0:00:00 | AI14: 05-10-2025 20:51:32 | AK14: 0 | AL14: 0 | AN14: 0 | AO14: 14312605 | AP14: 409055 | AQ14: 0 | AR14: 14721660 | AS14: 17722689 | AT14: 3001029 | AU14: 1693
A15: AUTOMOTRIZ BALMACEDA LTDA. | B15: LOCAL USADOS | C15: 0 | D15: 0 | I15: 07-07-2023 13:26:15 | K15: VR3FDAHDLP3008724 | L15: PEUGEOT | M15: Landtrek | N15: LANDTREK 4X4 1.9 | O15: LANUSA1 | P15: 2022 | Q15: 1980 | R15: BPECMTU000001 | S15: RSYF47 | T15: USADO | U15: GRIS GRAFITO | V15: POR DEFINIR | W15: 19490000 | X15: Disponible | Y15: 1166 | Z15: DISPONIBLE | AA15: LOCAL USADOS VEHICULOS | AC15: A5D22001392 | AD15: VR3FDAHDLP3008724 | AE15: CONSTRUCTORA BRAP SPA | AF15: 07-07-2023 0:00:00 | AG15: 1 | AH15: 07-07-2023 0:00:00 | AI15: 07-07-2023 13:25:46 | AK15: 0 | AL15: 0 | AN15: 0 | AO15: 21000000 | AP15: 13250 | AQ15: 0 | AR15: 21013250 | AS15: 19490000 | AT15: -1523250 | AU15: -782
A16: CALLEGARI E HIJOS LTDA | B16: FORD BALMACEDA | C16: 0 | D16: 0 | I16: 09-10-2025 15:07:31 | K16: 8AFBR01K6SJ443936 | L16: FORD | M16: RANGER | N16: RANGER LTD 4X4 3.0 AUT | O16: RANDEVTDXB62 | P16: 2025 | Q16: 0 | R16: CFOCMTU000014 | S16: TDXB62 | T16: SEMINUEVO | U16: BLANCO | W16: 0 | X16: Disponible | Y16: 341 | Z16: EN PREPARACION | AA16: BODEGA FORD BALMACEDA VEHICULO | AC16: BF2X SJ443936 | AD16: 8AFBR01K6SJ443936 | AE16: BANCO DE CHILE | AF16: 09-10-2025 0:00:00 | AG16: 45641330 | AH16: 25-11-2025 0:00:00 | AI16: 11-12-2025 20:22:57 | AK16: 0 | AL16: 0 | AN16: 0 | AO16: 39290000 | AP16: 0 | AQ16: 0 | AR16: 39290000 | AS16: 0 | AT16: -39290000 | AU16: -3929000000
A17: CALLEGARI E HIJOS LTDA | B17: LOCAL USADOS | C17: 0 | D17: 0 | I17: 01-10-2025 12:34:07 | K17: KNAB3512A RT199134 | L17: KIA MOTORS | M17: MORNING | N17: MORNING MPI 1.2 | O17: MPI1 | P17: 2025 | Q17: 0 | R17: CKIAUTU000005 | S17: VBWV23 | T17: USADO | U17: VERDE BOSQUE | V17: POR DEFINIR | W17: 11490000 | X17: Disponible | Y17: 349 | Z17: EN TALLER | AA17: LOCAL USADOS VEHICULOS | AC17: G4LAPP262114 | AD17: KNAB3512A RT199134 | AE17: BENJAMIN MOISES SOTO ALFARO | AF17: 01-10-2025 0:00:00 | AG17: 1 | AH17: 01-10-2025 0:00:00 | AI17: 01-10-2025 12:33:42 | AK17: 0 | AL17: 0 | AN17: 12 | AO17: 12473300 | AP17: 0 | AQ17: 0 | AR17: 12473300 | AS17: 11490000 | AT17: -983300 | AU17: -856
A18: CALLEGARI E HIJOS LTDA | B18: LOCAL USADOS | C18: 0 | D18: 0 | I18: 26-09-2023 16:20:52 | K18: 9V8FF4HY1PA800411 | L18: PEUGEOT | M18: LANDTREK | N18: Landtrek Active BlueHdi 180 4x4 AT | O18: 2PKPEKHMQNN088 | P18: 2024 | Q18: 50982 | R18: CPECMTN000018 | S18: TBCP54 | T18: SEMINUEVO | U18: NEGRO PERLA NERA | V18: POR DEFINIR | W18: 20990000 | X18: Disponible | Y18: 174 | Z18: DEMO/INTERNO | AA18: LOCAL USADOS VEHICULOS | AC18: VRAC4001479 | AD18: 9V8FF4HY1PA800411 | AE18: AUTOMOTRIZ BALMACEDA LTDA | AF18: 25-03-2026 0:00:00 | AG18: 55045 | AH18: 26-10-2023 0:00:00 | AI18: 26-09-2023 16:20:37 | AK18: 0 | AL18: 0 | AN18: 0 | AO18: 29014497 | AP18: 3058563 | AQ18: 0 | AR18: 32073060 | AS18: 20990000 | AT18: -11083060 | AU18: -528
A19: CALLEGARI E HIJOS LTDA | B19: LOCAL USADOS | C19: 0 | D19: 0 | I19: 24-03-2025 10:27:56 | K19: VR3KAHPY1SS006024 | L19: PEUGEOT | M19: NUEVO 3008 | N19: New 3008 PREMIERE MHEV 136 eDCT6 | O19: TCPE26 | P19: 2025 | Q19: 23967 | R19: CPESTWN000076 | S19: VBBD31 | T19: SEMINUEVO | U19: NEGRO PERLA NERA | V19: POR DEFINIR | W19: 24290000 | X19: Disponible | Y19: 162 | Z19: DEMO/INTERNO | AA19: LOCAL USADOS VEHICULOS | AC19: 10ZA040047007 | AD19: VR3KAHPY1SS006024 | AE19: AUTOMOTRIZ BALMACEDA LTDA | AF19: 06-04-2026 0:00:00 | AG19: 66117 | AH19: 19-04-2025 0:00:00 | AI19: 24-03-2025 10:27:42 | AK19: 0 | AL19: 0 | AN19: 0 | AO19: 25546891 | AP19: 1916780 | AQ19: 0 | AR19: 27463671 | AS19: 24290000 | AT19: -3173671 | AU19: -1307
A20: CALLEGARI E HIJOS LTDA | B20: BODEGA PDI | C20: 0 | D20: 0 | I20: 04-01-2019 18:31:16 | K20: JF1GT7LL5KG071115 | L20: SUBARU | M20: XV | N20: NEW XV 2.0I AWD CVT DYNAMIC | O20: XV 5695 | P20: 2019 | Q20: 6400 | R20: CSUSTWN000408 | S20: LBGX66 | T20: SEMINUEVO | U20: BLANCO CRISTAL PERLADO | V20: POR DEFINIR | W20: 15900000 | X20: Disponible | Y20: 1411 | Z20: NO DISPONIBLE | AA20: BODEGA PDI | AC20: CE04013 | AD20: JF1GT7LL5KG071115 | AE20: FORUM DISTRIBUIDORA S.A | AF20: 04-11-2022 0:00:00 | AG20: 347702 | AH20: 11-01-2019 0:00:00 | AI20: 22-01-2019 10:34:11 | AK20: 0 | AL20: 0 | AN20: 0 | AO20: 12497480 | AP20: 3135424 | AQ20: 0 | AR20: 15632904 | AS20: 15900000 | AT20: 267096 | AU20: 168
A21: CALLEGARI E HIJOS LTDA | B21: BODEGA PDI | C21: 0 | D21: 0 | I21: 24-03-2025 10:46:04 | K21: VR3EDYHT7TN500055 | L21: PEUGEOT | M21: NUEVA PARTNER | N21: Partner MCA L1 BlueHdi 100 | O21: TCPE7 | P21: 2026 | Q21: 0 | R21: CPEFRGN000018 | S21: VBBD56 | T21: SEMINUEVO | U21: BLANCO BLANC ICY | V21: POR DEFINIR | W21: 22717100 | X21: Disponible | Y21: 544 | Z21: DEMO/INTERNO | AA21: BODEGA PDI | AC21: 10Q4EU0479175 | AD21: VR3EDYHT7TN500055 | AE21: AUTOMOTRIZ BALMACEDA LTDA | AF21: 20-03-2025 0:00:00 | AG21: 66129 | AH21: 19-04-2025 0:00:00 | AI21: 24-03-2025 10:45:51 | AK21: 0 | AL21: 0 | AN21: 0 | AO21: 17413917 | AP21: 1073628 | AQ21: 0 | AR21: 18487545 | AS21: 19090000 | AT21: 602455 | AU21: 316
A22: CALLEGARI E HIJOS LTDA | B22: LOCAL USADOS COPIAPO | C22: 0 | D22: 0 | I22: 03-02-2025 11:10:46 | K22: VR3UPHMHDS5001280 | L22: PEUGEOT | M22: NUEVO 208 | N22: Nuevo 208 MCA Active Pack Puretech 75 MT5 | O22: TCPE8 | P22: 2025 | Q22: 0 | R22: CPEAUTN000115 | S22: TYWT29 | T22: SEMINUEVO | U22: GRIS ARTENSE | V22: POR DEFINIR | W22: 16690000 | X22: Disponible | Y22: 144 | Z22: DEMO/INTERNO | AA22: BODEGA LOS CARRERA COPIAPO | AC22: 10XKDU0264699 | AD22: VR3UPHMHDS5001280 | AE22: AUTOMOTRIZ BALMACEDA LTDA | AF22: 24-04-2026 0:00:00 | AG22: 65154 | AH22: 02-03-2025 0:00:00 | AI22: 03-02-2025 11:10:31 | AK22: 0 | AL22: 0 | AN22: 0 | AO22: 12945210 | AP22: 923669 | AQ22: 0 | AR22: 13868879 | AS22: 14025210 | AT22: 156331 | AU22: 111
A23: CALLEGARI E HIJOS LTDA | B23: MEGACENTRO OVALLE | C23: 0 | D23: 0 | I23: 24-03-2025 10:03:39 | K23: VR3KAHPY1SS006126 | L23: PEUGEOT | M23: NUEVO 3008 | N23: New 3008 PREMIERE MHEV 136 eDCT6 | O23: TCPE26 | P23: 2026 | Q23: 0 | R23: CPESTWN000071 | S23: VBBD42 | T23: SEMINUEVO | U23: BLANCO OKENITE | V23: POR DEFINIR | W23: 32990000 | X23: Disponible | Y23: 544 | Z23: DEMO/INTERNO | AA23: MEGACENTRO OVALLE VEHICULOS | AC23: 10ZA040054673 | AD23: VR3KAHPY1SS006126 | AE23: AUTOMOTRIZ BALMACEDA LTDA | AF23: 20-03-2025 0:00:00 | AG23: 66110 | AH23: 19-04-2025 0:00:00 | AI23: 24-03-2025 10:03:23 | AK23: 0 | AL23: 0 | AN23: 0 | AO23: 25546891 | AP23: 1916780 | AQ23: 0 | AR23: 27463671 | AS23: 27722689 | AT23: 259018 | AU23: 93
A24: CALLEGARI E HIJOS LTDA | B24: LOCAL USADOS | C24: 0 | D24: 0 | I24: 28-02-2026 16:54:41 | K24: 8AFBR01C4SJ412077 | L24: FORD | M24: RANGER | N24: RANGER XLT 4X4 2.0 AUT | O24: RANDEV24 | P24: 2025 | Q24: 66000 | R24: CFOCMTU000019 | S24: TDWY79 | T24: USADO | U24: NEGRO | V24: POR DEFINIR | W24: 32990000 | X24: Disponible | Y24: 199 | Z24: EN TALLER | AA24: LOCAL USADOS VEHICULOS | AC24: YN2X SJ412077 | AD24: 8AFBR01C4SJ412077 | AE24: TERRA ELQUI SPA | AF24: 28-02-2026 0:00:00 | AG24: 1 | AH24: 28-02-2026 0:00:00 | AI24: 28-02-2026 16:53:37 | AK24: 0 | AL24: 0 | AN24: 0 | AO24: 25000000 | AP24: 0 | AQ24: 0 | AR24: 25000000 | AS24: 32990000 | AT24: 7990000 | AU24: 2422
A25: CALLEGARI E HIJOS LTDA | B25: LOCAL USADOS | C25: 0 | D25: 0 | I25: 16-09-2025 21:38:11 | K25: 3KPFF51ABSE120765 | L25: KIA MOTORS | M25: K3 CROSS | N25: K3 CROSS EX 1.6L 6AT | O25: KIA 2368 | P25: 2026 | Q25: 3756 | R25: CKISTWN011896 | S25: VKCY35 | T25: SEMINUEVO | U25: PLATEADO SUAVE | V25: POR DEFINIR | W25: 19990000 | X25: Disponible | Y25: 180 | Z25: DEMO/INTERNO | AA25: LOCAL USADOS VEHICULOS | AC25: G4FGSE037043 | AD25: 3KPFF51ABSE120765 | AE25: FORUM DISTRIBUIDORA S.A | AF25: 19-03-2026 0:00:00 | AG25: 912269 | AH25: 25-09-2025 0:00:00 | AI25: 06-10-2025 11:32:06 | AK25: 0 | AL25: 0 | AN25: 0 | AO25: 14110588 | AP25: 731651 | AQ25: 0 | AR25: 14842239 | AS25: 16798319 | AT25: 1956080 | AU25: 1164
A26: CALLEGARI E HIJOS LTDA | B26: FORD BALMACEDA | C26: 0 | D26: 0 | I26: 21-04-2026 12:40:27 | K26: 8AFBR01K1SJ019046 | L26: FORD | M26: RANGER | N26: RANGER LTD 4X4 3.0 AUT | O26: RANDEVTDXB62 | P26: 2026 | Q26: 2366 | R26: CFOCMTU000021 | S26: VSWV91 | T26: SEMINUEVO | U26: GRIS MERCURIO | V26: POR DEFINIR | W26: 42900000 | X26: Disponible | Y26: 147 | Z26: DEVOLUCION NUEVOS NO DISPONIBLE | AA26: BODEGA FORD BALMACEDA VEHICULO | AC26: BF2XSJ019046 | AD26: 8AFBR01K1SJ019046 | AE26: MASTER REDES IT SPA | AF26: 21-04-2026 0:00:00 | AG26: 202 | AH26: 15-04-2026 0:00:00 | AI26: 21-04-2026 12:37:52 | AK26: 0 | AL26: 0 | AN26: 0 | AO26: 39737899 | AP26: 0 | AQ26: 0 | AR26: 39737899 | AS26: 42900000 | AT26: 3162101 | AU26: 737
A27: CALLEGARI E HIJOS LTDA | B27: MEGACENTRO OVALLE | C27: 0 | D27: 0 | I27: 23-09-2024 13:25:20 | K27: VR3EDYHT2SJ514486 | L27: PEUGEOT | M27: NUEVA PARTNER | N27: Partner MCA L1 BlueHdi 100 | O27: TCPE7 | P27: 2025 | Q27: 0 | R27: CPEFRGN000016 | S27: TSGB37 | T27: SEMINUEVO | U27: BLANCO HIELO | V27: POR DEFINIR | W27: 22717100 | X27: Disponible | Y27: 728 | Z27: DEMO/INTERNO | AA27: MEGACENTRO OVALLE VEHICULOS | AC27: 10Q4EU0366595 | AD27: VR3EDYHT2SJ514486 | AE27: AUTOMOTRIZ BALMACEDA LTDA | AF27: 17-09-2024 0:00:00 | AG27: 62373 | AH27: 17-10-2024 0:00:00 | AI27: 23-09-2024 13:25:03 | AK27: 0 | AL27: 0 | AN27: 0 | AO27: 17322917 | AP27: 440794 | AQ27: 0 | AR27: 17763711 | AS27: 19090000 | AT27: 1326289 | AU27: 695
A28: CALLEGARI E HIJOS LTDA | B28: LOCAL USADOS | C28: 0 | D28: 0 | I28: 24-03-2025 10:08:03 | K28: VR3KAHPY1SS005755 | L28: PEUGEOT | M28: NUEVO 3008 | N28: New 3008 PREMIERE MHEV 136 eDCT6 | O28: TCPE26 | P28: 2025 | Q28: 8160 | R28: CPESTWN000072 | S28: VBBD50 | T28: SEMINUEVO | U28: GRIS ARTENSE | V28: POR DEFINIR | W28: 32990000 | X28: Disponible | Y28: 162 | Z28: DEMO/INTERNO | AA28: LOCAL USADOS VEHICULOS | AC28: 10ZA040040304 | AD28: VR3KAHPY1SS005755 | AE28: AUTOMOTRIZ BALMACEDA LTDA | AF28: 06-04-2026 0:00:00 | AG28: 66111 | AH28: 19-04-2025 0:00:00 | AI28: 24-03-2025 10:07:47 | AK28: 0 | AL28: 0 | AN28: 0 | AO28: 25546891 | AP28: 2425655 | AQ28: 0 | AR28: 27972546 | AS28: 27722689 | AT28: -249857 | AU28: -9
... A42: CALLEGARI E HIJOS LTDA | B42: LOCAL USADOS | C42: 0 | D42: 0 | I42: 23-09-2024 10:44:44 | K42: VF3M45GBURS003230 | L42: PEUGEOT | M42: NUEVO 3008 | N42: 3008 GT HYBRID4 300 eEAT8 | O42: TCPE1 | P42: 2025 | Q42: 7735 | R42: CPESTWN000039 | S42: TSGB43 | T42: SEMINUEVO | U42: BLANCO NACARADO | V42: POR DEFINIR | W42: 30590000 | X42: Disponible | Y42: 533 | Z42: DEMO/INTERNO | AA42: LOCAL USADOS VEHICULOS | AC42: 10FKBJ3063820 | AD42: VF3M45GBURS003230 | AE42: AUTOMOTRIZ BALMACEDA LTDA | AF42: 31-03-2025 0:00:00 | AG42: 62327 | AH42: 16-10-2024 0:00:00 | AI42: 23-09-2024 10:44:27 | AK42: 0 | AL42: 0 | AN42: 0 | AO42: 38661008 | AP42: 876679 | AQ42: 0 | AR42: 39537687 | AS42: 30590000 | AT42: -8947687 | AU42: -2925
A43: CALLEGARI E HIJOS LTDA | B43: MEGACENTRO COPIAPO | C43: 0 | D43: 0 | I43: 03-01-2017 1:36:33 | K43: KNCSJX76AG7995915 | L43: KIA MOTORS | M43: FRONTIER | N43: FRONTIER C/C 2.5 6MT | O43: 17--1336 | P43: 2016 | Q43: 0 | R43: CKICMTN001890 | S43: HTCD28 | T43: SEMINUEVO | U43: BLANCO INVIERNO | V43: NO DEFINIDO | W43: 15590000 | X43: Disponible | Y43: 3911 | Z43: VEHICULO USO DE SERVICIO | AA43: MEGACENTRO COPIAPO VEHICULOS | AC43: D4CBF790346 | AD43: KNCSJX76AG7995915 | AE43: FORUM DISTRIBUIDORA S.A | AF43: 31-12-2015 0:00:00 | AG43: 81310 | AH43: 31-12-2015 0:00:00 | AI43: 31-12-2015 0:00:00 | AJ43: 31-12-2015 0:00:00 | AK43: 0 | AL43: 0 | AN43: 0 | AO43: 13050001 | AP43: 2576087 | AQ43: 0 | AR43: 15626088 | AS43: 13100840 | AT43: -2525248 | AU43: -1928
A44: CALLEGARI E HIJOS LTDA | B44: LOCAL USADOS | C44: 0 | D44: 0 | I44: 26-02-2026 9:25:15 | K44: 8AFBR01C4 SJ466852 | L44: FORD | M44: RANGER | N44: RANGER XLT 4X4 2.0 | O44: FORANXLT4X420MT | P44: 2025 | Q44: 28620 | R44: CFOCMTU000018 | S44: VHGF48 | T44: USADO | U44: ROJO BARI | W44: 32990000 | X44: Disponible | Y44: 201 | Z44: DEVOLUCION NUEVOS DISPONIBLE | AA44: LOCAL USADOS VEHICULOS | AC44: YN2X SJ466852 | AD44: 8AFBR01C4 SJ466852 | AE44: NATALIA MARGARITA BUSTOS MUÑOZ | AF44: 26-02-2026 0:00:00 | AG44: 1 | AH44: 26-02-2026 0:00:00 | AI44: 26-02-2026 9:24:51 | AK44: 0 | AL44: 0 | AN44: 0 | AO44: 37000000 | AP44: 0 | AQ44: 0 | AR44: 37000000 | AS44: 32990000 | AT44: -4010000 | AU44: -1216
A45: CALLEGARI E HIJOS LTDA | B45: Local Premium | C45: 0 | D45: 0 | I45: 11-12-2025 21:17:36 | K45: 8AFBR00E2RJ365404 | L45: FORD | M45: RANGER | N45: RANGER XLS 2.0 | O45: FORANXLS20MT | P45: 2024 | Q45: 37000 | R45: CFOCMTU000016 | S45: TJDC25 | T45: USADO | U45: GRIS PLATA | V45: POR DEFINIR | W45: 24990000 | X45: Disponible | Y45: 298 | Z45: DEVOLUCION NUEVOS DISPONIBLE | AA45: LOCAL PREMIUM | AC45: P02XRJ365404 | AD45: 8AFBR00E2RJ365404 | AE45: SERVICIO DE INGENIERIA MANTENIMIENTO Y CONSTRUCCION SPA | AF45: 21-11-2025 0:00:00 | AG45: 119 | AH45: 21-11-2025 0:00:00 | AI45: 11-12-2025 21:15:04 | AK45: 0 | AL45: 0 | AN45: 0 | AO45: 23490000 | AP45: 0 | AQ45: 0 | AR45: 23490000 | AS45: 24990000 | AT45: 1500000 | AU45: 6
A46: CALLEGARI E HIJOS LTDA | B46: LOCAL CAMIONES COPIAPO | C46: 0 | D46: 0 | I46: 28-06-2024 8:46:29 | K46: MMBJJLC10RH006958 | L46: MITSUBISHI | M46: L-200 EURO 6B | N46: L200 KATANA XRT | O46: CMLC1TJJDQDL | P46: 2024 | Q46: 0 | R46: CMICMTN005188 | S46: TPJD34 | T46: SEMINUEVO | U46: PLATEADO | V46: POR DEFINIR | W46: 38068100 | X46: Disponible | Y46: 809 | Z46: TEST CAR | AA46: BODEGA CAMIONES COPIAPO | AC46: 4N16UAH7777 | AD46: MMBJJLC10RH006958 | AE46: BANSA SANTANDER S A | AF46: 28-06-2024 0:00:00 | AG46: 309007 | AH46: 03-07-2024 0:00:00 | AI46: 03-07-2024 16:32:51 | AK46: 0 | AL46: 0 | AN46: 0 | AO46: 28820700 | AP46: 922481 | AQ46: 0 | AR46: 29743181 | AS46: 31990000 | AT46: 2246819 | AU46: 702
A47: CALLEGARI E HIJOS LTDA | B47: LOCAL CAMIONES | C47: 0 | D47: 0 | I47: 30-06-2022 10:01:47 | K47: VF3YD3MFBP2U94054 | L47: PEUGEOT | M47: BOXER | N47: Boxer Furgón L2H2 BlueHdi 160 | O47: boxer | P47: 2022 | Q47: 0 | R47: CPEFRGN000004 | S47: RZSJ13 | T47: SEMINUEVO | U47: BLANCO HIELO | V47: POR DEFINIR | W47: 0 | X47: Disponible | Y47: 1538 | Z47: VEHICULO USO DE SERVICIO | AA47: LOCAL CAMIONES VEHICULOS | AC47: 10DY2Z4100754 | AD47: VF3YD3MFBP2U94054 | AE47: AUTOMOTRIZ BALMACEDA LTDA | AF47: 30-06-2022 0:00:00 | AG47: 0 | AH47: 15-03-2024 15:20:00 | AI47: 15-03-2024 15:20:00 | AK47: 0 | AL47: 0 | AN47: 0 | AO47: 0 | AP47: 3479924 | AQ47: 0 | AR47: 3479924 | AS47: 0 | AT47: -3479924 | AU47: -347992400
A48: CALLEGARI E HIJOS LTDA | B48: BODEGA PDI | C48: 0 | D48: 0 | I48: 05-08-2026 16:43:53 | K48: LVUGTBHD9TD153122 | L48: OMODA | M48: C5 | N48: C5 1.5T HEV DHT LUXURY | O48: T7150DB | P48: 2026 | Q48: 0 | R48: COMOSTWN000587 | S48: VXJX72 | T48: SEMINUEVO | U48: BLANCO TECHO NEGRO | V48: POR DEFINIR | W48: 21490000 | X48: Disponible | Y48: 41 | Z48: TEST CAR | AA48: BODEGA PDI | AC48: SQRH4J15BZTC65662 | AD48: LVUGTBHD9TD153122 | AE48: SOCIEDAD HERMANAS CALLEGARI LTDA | AF48: 05-08-2026 0:00:00 | AG48: 245236 | AH48: 09-07-2026 0:00:00 | AI48: 05-08-2026 16:43:39 | AK48: 0 | AL48: 0 | AN48: 0 | AO48: 16698151 | AP48: 0 | AQ48: 0 | AR48: 16698151 | AS48: 18058824 | AT48: 1360673 | AU48: 753
A49: CALLEGARI E HIJOS LTDA | B49: BODEGA PDI | C49: 0 | D49: 0 | I49: 23-09-2025 12:46:31 | K49: VR3FBYHZ3SY502526 | L49: PEUGEOT | M49: NUEVO 308 | N49: 308 Allure Diesel 130hp AT | O49: TCPE45 | P49: 2026 | Q49: 0 | R49: CPEAUTN000123 | S49: VGWS84 | T49: SEMINUEVO | U49: GRIS ARTENSE | V49: POR DEFINIR | W49: 27690000 | X49: Disponible | Y49: 357 | Z49: DEMO/INTERNO | AA49: BODEGA PDI | AC49: 10Q3EJ2013110 | AD49: VR3FBYHZ3SY502526 | AE49: AUTOMOTRIZ BALMACEDA LTDA | AF49: 23-09-2025 0:00:00 | AG49: 69782 | AH49: 23-10-2025 0:00:00 | AI49: 23-09-2025 12:44:57 | AK49: 0 | AL49: 0 | AN49: 0 | AO49: 21449412 | AP49: 1072084 | AQ49: 0 | AR49: 22521496 | AS49: 23268908 | AT49: 747412 | AU49: 321
A50: CALLEGARI E HIJOS LTDA | B50: BODEGA PDI | C50: 0 | D50: 0 | I50: 24-03-2025 10:18:58 | K50: VR3KAHPY2SS009627 | L50: PEUGEOT | M50: NUEVO 3008 | N50: New 3008 Allure MHEV 136 eDCT6 | O50: TCPE29 | P50: 2026 | Q50: 0 | R50: CPESTWN000075 | S50: VBBD27 | T50: SEMINUEVO | U50: AZUL OBSESSION | V50: POR DEFINIR | W50: 31990000 | X50: Disponible | Y50: 544 | Z50: DEMO/INTERNO | AA50: BODEGA PDI | AC50: 10ZA040094875 | AD50: VR3KAHPY2SS009627 | AE50: AUTOMOTRIZ BALMACEDA LTDA | AF50: 20-03-2025 0:00:00 | AG50: 66115 | AH50: 19-04-2025 0:00:00 | AI50: 24-03-2025 10:18:45 | AK50: 0 | AL50: 0 | AN50: 0 | AO50: 24773782 | AP50: 1877401 | AQ50: 0 | AR50: 26651183 | AS50: 26882353 | AT50: 231170 | AU50: 86
A51: CALLEGARI E HIJOS LTDA | B51: MEGACENTRO COPIAPO | C51: 0 | D51: 0 | I51: 24-02-2026 16:40:04 | K51: LJD0AA29AR0251362 | L51: KIA | M51: SOLUTO | N51: SOLUTO MPI 1.4 | O51: TDYG27 | P51: 2024 | Q51: 0 | R51: CKIAUTU000006 | S51: TDYG27 | T51: USADO | U51: PLATEADO TITANIO | V51: POR DEFINIR | W51: 11082000 | X51: Disponible | Y51: 203 | Z51: EN TALLER | AA51: MEGACENTRO COPIAPO VEHICULOS | AC51: G4LCP1045504 | AD51: LJD0AA29AR0251362 | AE51: RODRIGO ALEJANDRO MARTINEZ DROGUETT | AF51: 24-02-2026 0:00:00 | AG51: 1 | AH51: 24-02-2026 0:00:00 | AI51: 24-02-2026 16:38:04 | AK51: 0 | AL51: 0 | AN51: 0 | AO51: 11082000 | AP51: 0 | AQ51: 0 | AR51: 11082000 | AS51: 11082000 | AT51: 0 | AU51: 0
A52: CALLEGARI E HIJOS LTDA | B52: LOCAL USADOS | C52: 0 | D52: 0 | I52: 03-03-2025 12:04:16 | K52: W0VEDYHTXSN500914 | L52: OPEL | M52: COMBO | N52: COMBO MCA 1.5 TD | O52: TCOP5 | P52: 2025 | Q52: 40200 | R52: COPFRGN000005 | S52: TZHX27 | T52: SEMINUEVO | U52: BLANCO HIELO | V52: POR DEFINIR | W52: 16290000 | X52: Disponible | Y52: 174 | Z52: DEMO/INTERNO | AA52: LOCAL USADOS VEHICULOS | AC52: 10Q4EU0410660 | AD52: W0VEDYHTXSN500914 | AE52: AUTOMOTRIZ BALMACEDA LTDA | AF52: 25-03-2026 0:00:00 | AG52: 65756 | AH52: 30-03-2025 0:00:00 | AI52: 03-03-2025 12:04:01 | AK52: 0 | AL52: 0 | AN52: 0 | AO52: 17140917 | AP52: 641547 | AQ52: 0 | AR52: 17782464 | AS52: 16290000 | AT52: -1492464 | AU52: -916
A53: CALLEGARI E HIJOS LTDA | B53: LOCAL GILDEMEISTER COPIAPO | C53: 0 | D53: 0 | I53: 27-10-2025 9:42:22 | K53: LJ12EKS32S4705578 | L53: JAC | M53: JS | N53: JS4 1.5T CVT ADVANCE | O53: JS415TCVT-ADV | P53: 2026 | Q53: 6800 | R53: CJASTWN000003 | S53: VJTV59 | T53: SEMINUEVO | U53: GRIS | V53: POR DEFINIR | W53: 17690000 | X53: Disponible | Y53: 326 | Z53: EN PREPARACION | AA53: LOCAL GILDEMEISTER CPP AUTOS | AC53: R3378662 | AD53: LJ12EKS32S4705578 | AE53: SOCIEDAD HERMANAS CALLEGARI LTDA | AF53: 24-10-2025 0:00:00 | AG53: 235401 | AH53: 24-10-2025 0:00:00 | AI53: 27-10-2025 9:42:00 | AK53: 0 | AL53: 0 | AN53: 0 | AO53: 13802352 | AP53: 610282 | AQ53: 0 | AR53: 14412634 | AS53: 14865546 | AT53: 452912 | AU53: 305
...
