Workbook

Sheet BBDD2
A1: Marca | B1: Modelo | C1: Versión | D1: Estado Dealer | E1: Año | F1: Placa Patente | G1: Suma de Días Stock | H1: Modelo-versión-año | I1: Precio toma historico | J1: Precio toma historico autored | K1: Precio unidad venta | L1: Precio Lista informe stock | M1: Precio Mercado | N1: Precio Compra Neto Informe Stock | O1: Total Costo Informe Stock
A2: BYD | B2: SHARK DMO | C2: SHARK 1.5 AUT | D2: CON PRENDA | E2: 2025 | F2: TGVF52 | G2: 57 | H2: =CONCATENATE(B2,C2,E2) -> SHARK DMOSHARK 1.5 AUT2025 | J2: =VLOOKUP(F2,'PRECIO TOMA HISTORICO '!A:B,2,0) -> 31627180 | L2: =_xlfn.XLOOKUP(F2,BBDD!$S:$S,BBDD!$AS:$AS) -> 36990000 | M2: =IFERROR(VLOOKUP(F2,'PRECIO MERCADO'!D:E,2,0),"0") -> 40300000 | N2: =_xlfn.XLOOKUP(F2,BBDD!$S:$S,BBDD!$AO:$AO) -> 31627180 | O2: =_xlfn.XLOOKUP(F2,BBDD!$S:$S,BBDD!$AR:$AR) -> 32230828
A3: BYD | B3: SONG PLUS DM-i | C3: SONG PLUS 4X2 1.5 AUT | D3: DISPONIBLE | E3: 2024 | F3: TJDC55 | G3: 145 | H3: =CONCATENATE(B3,C3,E3) -> SONG PLUS DM-iSONG PLUS 4X2 1.5 AUT2024 | J3: =VLOOKUP(F3,'PRECIO TOMA HISTORICO '!A:B,2,0) -> 20000000 | L3: =_xlfn.XLOOKUP(F3,BBDD!$S:$S,BBDD!$AS:$AS) -> 20990000 | M3: =IFERROR(VLOOKUP(F3,'PRECIO MERCADO'!D:E,2,0),"0") -> 22100000 | N3: =_xlfn.XLOOKUP(F3,BBDD!$S:$S,BBDD!$AO:$AO) -> 20000000 | O3: =_xlfn.XLOOKUP(F3,BBDD!$S:$S,BBDD!$AR:$AR) -> 20524003
A4: CHANGAN | B4: CHANGAN | C4: CX70 T 1.5 AUT | D4: EN PREPARACION | E4: 2022 | F4: RXCG78 | G4: 1 | H4: =CONCATENATE(B4,C4,E4) -> CHANGANCX70 T 1.5 AUT2022 | J4: =VLOOKUP(F4,'PRECIO TOMA HISTORICO '!A:B,2,0) -> #N/A | L4: =_xlfn.XLOOKUP(F4,BBDD!$S:$S,BBDD!$AS:$AS) -> 9490000 | M4: =IFERROR(VLOOKUP(F4,'PRECIO MERCADO'!D:E,2,0),"0") -> 9400000 | N4: =_xlfn.XLOOKUP(F4,BBDD!$S:$S,BBDD!$AO:$AO) -> 7100000 | O4: =_xlfn.XLOOKUP(F4,BBDD!$S:$S,BBDD!$AR:$AR) -> 7100000
A5: CHERY | B5: ARRIZO 3 | C5: NEW ARRIZO 3 GLS 1.5 | D5: DISPONIBLE | E5: 2021 | F5: PKHC89 | G5: 27 | H5: =CONCATENATE(B5,C5,E5) -> ARRIZO 3NEW ARRIZO 3 GLS 1.52021 | J5: =VLOOKUP(F5,'PRECIO TOMA HISTORICO '!A:B,2,0) -> 4800000 | L5: =_xlfn.XLOOKUP(F5,BBDD!$S:$S,BBDD!$AS:$AS) -> 6190000 | M5: =IFERROR(VLOOKUP(F5,'PRECIO MERCADO'!D:E,2,0),"0") -> 5990000 | N5: =_xlfn.XLOOKUP(F5,BBDD!$S:$S,BBDD!$AO:$AO) -> 4800000 | O5: =_xlfn.XLOOKUP(F5,BBDD!$S:$S,BBDD!$AR:$AR) -> 5001240
A6: CHERY | B6: TIGGO 2 | C6: TIGGO 2 GLS CVT 1.5 AUT | D6: EN PREPARACION | E6: 2023 | F6: SJVT25 | G6: 3 | H6: =CONCATENATE(B6,C6,E6) -> TIGGO 2TIGGO 2 GLS CVT 1.5 AUT2023 | J6: =VLOOKUP(F6,'PRECIO TOMA HISTORICO '!A:B,2,0) -> 7100000 | L6: =_xlfn.XLOOKUP(F6,BBDD!$S:$S,BBDD!$AS:$AS) -> 8490000 | M6: =IFERROR(VLOOKUP(F6,'PRECIO MERCADO'!D:E,2,0),"0") -> 8300000 | N6: =_xlfn.XLOOKUP(F6,BBDD!$S:$S,BBDD!$AO:$AO) -> 7100000 | O6: =_xlfn.XLOOKUP(F6,BBDD!$S:$S,BBDD!$AR:$AR) -> 7100000
A7: CHERY | B7: TIGGO 3 | C7: TIGGO 3 1.5 | D7: EN PREPARACION | E7: 2022 | F7: RPZK49 | G7: 3 | H7: =CONCATENATE(B7,C7,E7) -> TIGGO 3TIGGO 3 1.52022 | J7: =VLOOKUP(F7,'PRECIO TOMA HISTORICO '!A:B,2,0) -> 6450000 | L7: =_xlfn.XLOOKUP(F7,BBDD!$S:$S,BBDD!$AS:$AS) -> 7990000 | M7: =IFERROR(VLOOKUP(F7,'PRECIO MERCADO'!D:E,2,0),"0") -> 7930000 | N7: =_xlfn.XLOOKUP(F7,BBDD!$S:$S,BBDD!$AO:$AO) -> 6450000 | O7: =_xlfn.XLOOKUP(F7,BBDD!$S:$S,BBDD!$AR:$AR) -> 6450000
A8: CHERY | B8: TIGGO 3 | C8: TIGGO 3 1.5 | D8: EN RESCILIACION | E8: 2021 | F8: RBZD91 | G8: 223 | H8: =CONCATENATE(B8,C8,E8) -> TIGGO 3TIGGO 3 1.52021 | J8: =VLOOKUP(F8,'PRECIO TOMA HISTORICO '!A:B,2,0) -> 6200000 | L8: =_xlfn.XLOOKUP(F8,BBDD!$S:$S,BBDD!$AS:$AS) -> 8190000 | M8: =IFERROR(VLOOKUP(F8,'PRECIO MERCADO'!D:E,2,0),"0") -> 8400000 | N8: =_xlfn.XLOOKUP(F8,BBDD!$S:$S,BBDD!$AO:$AO) -> 6200000 | O8: =_xlfn.XLOOKUP(F8,BBDD!$S:$S,BBDD!$AR:$AR) -> 6419030
A9: CHERY | B9: TIGGO 3 PRO | C9: TIGGO 3 PRO GLS 1.5 AUT | D9: DISPONIBLE | E9: 2026 | F9: VKCY97 | G9: 33 | H9: =CONCATENATE(B9,C9,E9) -> TIGGO 3 PROTIGGO 3 PRO GLS 1.5 AUT2026 | J9: =VLOOKUP(F9,'PRECIO TOMA HISTORICO '!A:B,2,0) -> 10000000 | L9: =_xlfn.XLOOKUP(F9,BBDD!$S:$S,BBDD!$AS:$AS) -> 11690000 | M9: =IFERROR(VLOOKUP(F9,'PRECIO MERCADO'!D:E,2,0),"0") -> 11300000 | N9: =_xlfn.XLOOKUP(F9,BBDD!$S:$S,BBDD!$AO:$AO) -> 10000000 | O9: =_xlfn.XLOOKUP(F9,BBDD!$S:$S,BBDD!$AR:$AR) -> 10279240
A10: CHERY | B10: TIGGO 7 PRO | C10: TIGGO 7 GLX CVT PRO 1.5 AUT | D10: EN TALLER | E10: 2022 | F10: RVRD47 | G10: 118 | H10: =CONCATENATE(B10,C10,E10) -> TIGGO 7 PROTIGGO 7 GLX CVT PRO 1.5 AUT2022 | J10: =VLOOKUP(F10,'PRECIO TOMA HISTORICO '!A:B,2,0) -> 10000000 | L10: =_xlfn.XLOOKUP(F10,BBDD!$S:$S,BBDD!$AS:$AS) -> 11990000 | M10: =IFERROR(VLOOKUP(F10,'PRECIO MERCADO'!D:E,2,0),"0") -> 11900000 | N10: =_xlfn.XLOOKUP(F10,BBDD!$S:$S,BBDD!$AO:$AO) -> 10000000 | O10: =_xlfn.XLOOKUP(F10,BBDD!$S:$S,BBDD!$AR:$AR) -> 10276030
A11: CHERY | B11: TIGGO 8 | C11: TIGGO 8 1.5 | D11: EN PREPARACION | E11: 2022 | F11: RSJD48 | G11: 26 | H11: =CONCATENATE(B11,C11,E11) -> TIGGO 8TIGGO 8 1.52022 | J11: =VLOOKUP(F11,'PRECIO TOMA HISTORICO '!A:B,2,0) -> 9500000 | L11: =_xlfn.XLOOKUP(F11,BBDD!$S:$S,BBDD!$AS:$AS) -> 11490000 | M11: =IFERROR(VLOOKUP(F11,'PRECIO MERCADO'!D:E,2,0),"0") -> 11600000 | N11: =_xlfn.XLOOKUP(F11,BBDD!$S:$S,BBDD!$AO:$AO) -> 9500000 | O11: =_xlfn.XLOOKUP(F11,BBDD!$S:$S,BBDD!$AR:$AR) -> 9771740
A12: CHERY | B12: TIGGO 8 | C12: TIGGO 8 1.5 AUT | D12: EN PREPARACION | E12: 2022 | F12: RTWH37 | G12: 1 | H12: =CONCATENATE(B12,C12,E12) -> TIGGO 8TIGGO 8 1.5 AUT2022 | J12: =VLOOKUP(F12,'PRECIO TOMA HISTORICO '!A:B,2,0) -> #N/A | L12: =_xlfn.XLOOKUP(F12,BBDD!$S:$S,BBDD!$AS:$AS) -> 11390000 | M12: =IFERROR(VLOOKUP(F12,'PRECIO MERCADO'!D:E,2,0),"0") -> 11400000 | N12: =_xlfn.XLOOKUP(F12,BBDD!$S:$S,BBDD!$AO:$AO) -> 8800000 | O12: =_xlfn.XLOOKUP(F12,BBDD!$S:$S,BBDD!$AR:$AR) -> 8800000
A13: CHEVROLET | B13: CAPTIVA | C13: CAPTIVA LS 2.4 AT | D13: EN TALLER | E13: 2017 | F13: JHSK67 | G13: 279 | H13: =CONCATENATE(B13,C13,E13) -> CAPTIVACAPTIVA LS 2.4 AT2017 | J13: =VLOOKUP(F13,'PRECIO TOMA HISTORICO '!A:B,2,0) -> 7300000 | L13: =_xlfn.XLOOKUP(F13,BBDD!$S:$S,BBDD!$AS:$AS) -> 9590000 | M13: =IFERROR(VLOOKUP(F13,'PRECIO MERCADO'!D:E,2,0),"0") -> 9300000 | N13: =_xlfn.XLOOKUP(F13,BBDD!$S:$S,BBDD!$AO:$AO) -> 7300000 | O13: =_xlfn.XLOOKUP(F13,BBDD!$S:$S,BBDD!$AR:$AR) -> 7535530
... A134: ZX AUTO | B134: TERRALORD | C134: TERRALORD DCAB DLX 2.5 | D134: DISPONIBLE | E134: 2022 | F134: RDWB83 | G134: 35 | H134: =CONCATENATE(B134,C134,E134) -> TERRALORDTERRALORD DCAB DLX 2.52022 | J134: =VLOOKUP(F134,'PRECIO TOMA HISTORICO '!A:B,2,0) -> 8900000 | L134: =_xlfn.XLOOKUP(F134,BBDD!$S:$S,BBDD!$AS:$AS) -> 11290000 | M134: =IFERROR(VLOOKUP(F134,'PRECIO MERCADO'!D:E,2,0),"0") -> 11100000 | N134: =_xlfn.XLOOKUP(F134,BBDD!$S:$S,BBDD!$AO:$AO) -> 8900000 | O134: =_xlfn.XLOOKUP(F134,BBDD!$S:$S,BBDD!$AR:$AR) -> 9162740

Sheet PRECIO TOMA HISTORICO 
A1: Patente | B1: Precio toma autored
A2: DTBC89 | B2: 5000000
A3: DYZJ57 | B3: 7700000
A4: FCBT93 | B4: 7000000
A5: FKKK46 | B5: 1
A6: FSRC30 | B6: 4000000
A7: GGJW34 | B7: 4200000
A8: GGWC79 | B8: 7000000
A9: GHBF56 | B9: 14000000
A10: GJJL60 | B10: 12000000
A11: GKCY72 | B11: 4350000
A12: GLHV84 | B12: 8500000
A13: GPBL74 | B13: 9500000
... A2731: VPGG34 | B2731: 13000000

Sheet PRECIO MERCADO
A1: FECHA CONSULTA | B1: MARCA | C1: MODELO | D1: PATENTE | E1: VALOR AUTOPRESS
A2: 45827.41 | B2: HONDA | C2: HR-V | D2: PKTY15 | E2: 13100000
A3: 46014.258 | B3: FORD | C3: F-150 NEW | D3: TCTV39 | E3: 43400000
A4: 46014.285 | B4: FORD | C4: BRONCO | D4: No informado | E4: 48700000
A5: 46014.314 | B5: PEUGEOT | C5: NUEVO 308 | D5: SLRJ93 | E5: 16500000
A6: 46014.327 | B6: HYUNDAI | C6: ACCENT | D6: RDJS62 | E6: 10500000
A7: 46014.334 | B7: CHEVROLET | C7: ALL NEW TRACKER | D7: SBWS64 | E7: 11000000
A8: 46014.335 | B8: PEUGEOT | C8: 3008 | D8: LVCS57 | E8: 15000000
A9: 46014.347 | B9: MITSUBISHI | C9: MONTERO SPORT NEW | D9: LBVX49 | E9: 20200000
A10: 46014.352 | B10: FORD | C10: F-150 NEW | D10: TCTV39 | E10: 43400000
A11: 46014.38 | B11: JEEP | C11: GRAND CHEROKEE | D11: THRJ80 | E11: 43000000
A12: 46014.39 | B12: RENAULT | C12: KWID | D12: SJHZ88 | E12: 6780000
A13: 46014.397 | B13: PEUGEOT | C13: NUEVO 2008 | D13: RJCW76 | E13: 12400000
A14: 46014.401 | B14: PEUGEOT | C14: NUEVO 208 | D14: VBBD69 | E14: 19000000
A15: 46014.407 | B15: DFSK | C15: 560 | D15: RCBJ98 | E15: 8200000
A16: 46014.41 | B16: PEUGEOT | C16: NUEVO 3008 | D16: PRVP72 | E16: 15200000
A17: 46014.415 | B17: FORD | C17: NUEVO MUSTANG | D17: VDBS14 | E17: 45800000
A18: 46014.421 | B18: CHERY | C18: TIGGO 8 | D18: PSGB54 | E18: 11500000
A19: 46014.428 | B19: CHERY | C19: TIGGO 8 PRO | D19: SPPY18 | E19: 14700000
A20: 46014.438 | B20: TOYOTA | C20: COROLLA CROSS | D20: RVKL20 | E20: 23300000
A21: 46014.475 | B21: RAM | C21: 1500 | D21: SHLW33 | E21: 31400000
A22: 46014.479 | B22: NISSAN | C22: NUEVA X-TRAIL | D22: SHDG89 | E22: 20100000
A23: 46014.496 | B23: EXEED | C23: LX | D23: TRJC45 | E23: 14700000
A24: 46014.51 | B24: CHANGAN | C24: CS15 | D24: KTCV74 | E24: 5850000
A25: 46014.516 | B25: PEUGEOT | C25: 3008 | D25: TLRT68 | E25: 25800000
A26: 46014.553 | B26: CHERY | C26: TIGGO 2 | D26: RYDL24 | E26: 7600000
A27: 46015.296 | B27: KIA | C27: SOLUTO | D27: SYPS56 | E27: 8600000
A28: 46015.317 | B28: NISSAN | C28: QASHQAI | D28: RBXV26 | E28: 13000000
A29: 46015.323 | B29: PEUGEOT | C29: NUEVO 5008 | D29: SKSZ62 | E29: 23700000
A30: 46015.34 | B30: PEUGEOT | C30: LANDTREK | D30: RSYF47 | E30: 17200000
A31: 46015.349 | B31: CHERY | C31: TIGGO 3 | D31: RBZD91 | E31: 8400000
A32: 46015.35 | B32: FORD | C32: NEW F-150 RAPTOR | D32: LYPC19 | E32: 45300000
A33: 46015.352 | B33: PEUGEOT | C33: NEW 3008 | D33: TZTC96 | E33: 23900000
A34: 46015.356 | B34: PEUGEOT | C34: NUEVO 2008 | D34: SWBX38 | E34: 16900000
A35: 46015.357 | B35: FORD | C35: NUEVA EXPLORER | D35: TXYY85 | E35: 49700000
A36: 46015.361 | B36: FORD | C36: NUEVA RANGER | D36: SYPL90 | E36: 26400000
A37: 46015.363 | B37: BAIC | C37: X55 | D37: TRTW63 | E37: 12000000
... A43: 46015.376 | B43: FORD | C43: EDGE | D43: TFFD89 | E43: 26100000
A44: 46015.379 | B44: DFSK | C44: 580 | D44: SJJH10 | E44: 10300000
A45: 46015.38 | B45: NISSAN | C45: NUEVO SENTRA | D45: SJRW76 | E45: 15600000
...

Sheet INFORME VENTAS
A1: Marca | B1: Modelo | C1: Versión | D1: Año | E1: Modelo-version-año | F1: Placa Patente | G1: Suma de Unidad Venta | H1: Suma de Unidad Costo
G2: 0 | H2: 0
A3: AUDI | B3: A3 | C3: A3 HB 1.4 AUT | D3: 2019 | E3: =CONCATENATE(B3,C3,D3) -> A3A3 HB 1.4 AUT2019 | F3: KZRK80 | G3: 14582000 | H3: 15000000
A4: AUDI | B4: A3 | C4: A3 SEDAN 35 TFSI 1.4 AUT | D4: 2022 | E4: =CONCATENATE(B4,C4,D4) -> A3A3 SEDAN 35 TFSI 1.4 AUT2022 | F4: RTLW29 | G4: 22990000 | H4: 23800000
A5: AUDI | B5: Q2 | C5: Q2 35 TFSI 1.4 AUT | D5: 2023 | E5: =CONCATENATE(B5,C5,D5) -> Q2Q2 35 TFSI 1.4 AUT2023 | F5: SPZD69 | G5: 26190000 | H5: 22500000
A6: AUDI | B6: Q3 | C6: Q3 35 TFSI 1.4 AUT | D6: 2023 | E6: =CONCATENATE(B6,C6,D6) -> Q3Q3 35 TFSI 1.4 AUT2023 | F6: SRZH16 | G6: 25990000 | H6: 23200000
A7: AUDI | B7: Q3 | C7: Q3 35 TFSI SPORTBACK 1.4 AUT | D7: 2023 | E7: =CONCATENATE(B7,C7,D7) -> Q3Q3 35 TFSI SPORTBACK 1.4 AUT2023 | F7: SLYZ27 | G7: 33990000 | H7: 29000000
A8: AUDI | B8: Q5 | C8: Q5 TDI 2.0 | D8: 2012 | E8: =CONCATENATE(B8,C8,D8) -> Q5Q5 TDI 2.02012 | F8: DTLC56 | G8: 11000000 | H8: 15000000
A9: AUDI | B9: Q5 | C9: Q5 TFSI 4X4 2.0 AUT | D9: 2020 | E9: =CONCATENATE(B9,C9,D9) -> Q5Q5 TFSI 4X4 2.0 AUT2020 | F9: LPXH29 | G9: 25390000 | H9: 31300000
A10: AUDI | B10: Q5 | C10: Q5 TFSI 4X4 2.0 AUT | D10: 2020 | E10: =CONCATENATE(B10,C10,D10) -> Q5Q5 TFSI 4X4 2.0 AUT2020 | F10: PFRP23 | G10: 23490000 | H10: 32000000
A11: AUDI | B11: Q7 | C11: Q7 TDI 4X4 3.0 AUT | D11: 2019 | E11: =CONCATENATE(B11,C11,D11) -> Q7Q7 TDI 4X4 3.0 AUT2019 | F11: KWYD58 | G11: 33490000 | H11: 29000000
A12: BAIC | B12: BAIC | C12: X35 1.5 | D12: 2019 | E12: =CONCATENATE(B12,C12,D12) -> BAICX35 1.52019 | F12: LGXV34 | G12: 7990000 | H12: 8800000
A13: BAIC | B13: BAIC | C13: X35 1.5 | D13: 2023 | E13: =CONCATENATE(B13,C13,D13) -> BAICX35 1.52023 | F13: SBLF15 | G13: 7890000 | H13: 6500000
A14: BAIC | B14: BAIC | C14: X55 1.5T | D14: 2023 | E14: =CONCATENATE(B14,C14,D14) -> BAICX55 1.5T2023 | F14: SSRS44 | G14: 8690000 | H14: 6800000
... A326: CITROEN | B326: C4 | C326: C4 1.2 AT | D326: 2025 | E326: =CONCATENATE(B326,C326,D326) -> C4C4 1.2 AT2025 | F326: VBHL43 | G326: 18990000 | H326: 16500000
A327: CITROEN | B327: C4 | C327: C4 1.5 AUT | D327: 2025 | E327: =CONCATENATE(B327,C327,D327) -> C4C4 1.5 AUT2025 | G327: 17990000 | H327: 0
A328: CITROEN | B328: C4 | C328: C4 1.5 AUT | D328: 2025 | E328: =CONCATENATE(B328,C328,D328) -> C4C4 1.5 AUT2025 | F328: TXZB72 | G328: 17990000 | H328: 14500000
A329: CITROEN | B329: C4 | C329: C4 1.6 | D329: 2010 | E329: =CONCATENATE(B329,C329,D329) -> C4C4 1.62010 | F329: CJZV22 | G329: 2000000 | H329: 3600000
A330: CITROEN | B330: C4 | C330: C4 CACTUS HDI 1.6 | D330: 2016 | E330: =CONCATENATE(B330,C330,D330) -> C4C4 CACTUS HDI 1.62016 | F330: HRWS66 | G330: 9690000 | H330: 8000000
A331: CITROEN | B331: C4 | C331: C4 HDI 1.6 | D331: 2016 | E331: =CONCATENATE(B331,C331,D331) -> C4C4 HDI 1.62016 | F331: HJSY32 | G331: 8490000 | H331: 7000000
A332: CITROEN | B332: C5 | C332: C5 AIRCROSS 1.5 AUT | D332: 2019 | E332: =CONCATENATE(B332,C332,D332) -> C5C5 AIRCROSS 1.5 AUT2019 | G332: 16490000 | H332: 0
A333: CITROEN | B333: C5 | C333: C5 AIRCROSS 1.5 AUT | D333: 2019 | E333: =CONCATENATE(B333,C333,D333) -> C5C5 AIRCROSS 1.5 AUT2019 | F333: LFXV54 | G333: 27980000 | H333: 29800000
A334: CITROEN | B334: C5 | C334: C5 AIRCROSS 1.5 AUT | D334: 2020 | E334: =CONCATENATE(B334,C334,D334) -> C5C5 AIRCROSS 1.5 AUT2020 | F334: LVWV64 | G334: 14190000 | H334: 12000000
A335: CITROEN | B335: C5 | C335: C5 AIRCROSS BHDI 1.5 AUT | D335: 2020 | E335: =CONCATENATE(B335,C335,D335) -> C5C5 AIRCROSS BHDI 1.5 AUT2020 | F335: LVWY70 | G335: 21990000 | H335: 21330300
A336: CITROEN | B336: C5 | C336: C5 AIRCROSS BLUEHDI 1.5 AUT | D336: 2022 | E336: =CONCATENATE(B336,C336,D336) -> C5C5 AIRCROSS BLUEHDI 1.5 AUT2022 | F336: PCFG80 | G336: 18090000 | H336: 15500000
A337: CITROEN | B337: C5 | C337: C5 AIRCROSS CVA8 STT 1.5 AUT | D337: 2024 | E337: =CONCATENATE(B337,C337,D337) -> C5C5 AIRCROSS CVA8 STT 1.5 AUT2024 | F337: TCTS12 | G337: 19150000 | H337: 16750000
A338: CITROEN | B338: C-ELYSEE | C338: C ELYSEE 1.2 | D338: 2018 | E338: =CONCATENATE(B338,C338,D338) -> C-ELYSEEC ELYSEE 1.22018 | F338: KGLK41 | G338: 6100000 | H338: 4900000
A339: CITROEN | B339: C-ELYSEE | C339: C ELYSEE 1.6 | D339: 2017 | E339: =CONCATENATE(B339,C339,D339) -> C-ELYSEEC ELYSEE 1.62017 | F339: JGCC12 | G339: 5590000 | H339: 5000000
A340: CITROEN | B340: SPACETOURER | C340: BUSINEES HDI 2.0 | D340: 2022 | E340: =CONCATENATE(B340,C340,D340) -> SPACETOURERBUSINEES HDI 2.02022 | F340: PCFG40 | G340: 20390000 | H340: 17500000
A341: DFLM | B341: JOYEAR | C341: JOYEAR SX5 1.6 | D341: 2021 | E341: =CONCATENATE(B341,C341,D341) -> JOYEARJOYEAR SX5 1.62021 | F341: RFHP74 | G341: 7746004 | H341: 6500000
A342: DFM | B342: AX4 | C342: AX4 LUXURY 1.6 AUT | D342: 2021 | E342: =CONCATENATE(B342,C342,D342) -> AX4AX4 LUXURY 1.6 AUT2021 | F342: PSPC17 | G342: 7990000 | H342: 5700000
A343: DFM | B343: JOYEAR | C343: JOYEAR SX5 1.6 | D343: 2022 | E343: =CONCATENATE(B343,C343,D343) -> JOYEARJOYEAR SX5 1.62022 | F343: RXSL88 | G343: 7850000 | H343: 6500000
A344: DFM | B344: T5L | C344: T5L LUX 1.8 | D344: 2025 | E344: =CONCATENATE(B344,C344,D344) -> T5LT5L LUX 1.82025 | F344: TSRG98 | G344: 11990000 | H344: 10700000
... A380: DFSK | B380: CARGO | C380: CARGO VAN C35 1.5 | D380: 2022 | E380: =CONCATENATE(B380,C380,D380) -> CARGOCARGO VAN C35 1.52022 | F380: SCGS46 | G380: 10265960 | H380: 12000000
A381: DFSK | B381: DFSK | C381: CARGO BOX XL 1.3 | D381: 2014 | E381: =CONCATENATE(B381,C381,D381) -> DFSKCARGO BOX XL 1.32014 | G381: 3990000 | H381: 0
A382: DFSK | B382: DFSK | C382: CARGO BOX XL 1.3 | D382: 2014 | E382: =CONCATENATE(B382,C382,D382) -> DFSKCARGO BOX XL 1.32014 | F382: GBDZ39 | G382: 3990000 | H382: 4331719
A383: DFSK | B383: PICK UP D1 | C383: D1 COMFORT 2.3 | D383: 2024 | E383: =CONCATENATE(B383,C383,D383) -> PICK UP D1D1 COMFORT 2.32024 | F383: TCHY13 | G383: 13990000 | H383: 14500000
A384: DFSK | B384: PICK UP D1 | C384: D1 LUXURY 4X4 2.3 | D384: 2024 | E384: =CONCATENATE(B384,C384,D384) -> PICK UP D1D1 LUXURY 4X4 2.32024 | F384: TLRR98 | G384: 16490000 | H384: 13750000
A385: DFSK | B385: TRUCK | C385: TRUCK CS C21 1.3 | D385: 2026 | E385: =CONCATENATE(B385,C385,D385) -> TRUCKTRUCK CS C21 1.32026 | F385: VJTT72 | G385: 7690000 | H385: 6500000
A386: DFSK | B386: TRUCK | C386: TRUCK DC 1.0 | D386: 2025 | E386: =CONCATENATE(B386,C386,D386) -> TRUCKTRUCK DC 1.02025 | F386: VCRP11 | G386: 6990000 | H386: 0
...

Sheet BBDD
A1: Empresa | B1: Sucursal | C1: Folio Venta | D1: Venta | E1: Estado Venta | F1: Fecha Venta | G1: Tipo Documento (Folio) | H1: Vendedor | I1: Fecha Ingreso | J1: Fecha Facturación | K1: Numero VIN | L1: Marca | M1: Modelo | N1: Versión | O1: Código Versión | P1: Año | Q1: Kilometraje | R1: Código Interno | S1: Placa Patente | T1: Condición Vehículo | U1: Color Exterior | V1: Color Interior | W1: Precio Venta Total | X1: Estado AutoPro | Y1: Días Stock | Z1: Estado Dealer | AA1: Bodega | AB1: Equipamiento | AC1: Numero Motor | AD1: Numero Chasis | AE1: Proveedor | AF1: Fecha Disponibilidad | AG1: Factura Compra | AH1: Vencimiento Documento | AI1: Fecha Compra | AJ1: Fecha Vencto. Revisión Técnica | AK1: N° Propietarios | AL1: Folio Retoma | AM1: Fecha Retoma | AN1: Días Reservado | AO1: Precio Compra Neto | AP1: Gasto | AQ1: Accesorios | AR1: Total Costo | AS1: Precio Lista | AT1: Margen | AU1: Margen %
A2: IMPORTADORA TRENTO LTDA | B2: LOCAL USADOS COPIAPO | C2: 0 | D2: 0 | I2: 13-11-2025 16:08:09 | K2: VF3MCYHZU PS006748 | L2: PEUGEOT | M2: 5008 | N2: 5008 BLUEHDI 130 1.5 AUT | O2: 5008BH130 | P2: 2023 | Q2: 66999 | R2: TPESTWU000433 | S2: SFLW13 | T2: USADO | U2: BLANCO NACARADO | V2: POR DEFINIR | W2: 22690000 | X2: Disponible | Y2: 201 | Z2: DISPONIBLE | AA2: BODEGA LOS CARRERA COPIAPO | AB2: AE,CC,EE,AAC,ABS,LL,VC,AISO,AAUTO,CRE,MAV,ACD,SR,U | AC2: 10Q4EP0125437 | AD2: VF3MCYHZU PS006748 | AE2: YOANA ELENA ROJAS HENRIQUEZ | AF2: 13-11-2025 0:00:00 | AG2: 1 | AH2: 13-11-2025 0:00:00 | AI2: 13-11-2025 16:00:05 | AJ2: 30-06-2027 0:00:00 | AK2: 1 | AL2: 0 | AN2: 0 | AO2: 19800000 | AP2: 423030 | AQ2: 0 | AR2: 20223030 | AS2: 22690000 | AT2: 2466970 | AU2: 1087
A3: IMPORTADORA TRENTO LTDA | B3: LOCAL USADOS | C3: 0 | D3: 0 | I3: 05-02-2026 13:04:12 | K3: VF3M45GFUPS010582 | L3: PEUGEOT | M3: 5008 | N3: 5008 PURETECH 180 EAT8 1.6 AUT | O3: PE5008PT16AT | P3: 2023 | Q3: 76000 | R3: TPESTWU000446 | S3: SJKL16 | T3: USADO | U3: GRIS ARTENSE | V3: POR DEFINIR | W3: 19290000 | X3: Disponible | Y3: 117 | Z3: CON PRENDA | AA3: BODEGA VEHICULOS | AB3: AE,CC,EE,AAC,ABS,LL,VC,AISO,AAUTO,CRE,MAV,ACD,SR,U | AC3: 10FKBL3003916 | AD3: VF3M45GFUPS010582 | AE3: JOHNNY SEBASTIAN DIAZ ZAMORANO | AF3: 05-02-2026 0:00:00 | AG3: 1 | AH3: 05-02-2026 0:00:00 | AI3: 05-02-2026 13:00:32 | AJ3: 30-09-2027 0:00:00 | AK3: 1 | AL3: 0 | AN3: 0 | AO3: 16500000 | AP3: 373530 | AQ3: 0 | AR3: 16873530 | AS3: 19290000 | AT3: 2416470 | AU3: 1253
A4: IMPORTADORA TRENTO LTDA | B4: LOCAL USADOS | C4: 0 | D4: 0 | I4: 03-01-2017 1:36:33 | K4: LGHT12173E9700288 | L4: DFSK | M4: DFSK | N4: CARGO BOX XL 1.3 | O4: 2012--CARGOBOX1 | P4: 2014 | Q4: 0 | R4: TDFCMTU000001 | S4: GBDZ38 | T4: USADO | U4: BLANCO | V4: NO DEFINIDO | W4: 3490000 | X4: Disponible | Y4: 4381 | Z4: VEHICULO USO DE SERVICIO | AA4: BODEGA VEHICULOS | AC4: EQ474I-3013074700 | AD4: LGHT12173E9700288 | AE4: SOCIEDAD HERMANAS CALLEGARI LTDA | AF4: 04-06-2014 0:00:00 | AG4: 0 | AJ4: 04-06-2014 0:00:00 | AK4: 0 | AL4: 0 | AN4: 0 | AO4: 82597 | AP4: 4016851 | AQ4: 0 | AR4: 4099448 | AS4: 3490000 | AT4: -609448 | AU4: -1746
A5: IMPORTADORA TRENTO LTDA | B5: LOCAL PREMIUM CAR SALES | C5: 0 | D5: 0 | I5: 06-04-2026 18:46:12 | K5: LGWEE4A40LH899522 | L5: HAVAL | M5: H2 | N5: H2 ELITE 1.5 | O5: HL1 | P5: 2019 | Q5: 88000 | R5: THASTWU000022 | S5: LHCV19 | T5: USADO | U5: AZUL | V5: POR DEFINIR | W5: 8290000 | X5: Disponible | Y5: 57 | Z5: DISPONIBLE | AA5: PREMIUM CAR SALES | AB5: AE,CC,EE,NB,ABS,LL,VC,AC,AISO,AAUTO,CRE,MAV,ACD,SR | AC5: GW4G15B1805110609 | AD5: LGWEE4A40LH899522 | AE5: YORMAN JOSE HERNANDEZ USECHE | AF5: 06-04-2026 0:00:00 | AG5: 1 | AH5: 06-04-2026 0:00:00 | AI5: 06-04-2026 18:45:47 | AJ5: 31-01-2027 0:00:00 | AK5: 1 | AL5: 0 | AN5: 0 | AO5: 6800000 | AP5: 231240 | AQ5: 0 | AR5: 7031240 | AS5: 8290000 | AT5: 1258760 | AU5: 1518
A6: IMPORTADORA TRENTO LTDA | B6: LOCAL USADOS | C6: 0 | D6: 0 | I6: 29-04-2025 19:05:19 | K6: LJXCU2BB5 NTF05473 | L6: FORD | M6: TERRITORY | N6: TERRITORY 1.5 AUT | O6: FTU1 | P6: 2022 | Q6: 25200 | R6: TFOSTWU001363 | S6: RRWP38 | T6: USADO | U6: NEGRO PANTERA | V6: POR DEFINIR | W6: 10490000 | X6: Disponible | Y6: 399 | Z6: EN TALLER | AA6: BODEGA VEHICULOS | AB6: AE,CC,EE,NB,AAC,ABS,LL,VC,AISO,AAUTO,CRE,MAV,ACD,S | AC6: M9G068199 | AD6: LJXCU2BB5 NTF05473 | AE6: JAIME NICOLAS MUÑOZ RODRIGUEZ | AF6: 29-04-2025 0:00:00 | AG6: 1 | AH6: 29-04-2025 0:00:00 | AI6: 29-04-2025 18:59:46 | AJ6: 30-11-2026 0:00:00 | AK6: 1 | AL6: 0 | AN6: 1 | AO6: 10300000 | AP6: 280530 | AQ6: 0 | AR6: 10580530 | AS6: 10490000 | AT6: -90530 | AU6: -86
A7: IMPORTADORA TRENTO LTDA | B7: LOCAL PREMIUM CAR SALES | C7: 0 | D7: 0 | I7: 02-09-2025 15:11:09 | K7: KMFYFX71AMU043854 | L7: HYUNDAI | M7: STARIA | N7: US4 CRDI 6MT 2.2 | O7: HYSTAMTDSL | P7: 2022 | Q7: 28000 | R7: THYFRGU000001 | S7: RXXW40 | T7: USADO | U7: BLANCO | V7: POR DEFINIR | W7: 21500000 | X7: Disponible | Y7: 273 | Z7: DISPONIBLE | AA7: PREMIUM CAR SALES | AB7: AE,CC,EE,2AB,ABS,AC,AISO,AAUTO,MAV,ACD,UD,DLL | AC7: D4HBNU232537 | AD7: KMFYFX71AMU043854 | AE7: ELISEO SERGIO GAJARDO VALDERRAMA | AF7: 02-09-2025 0:00:00 | AG7: 1 | AH7: 02-09-2025 0:00:00 | AI7: 02-09-2025 15:10:43 | AJ7: 28-02-2027 0:00:00 | AK7: 1 | AL7: 0 | AN7: 0 | AO7: 20000000 | AP7: 426030 | AQ7: 0 | AR7: 20426030 | AS7: 21500000 | AT7: 1073970 | AU7: 5
A8: IMPORTADORA TRENTO LTDA | B8: LOCAL USADOS COPIAPO | C8: 0 | D8: 0 | I8: 01-06-2026 18:21:00 | K8: //+**+++///++*... | L8: CHERY | M8: TIGGO 8 | N8: TIGGO 8 1.5 AUT | O8: TY8US | P8: 2022 | Q8: 93000 | R8: TCYSTWU000356 | S8: RTWH37 | T8: USADO | U8: BLANCO METALIZADO | V8: POR DEFINIR | W8: 11390000 | X8: Disponible | Y8: 1 | Z8: EN PREPARACION | AA8: BODEGA LOS CARRERA COPIAPO | AB8: AE,CC,EE,ABS,LL,AC,AISO,AAUTO,CRE,MAV,ACD,SR,DLL,6 | AC8: SQRE4T15BAVMJ00643 | AD8: LVTDB21B8ND032457 | AE8: FÉLIX RODRIGO TIFFI ARAVENA | AF8: 01-06-2026 0:00:00 | AG8: 1 | AH8: 01-06-2026 0:00:00 | AI8: 01-06-2026 18:18:33 | AK8: 2 | AL8: 0 | AN8: 0 | AO8: 8800000 | AP8: 0 | AQ8: 0 | AR8: 8800000 | AS8: 11390000 | AT8: 2590000 | AU8: 2274
A9: IMPORTADORA TRENTO LTDA | B9: LOCAL USADOS COPIAPO | C9: 0 | D9: 0 | I9: 12-09-2025 18:26:55 | K9: *---****.../*.... | L9: JAC | M9: T8 | N9: T8 PRO TM 4X4 2.0 | O9: JAT8PRO4X420MT | P9: 2023 | Q9: 40695 | R9: TJACMTU000006 | S9: SSVL57 | T9: USADO | U9: GRIS | V9: POR DEFINIR | W9: 12790000 | X9: Disponible | Y9: 263 | Z9: EN TALLER | AA9: BODEGA LOS CARRERA COPIAPO | AC9: N4127324 | AD9: LJ11PABD8 PC091786 | AE9: CARLOS GABRIEL ROMERO PINO | AF9: 12-09-2025 0:00:00 | AG9: 1 | AH9: 12-09-2025 0:00:00 | AI9: 12-09-2025 18:26:22 | AK9: 3 | AL9: 0 | AN9: 0 | AO9: 10600000 | AP9: 285030 | AQ9: 0 | AR9: 10885030 | AS9: 12790000 | AT9: 1904970 | AU9: 1489
A10: IMPORTADORA TRENTO LTDA | B10: LOCAL PREMIUM CAR SALES | C10: 0 | D10: 0 | I10: 25-05-2026 10:35:24 | K10: 3FTTW8H92RRA99365 | L10: FORD | M10: MAVERICK | N10: MAVERICK XLT 2.0 AUT | O10: FOMAVXLT204X2AT | P10: 2025 | Q10: 24000 | R10: TFOCMTU001161 | S10: TTVV23 | T10: USADO | U10: NEGRO PROFUNDO | V10: POR DEFINIR | W10: 22990000 | X10: Disponible | Y10: 8 | Z10: EN PREPARACION | AA10: PREMIUM CAR SALES | AC10: RRA99365 | AD10: 3FTTW8H92RRA99365 | AE10: INSIGHTGROUP SPA | AF10: 25-05-2026 0:00:00 | AG10: 1 | AH10: 25-05-2026 0:00:00 | AI10: 25-05-2026 10:34:53 | AK10: 3 | AL10: 0 | AN10: 0 | AO10: 20000000 | AP10: 0 | AQ10: 0 | AR10: 20000000 | AS10: 22990000 | AT10: 2990000 | AU10: 1301
A11: IMPORTADORA TRENTO LTDA | B11: LOCAL PREMIUM CAR SALES | C11: 0 | D11: 0 | I11: 29-04-2026 14:31:23 | K11: LVZA53P91 NA129835 | L11: DFSK | M11: 560 | N11: SUV 560 OTTO 1.8 | O11: S560 | P11: 2023 | Q11: 75442 | R11: TDFSTWU000054 | S11: SSTB40 | T11: USADO | U11: BLANCO | V11: POR DEFINIR | W11: 8890000 | X11: Disponible | Y11: 34 | Z11: CON PRENDA | AA11: PREMIUM CAR SALES | AB11: AE,CC,EE,2AB,ABS,LL,AC,AISO,AAUTO,MAV,ACD,SR,UD,DL | AC11: SFG18-22348600 | AD11: LVZA53P91 NA129835 | AE11: MELISSA VALESKA SAEZ FUENTES | AF11: 29-04-2026 0:00:00 | AG11: 1 | AH11: 29-04-2026 0:00:00 | AI11: 29-04-2026 14:30:57 | AK11: 1 | AL11: 0 | AN11: 0 | AO11: 6900000 | AP11: 232740 | AQ11: 0 | AR11: 7132740 | AS11: 8890000 | AT11: 1757260 | AU11: 1977
A12: IMPORTADORA TRENTO LTDA | B12: LOCAL PREMIUM CAR SALES | C12: 0 | D12: 0 | I12: 07-01-2026 16:22:02 | K12: /**//+.+///++*... | L12: HYUNDAI | M12: HYUNDAI | N12: SANTA FE MX5 GDI 2.5 AUT | O12: HYSTFMX525AT | P12: 2024 | Q12: 58500 | R12: THYSTWU000548 | S12: THXK86 | T12: USADO | U12: PLATEADO PLATA | V12: POR DEFINIR | W12: 26390000 | X12: Disponible | Y12: 146 | Z12: DISPONIBLE | AA12: PREMIUM CAR SALES | AB12: AE,CC,EE,ABS,LL,TC,VC,AC,AISO,ACP,AAUTO,CRE,MAV,AC | AC12: G4KNRA734924 | AD12: KMHP281JBRU017462 | AE12: MARIA PAZ GONZALEZ ARAYA | AF12: 07-01-2026 0:00:00 | AG12: 1 | AH12: 07-01-2026 0:00:00 | AI12: 07-01-2026 16:21:28 | AK12: 1 | AL12: 0 | AN12: 0 | AO12: 23500000 | AP12: 903834 | AQ12: 0 | AR12: 24403834 | AS12: 26390000 | AT12: 1986166 | AU12: 753
A13: IMPORTADORA TRENTO LTDA | B13: LOCAL PREMIUM CAR SALES | C13: 0 | D13: 0 | I13: 23-12-2025 18:40:06 | K13: 1C6RR7LG8 NS154084 | L13: RAM | M13: RAM 1500 | N13: 1500 CREW CAB SPORT DCAB 4X4 3.6 AT | O13: RA1500CRSPDC4X436AT | P13: 2023 | Q13: 33892 | R13: TRACMTU000047 | S13: SHLW33 | T13: USADO | U13: BLANCO | V13: POR DEFINIR | W13: 29490000 | X13: Disponible | Y13: 161 | Z13: DISPONIBLE | AA13: PREMIUM CAR SALES | AB13: AE,CC,EE,NB,AAC,ABS,LL,VC,AISO,AAUTO,CRE,MAV,ACD,S | AC13: NS154084 | AD13: 1C6RR7LG8 NS154084 | AE13: MIXY GRACIELA CORNEJO BASTIAS SOCIEDAD GASTRONOMICA E.I.R.L | AF13: 23-12-2025 0:00:00 | AG13: 1 | AH13: 23-12-2025 0:00:00 | AI13: 23-12-2025 18:39:16 | AJ13: 30-06-2027 0:00:00 | AK13: 1 | AL13: 0 | AN13: 0 | AO13: 26200000 | AP13: 519030 | AQ13: 0 | AR13: 26719030 | AS13: 29490000 | AT13: 2770970 | AU13: 94
A14: IMPORTADORA TRENTO LTDA | B14: LOCAL PREMIUM CAR SALES | C14: 0 | D14: 0 | I14: 30-05-2026 13:15:09 | K14: LVPC52898 TCB00699 | L14: DFSK | M14: 600 | N14: 600 PHEV 4X2 1.5 AUT | O14: DF600PHEV4X215AT | P14: 2026 | Q14: 598 | R14: TDFSTWU000056 | S14: VRHP15 | T14: USADO | U14: GRIS CLARO | V14: POR DEFINIR | W14: 18990000 | X14: Disponible | Y14: 3 | Z14: EN PREPARACION | AA14: PREMIUM CAR SALES | AB14: AE,CC,EE,AAC,ABS,LL,VC,AISO,AAUTO,CRE,MAV,ACD,SR,U | AC14: F31A 125003402 | AD14: LVPC52898 TCB00699 | AE14: EMILIO ANDRES ORDENES ROJAS | AF14: 30-05-2026 0:00:00 | AG14: 1 | AH14: 30-05-2026 0:00:00 | AI14: 30-05-2026 13:12:38 | AK14: 1 | AL14: 0 | AN14: 0 | AO14: 16500000 | AP14: 0 | AQ14: 0 | AR14: 16500000 | AS14: 18990000 | AT14: 2490000 | AU14: 1311
A15: IMPORTADORA TRENTO LTDA | B15: LOCAL USADOS COPIAPO | C15: 0 | D15: 0 | I15: 30-05-2026 11:28:44 | K15: WF0AXXWPMHGY88472 | L15: FORD | M15: ESCAPE | N15: ESCAPE 4X4 2.0 AUT | O15: 01--ESCAUT1 | P15: 2018 | Q15: 66252 | R15: TFOSTWU001411 | S15: JXDK27 | T15: USADO | U15: NEGRO ABSOLUTO | V15: POR DEFINIR | W15: 10490000 | X15: Disponible | Y15: 3 | Z15: EN PREPARACION | AA15: BODEGA LOS CARRERA COPIAPO | AB15: AE,CC,EE,AAC,ABS,LL,VC,AISO,AAUTO,CRE,MAV,ACD,SR,U | AC15: HGY88472 | AD15: WF0AXXWPMHGY88472 | AE15: SUSAN CARMEN GLORIA HENRY HENRY | AF15: 30-05-2026 0:00:00 | AG15: 1 | AH15: 30-05-2026 0:00:00 | AI15: 30-05-2026 11:28:08 | AJ15: 31-10-2027 0:00:00 | AK15: 1 | AL15: 0 | AN15: 0 | AO15: 8600000 | AP15: 0 | AQ15: 0 | AR15: 8600000 | AS15: 10490000 | AT15: 1890000 | AU15: 1802
A16: IMPORTADORA TRENTO LTDA | B16: LOCAL PREMIUM CAR SALES | C16: 0 | D16: 0 | I16: 30-05-2026 11:49:56 | K16: 98867545CKKH86607 | L16: JEEP | M16: COMPASS | N16: ALL NEW COMPASS SPORT LX 2.4 | O16: CVN | P16: 2018 | Q16: 105000 | R16: TJESTWU000441 | S16: KSRT45 | T16: USADO | U16: PLATEADO | V16: POR DEFINIR | W16: 8990000 | X16: Disponible | Y16: 3 | Z16: EN PREPARACION | AA16: PREMIUM CAR SALES | AB16: AE,CC,EE,ABS,LL,AC,AISO,AAUTO,CRE,MAV,ACD,SR,DLL,6 | AC16: 0255313 | AD16: 98867545CKKH86607 | AE16: LAURA CECILIA FLORES ROJAS | AF16: 30-05-2026 0:00:00 | AG16: 1 | AH16: 30-05-2026 0:00:00 | AI16: 30-05-2026 11:48:50 | AJ16: 31-08-2026 0:00:00 | AK16: 3 | AL16: 0 | AN16: 0 | AO16: 7600000 | AP16: 0 | AQ16: 0 | AR16: 7600000 | AS16: 8990000 | AT16: 1390000 | AU16: 1546
A17: IMPORTADORA TRENTO LTDA | B17: LOCAL PREMIUM CAR SALES | C17: 0 | D17: 0 | I17: 18-02-2026 9:46:22 | K17: KNACP81EG P5055975 | L17: KIA MOTORS | M17: NIRO | N17: NIRO HEV DCT GDI 1.6 AUT | O17: KINIRO16AT | P17: 2024 | Q17: 43000 | R17: TKISTWU001335 | S17: THXP99 | T17: USADO | U17: BLANCO INVIERNO | V17: POR DEFINIR | W17: 19990000 | X17: Disponible | Y17: 104 | Z17: DISPONIBLE | AA17: PREMIUM CAR SALES | AB17: AE,CC,EE,AAC,ABS,LL,AISO,AAUTO,CRE,MAV,SR,DLL,6AB | AC17: G4LLNS082877 | AD17: KNACP81EG P5055975 | AE17: MARY CARMEN ALFARO AHUMADA | AF17: 18-02-2026 0:00:00 | AG17: 1 | AH17: 18-02-2026 0:00:00 | AI17: 18-02-2026 9:45:23 | AK17: 0 | AL17: 0 | AN17: 0 | AO17: 17750000 | AP17: 392280 | AQ17: 0 | AR17: 18142280 | AS17: 19990000 | AT17: 1847720 | AU17: 924
A18: IMPORTADORA TRENTO LTDA | B18: LOCAL USADOS COPIAPO | C18: 0 | D18: 0 | I18: 01-06-2026 17:30:09 | K18: MMBGJKR10NH010717 | L18: MITSUBISHI | M18: MONTERO | N18: MONTERO SPORT 2.4 | O18: KM7000 | P18: 2023 | Q18: 67096 | R18: TMISTWU000374 | S18: SDKF65 | T18: USADO | U18: BLANCO DIAMANTE | V18: POR DEFINIR | W18: 22990000 | X18: Disponible | Y18: 1 | Z18: EN PREPARACION | AA18: BODEGA LOS CARRERA COPIAPO | AB18: AE,CC,EE,ABS,LL,VC,AC,AISO,AAUTO,CRE,MAV,ACD,SR,UD | AC18: 4N15 UJD6131 | AD18: MMBGJKR10NH010717 | AE18: IBAR RODRIGO MANZANO REQUENA | AF18: 01-06-2026 0:00:00 | AG18: 1 | AH18: 01-06-2026 0:00:00 | AI18: 01-06-2026 17:29:47 | AK18: 1 | AL18: 0 | AN18: 0 | AO18: 18300000 | AP18: 0 | AQ18: 0 | AR18: 18300000 | AS18: 22990000 | AT18: 4690000 | AU18: 204
A19: IMPORTADORA TRENTO LTDA | B19: LOCAL PREMIUM CAR SALES | C19: 0 | D19: 0 | I19: 28-04-2026 10:56:17 | K19: ///***++///++*... | L19: VOLKSWAGEN | M19: SAVEIRO | N19: SAVEIRO CD 4X2 1.6 | O19: VOSAVECD16 | P19: 2024 | Q19: 31107 | R19: TVOCMTU000041 | S19: TFGS79 | T19: USADO | U19: BLANCO CANDY | V19: POR DEFINIR | W19: 11590000 | X19: Disponible | Y19: 35 | Z19: CON PRENDA | AA19: PREMIUM CAR SALES | AB19: AE,CC,EE,2AB,NB,ABS,LL,AC,AISO,AAUTO,ACD,UD,DLL | AC19: CWS 588198 | AD19: 9BWJL45U9 PP056766 | AE19: BARBARA ANDREINA CASTILLO MAVARES | AF19: 28-04-2026 0:00:00 | AG19: 1 | AH19: 28-04-2026 0:00:00 | AI19: 28-04-2026 10:53:19 | AK19: 1 | AL19: 0 | AN19: 0 | AO19: 9600000 | AP19: 273240 | AQ19: 0 | AR19: 9873240 | AS19: 11590000 | AT19: 1716760 | AU19: 1481
A20: IMPORTADORA TRENTO LTDA | B20: LOCAL PREMIUM CAR SALES | C20: 0 | D20: 0 | I20: 30-04-2026 17:13:00 | K20: 9BGJK7560LB180490 | L20: CHEVROLET | M20: SPIN | N20: SPIN 1.8 | O20: CHSPI18MT | P20: 2021 | Q20: 83079 | R20: TCHSTWU000321 | S20: PKZB80 | T20: USADO | U20: AZUL ATLANTICO | V20: POR DEFINIR | W20: 8990000 | X20: Disponible | Y20: 33 | Z20: DISPONIBLE | AA20: PREMIUM CAR SALES | AC20: JWJ001279 | AD20: 9BGJK7560LB180490 | AE20: ROBERTO EMILIO VILLABLANCA VERA | AF20: 30-04-2026 0:00:00 | AG20: 1 | AH20: 30-04-2026 0:00:00 | AI20: 30-04-2026 17:12:42 | AJ20: 28-02-2027 0:00:00 | AK20: 1 | AL20: 0 | AN20: 0 | AO20: 7100000 | AP20: 0 | AQ20: 0 | AR20: 7100000 | AS20: 8990000 | AT20: 1890000 | AU20: 2102
A21: IMPORTADORA TRENTO LTDA | B21: LOCAL PREMIUM CAR SALES | C21: 0 | D21: 0 | I21: 06-05-2026 18:05:59 | K21: //.//+*+///++*... | L21: MITSUBISHI | M21: OUTLANDER | N21: OUTLANDER GLS 4X4 2.5 AT | O21: NOI09 | P21: 2025 | Q21: 13500 | R21: TMISTWU000373 | S21: VDFP78 | T21: USADO | U21: GRIS GRAFITO | V21: POR DEFINIR | W21: 31590000 | X21: Disponible | Y21: 27 | Z21: EN PREPARACION | AA21: PREMIUM CAR SALES | AB21: AE,CC,EE,NB,AAC,ABS,LL,VC,AISO,AAUTO,CRE,MAV,ACD,S | AC21: PR25 573855F | AD21: JMYXTGM4WSZ002020 | AE21: LUIS GASTÓN ALCAYAGA NUÑEZ | AF21: 06-05-2026 0:00:00 | AG21: 1 | AH21: 06-05-2026 0:00:00 | AI21: 06-05-2026 18:05:30 | AK21: 1 | AL21: 0 | AN21: 0 | AO21: 26300000 | AP21: 523740 | AQ21: 0 | AR21: 26823740 | AS21: 31590000 | AT21: 4766260 | AU21: 1509
A22: IMPORTADORA TRENTO LTDA | B22: MEGACENTRO OVALLE | C22: 0 | D22: 0 | I22: 28-02-2026 16:17:28 | K22: 8AFBR01C4RJ372982 | L22: FORD | M22: RANGER | N22: RANGER XLT 4X4 2.0 | O22: FORANXLT4X420MT | P22: 2024 | Q22: 40100 | R22: TFOCMTU001156 | S22: THRJ79 | T22: USADO | U22: GRIS MERCURIO | V22: POR DEFINIR | W22: 28490000 | X22: Disponible | Y22: 94 | Z22: DISPONIBLE | AA22: BODEGA OVALLEveih | AC22: YN2X RJ372982 | AD22: 8AFBR01C4RJ372982 | AE22: HECTOR LIAZ CAYULEF HUICHICOY | AF22: 28-02-2026 0:00:00 | AG22: 1 | AH22: 28-02-2026 0:00:00 | AI22: 28-02-2026 16:16:52 | AK22: 0 | AL22: 0 | AN22: 0 | AO22: 24000000 | AP22: 877705 | AQ22: 0 | AR22: 24877705 | AS22: 28490000 | AT22: 3612295 | AU22: 1268
A23: IMPORTADORA TRENTO LTDA | B23: LOCAL USADOS | C23: 0 | D23: 0 | I23: 28-02-2026 11:42:29 | K23: 1FM5K8FH7KGA98168 | L23: FORD | M23: EXPLORER | N23: EXPLORER LTD 4X4 2.3 AUT | O23: EXPUS1 | P23: 2020 | Q23: 84600 | R23: TFOSTWU001401 | S23: LSZV62 | T23: USADO | U23: BLANCO METAL | V23: POR DEFINIR | W23: 22990000 | X23: Disponible | Y23: 94 | Z23: EN TALLER | AA23: BODEGA VEHICULOS | AC23: KGA98168 | AD23: 1FM5K8FH7KGA98168 | AE23: CLAUDIO VALENZUELA CELIS | AF23: 28-02-2026 0:00:00 | AG23: 1 | AH23: 28-02-2026 0:00:00 | AI23: 28-02-2026 11:42:08 | AK23: 0 | AL23: 0 | AN23: 0 | AO23: 17000000 | AP23: 381030 | AQ23: 0 | AR23: 17381030 | AS23: 22990000 | AT23: 5608970 | AU23: 244
A24: IMPORTADORA TRENTO LTDA | B24: MEGACENTRO OVALLE | C24: 0 | D24: 0 | I24: 07-05-2026 12:16:55 | K24: VF3MRHNSM RS002587 | L24: PEUGEOT | M24: 3008 | N24: 3008 PURETECH 1.2L | O24: 3P1L | P24: 2023 | Q24: 18500 | R24: TPESTWU000455 | S24: SVGL34 | T24: USADO | U24: BLANCO NACARADO | V24: POR DEFINIR | W24: 13690000 | X24: Disponible | Y24: 26 | Z24: EN PREPARACION | AA24: BODEGA OVALLEveih | AB24: AE,CC,EE,AAC,ABS,LL,VC,AISO,AAUTO,CRE,MAV,SR,DLL,6 | AC24: 10Z1AJ0024780 | AD24: VF3MRHNSM RS002587 | AE24: PABLO ALEJANDRO IGNACIO FIGUEROA TELLO | AF24: 07-05-2026 0:00:00 | AG24: 1 | AH24: 07-05-2026 0:00:00 | AI24: 07-05-2026 12:16:07 | AJ24: 31-07-2027 0:00:00 | AK24: 2 | AL24: 0 | AN24: 0 | AO24: 11200000 | AP24: 297240 | AQ24: 0 | AR24: 11497240 | AS24: 13690000 | AT24: 2192760 | AU24: 1602
A25: IMPORTADORA TRENTO LTDA | B25: LOCAL USADOS COPIAPO | C25: 0 | D25: 0 | I25: 30-04-2026 16:45:15 | K25: 9FBHSRA95LM023521 | L25: RENAULT | M25: RENAULT | N25: DUSTER ZEN 1.6 | O25: 124FG | P25: 2019 | Q25: 95000 | R25: TRESTWU000047 | S25: LPXF73 | T25: USADO | U25: GRIS ESTRELLA | V25: POR DEFINIR | W25: 7690000 | X25: Disponible | Y25: 33 | Z25: EN TALLER | AA25: BODEGA LOS CARRERA COPIAPO | AB25: AE,CC,EE,2AB,NB,ABS,LL,AC,AISO,MAV,SR,UD,DLL | AC25: K4M2842Q234165 | AD25: 9FBHSRA95LM023521 | AE25: MIRIAM ELIANA ROJAS PAEZ | AF25: 30-04-2026 0:00:00 | AG25: 1 | AH25: 30-04-2026 0:00:00 | AI25: 30-04-2026 16:43:05 | AJ25: 30-06-2026 0:00:00 | AK25: 1 | AL25: 0 | AN25: 0 | AO25: 5800000 | AP25: 0 | AQ25: 0 | AR25: 5800000 | AS25: 7690000 | AT25: 1890000 | AU25: 2458
A26: IMPORTADORA TRENTO LTDA | B26: LOCAL USADOS COPIAPO | C26: 0 | D26: 0 | I26: 28-01-2026 17:28:07 | K26: 1FMCU0BZ6NUB03562 | L26: FORD | M26: ESCAPE | N26: ESCAPE FHEV 2.5 AUT | O26: FOESFEHV20AT | P26: 2023 | Q26: 45000 | R26: TFOSTWU001396 | S26: SBLD74 | T26: USADO | U26: BLANCO METALICO | V26: POR DEFINIR | W26: 19990000 | X26: Disponible | Y26: 125 | Z26: DISPONIBLE | AA26: BODEGA LOS CARRERA COPIAPO | AB26: AE,CC,EE,AAC,ABS,LL,AISO,AAUTO,CRE,MAV,ACD,SR,UD,D | AC26: NUB03562 | AD26: 1FMCU0BZ6NUB03562 | AE26: SOCIEDAD COMERCIAL HERMANOS GODOY ARAYA SPA | AF26: 28-01-2026 0:00:00 | AG26: 1 | AH26: 28-01-2026 0:00:00 | AI26: 28-01-2026 17:22:31 | AK26: 1 | AL26: 0 | AN26: 0 | AO26: 17500000 | AP26: 388530 | AQ26: 0 | AR26: 17888530 | AS26: 19990000 | AT26: 2101470 | AU26: 1051
A27: IMPORTADORA TRENTO LTDA | B27: LOCAL USADOS COPIAPO | C27: 0 | D27: 0 | I27: 06-02-2026 23:32:37 | K27: 98859125B TKS03533 | L27: RAM | M27: RAM 1500 | N27: RAMPAGE DS LARAMIE 4X4 2.0 AUT | O27: RARAMCSLA4X420AT | P27: 2025 | Q27: 16869 | R27: TRACMTU000050 | S27: VFSF65 | T27: USADO | U27: PLATEADO PLATA BILLET | V27: POR DEFINIR | W27: 31590000 | X27: Disponible | Y27: 116 | Z27: DISPONIBLE | AA27: BODEGA LOS CARRERA COPIAPO | AB27: AE,CC,EE,AAC,ABS,LL,VC,AC,AISO,AAUTO,CRE,MAV,ACD,S | AC27: 463495081880130 | AD27: 98859125B TKS03533 | AE27: BERNARDO MAURICIO CORTES AVALOS | AF27: 06-02-2026 0:00:00 | AG27: 60226 | AH27: 06-02-2026 0:00:00 | AI27: 06-02-2026 23:31:06 | AK27: 0 | AL27: 0 | AN27: 0 | AO27: 29000000 | AP27: 561030 | AQ27: 0 | AR27: 29561030 | AS27: 31590000 | AT27: 2028970 | AU27: 642
A28: IMPORTADORA TRENTO LTDA | B28: LOCAL PREMIUM CAR SALES | C28: 0 | D28: 0 | I28: 28-02-2026 15:52:31 | K28: LVVDB21B7 SC004108 | L28: JAECOO | M28: 7 | N28: 7 DCT FWD 1.6 AUT | O28: JE7AWD16AT | P28: 2025 | Q28: 7500 | R28: TJAESTWU000003 | S28: VDWK12 | T28: USADO | U28: PLATEADO NEGRO | V28: POR DEFINIR | W28: 17490000 | X28: Disponible | Y28: 94 | Z28: DISPONIBLE | AA28: PREMIUM CAR SALES | AB28: AE,CC,EE,AAC,ABS,LL,AISO,ACP,AAUTO,CRE,MAV,ACD,SR, | AC28: SQRF4J16CAHRE00209 | AD28: LVVDB21B7 SC004108 | AE28: WILSON ELOY PIZARRO GERALDO | AF28: 28-02-2026 0:00:00 | AG28: 1 | AH28: 28-02-2026 0:00:00 | AI28: 28-02-2026 15:51:53 | AK28: 0 | AL28: 0 | AN28: 0 | AO28: 15500000 | AP28: 358530 | AQ28: 0 | AR28: 15858530 | AS28: 17490000 | AT28: 1631470 | AU28: 933
A29: IMPORTADORA TRENTO LTDA | B29: LOCAL PREMIUM CAR SALES | C29: 0 | D29: 0 | I29: 08-01-2026 15:20:40 | K29: LGXC74C40R0005634 | L29: BYD | M29: SONG PLUS DM-i | N29: SONG PLUS 4X2 1.5 AUT | O29: BYSONP15AT | P29: 2024 | Q29: 30000 | R29: TBYSTWU000006 | S29: TJDC55 | T29: USADO | U29: ROJO | V29: POR DEFINIR | W29: 20990000 | X29: Disponible | Y29: 145 | Z29: DISPONIBLE | AA29: PREMIUM CAR SALES | AB29: AE,CC,EE,AAC,ABS,LL,AISO,AAUTO,CRE,MAV,SR,UD,DLL,6 | AC29: BYD472QA S23333377 | AD29: LGXC74C40R0005634 | AE29: EMILIO ANDRES ORDENES ROJAS | AF29: 08-01-2026 0:00:00 | AG29: 1 | AH29: 08-01-2026 0:00:00 | AI29: 08-01-2026 15:16:26 | AK29: 1 | AL29: 0 | AN29: 0 | AO29: 20000000 | AP29: 524003 | AQ29: 0 | AR29: 20524003 | AS29: 20990000 | AT29: 465997 | AU29: 222
A30: IMPORTADORA TRENTO LTDA | B30: LOCAL USADOS | C30: 0 | D30: 0 | I30: 17-02-2022 15:53:19 | K30: VF3M45GZWJS004469 | L30: PEUGEOT | M30: 3008 | N30: 3008 ALLURE 1.6 AT | O30: PALL7 | P30: 2018 | Q30: 120000 | R30: TPESTWU000279 | S30: JXGC32 | T30: USADO | U30: GRIS HURRICANE | V30: POR DEFINIR | W30: 14390000 | X30: Disponible | Y30: 1566 | Z30: EN TALLER | AA30: BODEGA VEHICULOS | AB30: AE,CC,EE,2AB,NB,AAC,ABS,LL,TC,VC,4AB,ESP,CT,SS,AIS | AC30: 10FJCC2346652 | AD30: VF3M45GZWJS004469 | AE30: OSCAR ARMANDO PIZARRO BEMBOW | AF30: 17-02-2022 0:00:00 | AG30: 1 | AH30: 29-04-2022 19:24:00 | AI30: 29-04-2022 19:24:00 | AK30: 0 | AL30: 0 | AN30: 0 | AO30: 17650000 | AP30: 753678 | AQ30: 0 | AR30: 18403678 | AS30: 14390000 | AT30: -4013678 | AU30: -2789
A31: IMPORTADORA TRENTO LTDA | B31: LOCAL PREMIUM CAR SALES | C31: 0 | D31: 0 | I31: 14-03-2023 10:52:12 | K31: 2FMPK4J94KBB16022 | L31: FORD | M31: EDGE | N31: EDGE SEL 4X4 2.0 AUT | O31: EDD900 | P31: 2020 | Q31: 55000 | R31: TFOSTWU001240 | S31: PCDV84 | T31: USADO | U31: GRIS METALICO | V31: POR DEFINIR | W31: 18490000 | X31: Disponible | Y31: 1176 | Z31: EN TALLER | AA31: PREMIUM CAR SALES | AB31: AE,CC,EE,NB,AAC,ABS,LL,TC,VC,ESP,CT,SS,AISO,ACP,AA | AC31: KBB16022 | AD31: 2FMPK4J94KBB16022 | AE31: BARBARA YEIME CEA URRIAGA | AF31: 14-03-2023 0:00:00 | AG31: 1 | AH31: 14-03-2023 0:00:00 | AI31: 14-03-2023 10:51:51 | AK31: 0 | AL31: 0 | AN31: 0 | AO31: 18000000 | AP31: 673380 | AQ31: 0 | AR31: 18673380 | AS31: 18490000 | AT31: -183380 | AU31: -99
A32: IMPORTADORA TRENTO LTDA | B32: LOCAL USADOS COPIAPO | C32: 0 | D32: 0 | I32: 22-01-2026 12:55:07 | K32: KNARH81BHR5259144 | L32: KIA MOTORS | M32: SORENTO | N32: SORENTO 8DCT 4WD 2.2 AUT | O32: KISO4WD2.2AT | P32: 2024 | Q32: 37000 | R32: TKISTWU001330 | S32: TRBJ23 | T32: USADO | U32: GRIS ACERO | V32: POR DEFINIR | W32: 33490000 | X32: Disponible | Y32: 131 | Z32: DISPONIBLE | AA32: BODEGA LOS CARRERA COPIAPO | AB32: AE,CC,EE,AAC,ABS,LL,TC,VC,AISO,AAUTO,CRE,MAV,ACD,S | AC32: D4HEPH357028 | AD32: KNARH81BHR5259144 | AE32: OPERACIONES JORGE ALEJANDRO VARAS VARAS E.I.R.L | AF32: 22-01-2026 0:00:00 | AG32: 1 | AH32: 22-01-2026 0:00:00 | AI32: 22-01-2026 12:54:40 | AK32: 1 | AL32: 0 | AN32: 0 | AO32: 28000000 | AP32: 1142194 | AQ32: 0 | AR32: 29142194 | AS32: 33490000 | AT32: 4347806 | AU32: 1298
A33: IMPORTADORA TRENTO LTDA | B33: LOCAL PREMIUM CAR SALES | C33: 0 | D33: 0 | I33: 06-04-2026 15:27:31 | K33: LPE19W2A6TF007924 | L33: BYD | M33: SHARK DMO | N33: SHARK 1.5 AUT | O33: BYDSHA15AT | P33: 2025 | Q33: 20000 | R33: TBYCMTU000001 | S33: TGVF52 | T33: USADO | U33: BLANCO | V33: POR DEFINIR | W33: 36990000 | X33: Disponible | Y33: 57 | Z33: CON PRENDA | AA33: PREMIUM CAR SALES | AB33: AE,CC,EE,NB,AAC,ABS,LL,TC,AISO,AAUTO,CRE,ACD,SR,UD | AC33: BYD476ZQFT25007008 | AD33: LPE19W2A6TF007924 | AE33: SEGURIDAD PRIVADA Y ASEO INDUSTRIAL GUILLERMO DE JESUS NEIRA ARAYA SPA . . | AF33: 06-04-2026 0:00:00 | AG33: 1 | AH33: 06-04-2026 0:00:00 | AI33: 06-04-2026 15:26:56 | AK33: 1 | AL33: 0 | AN33: 0 | AO33: 31627180 | AP33: 603648 | AQ33: 0 | AR33: 32230828 | AS33: 36990000 | AT33: 4759172 | AU33: 1287
A34: IMPORTADORA TRENTO LTDA | B34: LOCAL USADOS COPIAPO | C34: 0 | D34: 0 | I34: 30-04-2026 10:10:05 | K34: MALGT41DASM115787 | L34: HYUNDAI | M34: HYUNDAI | N34: ACCENT 1.5 | O34: 20--ACC90 | P34: 2025 | Q34: 7193 | R34: THYAUTU000585 | S34: TTXB96 | T34: USADO | U34: GRIS GRAFITO | V34: POR DEFINIR | W34: 12890000 | X34: Disponible | Y34: 33 | Z34: CON PRENDA | AA34: BODEGA LOS CARRERA COPIAPO | AB34: AE,CC,EE,AAC,ABS,LL,VC,AISO,AAUTO,CRE,MAV,ACD,SR,U | AC34: G4FLRQ356179 | AD34: MALGT41DASM115787 | AE34: JESSICA DEL CARMEN CHILLA CAMPILLAY | AF34: 30-04-2026 0:00:00 | AG34: 1 | AH34: 30-04-2026 0:00:00 | AI34: 30-04-2026 10:07:04 | AK34: 1 | AL34: 0 | AN34: 0 | AO34: 10350000 | AP34: 284490 | AQ34: 0 | AR34: 10634490 | AS34: 12890000 | AT34: 2255510 | AU34: 175
A35: IMPORTADORA TRENTO LTDA | B35: LOCAL PREMIUM CAR SALES | C35: 0 | D35: 0 | I35: 06-04-2026 11:44:19 | K35: 1FTFW1E50 MFA34669 | L35: FORD | M35: F-150 | N35: F150 LARIAT LUXURY 4X4 5.0L AUT | O35: F150AUT | P35: 2021 | Q35: 47500 | R35: TFOCMTU001159 | S35: PSTV42 | T35: USADO | U35: ROJO METALICO | V35: POR DEFINIR | W35: 31990000 | X35: Disponible | Y35: 57 | Z35: EN TALLER | AA35: PREMIUM CAR SALES | AB35: AE,CC,EE,NB,AAC,ABS,LL,TC,VC,AISO,ACP,AAUTO,CRE,MA | AC35: MFA34669 | AD35: 1FTFW1E50 MFA34669 | AE35: FREDDY ORLANDO ARIAS CHOQUE | AF35: 06-04-2026 0:00:00 | AG35: 1 | AH35: 06-04-2026 0:00:00 | AI35: 06-04-2026 11:43:26 | AJ35: 31-05-2026 0:00:00 | AK35: 1 | AL35: 0 | AN35: 0 | AO35: 20000000 | AP35: 429240 | AQ35: 0 | AR35: 20429240 | AS35: 31990000 | AT35: 11560760 | AU35: 3614
A36: IMPORTADORA TRENTO LTDA | B36: LOCAL PREMIUM CAR SALES | C36: 0 | D36: 0 | I36: 24-09-2025 17:50:46 | K36: 8AFBR01K1 RJ394381 | L36: FORD | M36: RANGER | N36: RANGER LTD 4X4 3.0 AUT | O36: RANGERDEV | P36: 2024 | Q36: 69690 | R36: TFOCMTU001136 | S36: TJSK30 | T36: USADO | U36: GRIS MERCURIO | V36: POR DEFINIR | W36: 34990000 | X36: Disponible | Y36: 251 | Z36: DISPONIBLE | AA36: PREMIUM CAR SALES | AB36: AE,CC,EE,AAC,ABS,LL,VC,AISO,AAUTO,CRE,MAV,ACD,SR,U | AC36: BF2X RJ394381 | AD36: 8AFBR01K1 RJ394381 | AE36: DRILLING SERVICES AND SOLUTIONS SPA | AF36: 24-09-2025 0:00:00 | AG36: 1 | AH36: 24-09-2025 0:00:00 | AI36: 24-09-2025 17:50:08 | AK36: 1 | AL36: 0 | AN36: 0 | AO36: 34000000 | AP36: 1178778 | AQ36: 0 | AR36: 35178778 | AS36: 34990000 | AT36: -188778 | AU36: -54
A37: IMPORTADORA TRENTO LTDA | B37: MEGACENTRO OVALLE | C37: 0 | D37: 0 | I37: 02-01-2026 15:09:11 | K37: VF3M45GZWJS004343 | L37: PEUGEOT | M37: 3008 | N37: 3008 ACTIVE 1.6 | O37: P7R9 | P37: 2018 | Q37: 95984 | R37: TPESTWU000443 | S37: JYBF33 | T37: USADO | U37: ROJO ULTIMATE | V37: POR DEFINIR | W37: 10490000 | X37: Disponible | Y37: 151 | Z37: EN TALLER | AA37: BODEGA OVALLEveih | AB37: AE,CC,EE,ABS,LL,VC,AC,AISO,AAUTO,CRE,MAV,ACD,SR,UD | AC37: 10FJCC2344377 | AD37: VF3M45GZWJS004343 | AE37: mario lagunas | AF37: 02-01-2026 0:00:00 | AG37: 1 | AH37: 10-03-2026 22:23:00 | AI37: 10-03-2026 22:23:00 | AJ37: 30-06-2026 0:00:00 | AK37: 1 | AL37: 0 | AN37: 0 | AO37: 8800000 | AP37: 258030 | AQ37: 0 | AR37: 9058030 | AS37: 10490000 | AT37: 1431970 | AU37: 1365
A38: IMPORTADORA TRENTO LTDA | B38: LOCAL USADOS COPIAPO | C38: 0 | D38: 0 | I38: 22-10-2025 9:20:00 | K38: LVVDB11B7 MD082945 | L38: CHERY | M38: TIGGO 3 | N38: TIGGO 3 1.5 | O38: T315 | P38: 2021 | Q38: 40095 | R38: TCYSTWU000320 | S38: RBZD91 | T38: USADO | U38: AZUL METALIZADO | V38: POR DEFINIR | W38: 8190000 | X38: Disponible | Y38: 223 | Z38: EN RESCILIACION | AA38: BODEGA LOS CARRERA COPIAPO | AB38: AE,CC,EE,ABS,LL,4AB,AC,AISO,AAUTO,CRE,ACD,SR,UD,DL | AC38: SQRE4G15BATMC00062 | AD38: LVVDB11B7 MD082945 | AE38: MILENKA SUSANA NEGRON CABALLERO | AF38: 22-10-2025 0:00:00 | AG38: 1 | AH38: 22-10-2025 0:00:00 | AI38: 22-10-2025 9:19:18 | AJ38: 30-04-2026 0:00:00 | AK38: 1 | AL38: 0 | AN38: 0 | AO38: 6200000 | AP38: 219030 | AQ38: 0 | AR38: 6419030 | AS38: 8190000 | AT38: 1770970 | AU38: 2162
A39: IMPORTADORA TRENTO LTDA | B39: LOCAL PREMIUM CAR SALES | C39: 0 | D39: 0 | I39: 02-05-2022 18:10:07 | K39: VF3MCYHZRLS003227 | L39: PEUGEOT | M39: 3008 | N39: 3008 BLUE HDI HP 1.5 AUT | O39: PCM10 | P39: 2020 | Q39: 31000 | R39: TPESTWU000283 | S39: LVCS57 | T39: USADO | U39: BLANCO NACARADO | V39: POR DEFINIR | W39: 14990000 | X39: Disponible | Y39: 1492 | Z39: EN TALLER | AA39: PREMIUM CAR SALES | AB39: AE,CC,EE,NB,ABS,LL,AC,AISO,AAUTO,CRE,ACD,SR,DLL,6A | AC39: 10Q3BC0371833 | AD39: VF3MCYHZRLS003227 | AE39: PRUDENCIA LEONELLY VALDIVIA PLAZA | AF39: 02-05-2022 0:00:00 | AG39: 1 | AH39: 26-02-2025 17:20:00 | AI39: 26-02-2025 17:20:00 | AK39: 0 | AL39: 0 | AN39: 7 | AO39: 20000000 | AP39: 1051072 | AQ39: 0 | AR39: 21051072 | AS39: 14990000 | AT39: -6061072 | AU39: -4043
A40: IMPORTADORA TRENTO LTDA | B40: LOCAL PDI | C40: 0 | D40: 0 | I40: 14-08-2018 18:36:12 | K40: KNABE511AET622431 | L40: KIA MOTORS | M40: MORNING | N40: MORNING LX 1.0 | O40: 17--1416E4 | P40: 2014 | Q40: 50000 | R40: TKIAUTU001659 | S40: FZPL81 | T40: USADO | U40: ROJO SIGNAL | V40: POR DEFINIR | W40: 4390000 | X40: Disponible | Y40: 2849 | Z40: VEHICULO EMPRESA | AA40: BODEGA PDI | AC40: G3LADP101529 | AD40: KNABE511AET622431 | AE40: JUAN CARLOS MORALES GODOY | AF40: 14-08-2018 0:00:00 | AG40: 0 | AK40: 0 | AL40: 0 | AN40: 1 | AO40: 0 | AP40: 1812732 | AQ40: 0 | AR40: 1812732 | AS40: 4390000 | AT40: 2577268 | AU40: 5871
...
